Workbook
Name cash: DCF!$C$24
Name debt: DCF!$C$25
Name ebi: CCA!$L$20:$L$24,CCA!$L$26:$L$30
Name fcff: DCF!$L$18
Name reve: CCA!$J$20:$J$23,CCA!$J$25:$J$30
Name tgr: DCF!$I$22
Name wacc: DCF!$I$21

Sheet DCF
B2: Discounted Cash Flow Analysis | F2: CSX Corp. (CSX)
B3: Perpetuity Approach
H4: 0.5 | I4: =H4+1 -> 1.5 | J4: =I4+1 -> 2.5 | K4: =J4+1 -> 3.5 | L4: =K4+1 -> 4.5
B5: $M | C5: 2018 | D5: 2019 | E5: 2020 | F5: 2021 | G5: 2022 | H5: 2023 | I5: 2024 | J5: 2025 | K5: 2026 | L5: 2027
B6: Revenue, Adj | C6: 12250 | D6: 11937 | E6: 10583 | F6: 12522 | G6: 14853 | H6: 14614.154 | I6: 14995.846 | J6: =1091.8*2025-2194100 -> 16795 | K6: =1092.6*2026-2194100 -> 19507.6 | L6: =1091.8*2027-2194100 -> 18978.6
B7: Growth %, YoY | C7: 7.3808 | D7: -2.5551 | E7: -11.3429 | F7: 18.3218 | G7: 18.6152 | H7: =(H6/G6-1)*100 -> -1.6080657 | I7: =(I6/H6-1)*100 -> 2.6117968 | J7: =(J6/I6-1)*100 -> 11.997683 | K7: =(K6/J6-1)*100 -> 16.151235 | L7: =(L6/K6-1)*100 -> -2.7117636
B8: Gross Profit, Adj | C8: — | D8: — | E8: — | F8: — | G8: — | H8: — | I8: — | J8: — | K8: — | L8: —
B9: Margin % | C9: — | D9: — | E9: — | F9: — | G9: — | H9: — | I9: — | J9: — | K9: — | L9: —
B10: EBITDA, Adj | C10: 6046 | D10: 6269 | E10: 5792 | F10: 6649 | G10: 7394 | H10: 7149.182 | I10: 7417.5 | J10: =J6*J11/100 -> 8598.7811 | K10: =K6*K11/100 -> 9849.8346 | L10: =L6*L11/100 -> 9483.8043
B11: Margin % | C11: 49.355102 | D11: 52.517383 | E11: 54.729283 | F11: 53.098547 | G11: 49.781189 | H11: =H10/H6*100 -> 48.919575 | I11: =I10/I6*100 -> 49.463698 | J11: =AVERAGE(E11:I11) -> 51.198458 | K11: =AVERAGE(F11:J11) -> 50.492293 | L11: =AVERAGE(G11:K11) -> 49.971043
B12: Net Income, Adj | C12: 3200.34 | D12: 3198.09 | E12: 2737.35 | F12: 3378.34 | G12: 3907.98 | H12: 3695.192 | I12: 3837.577 | J12: =145.59*2025-290817 -> 4002.75 | K12: =145.59*2026-290817 -> 4148.34 | L12: =145.59*2027-290817 -> 4293.93
B13: Margin % | C13: 26.125224 | D13: 26.791405 | E13: 25.865539 | F13: 26.979237 | G13: 26.311048 | H13: =H12/H6*100 -> 25.285022 | I13: =I12/I6*100 -> 25.590934 | J13: =J12/J6*100 -> 23.832986 | K13: =K12/K6*100 -> 21.26525 | L13: =L12/L6*100 -> 22.625115
B14: EPS, Adj | C14: 1.2383 | D14: 1.3345 | E14: 0.396 | F14: 1.5014 | G14: 1.8295 | H14: 1.833 | I14: 1.984 | J14: =J12/$C$27 -> 2.0256832 | K14: =K12/$C$27 -> 2.0993623 | L14: =L12/$C$27 -> 2.1730415
B15: Growth %, YoY | C15: 65.458561 | D15: 7.7673784 | E15: -70.326001 | F15: 279.1498 | G15: 21.849002 | H15: =((H14/G14)-1)*100 -> 0.1913091 | I15: =((I14/H14)-1)*100 -> 8.2378614 | J15: =((J14/I14)-1)*100 -> 2.1009677 | K15: =((K14/J14)-1)*100 -> 3.6372494 | L15: =((L14/K14)-1)*100 -> 3.5095966
B16: Cash from Operations | C16: 4641 | D16: 4850 | E16: 4263 | F16: 5099 | G16: 5619 | H16: 5768.1582 | I16: 5966.3163 | J16: 6653.8023 | K16: 7702.5743 | L16: 7446.8086
B17: Capital Expenditures | C17: -1745 | D17: -1657 | E17: -1626 | F17: -1791 | G17: -2133 | H17: -2108.9374 | I17: -2169.5937 | J17: -2449.6037 | K17: -2814.8542 | L17: -2743.3311
B18: Free Cash Flow | C18: 2896 | D18: 3193 | E18: 2637 | F18: 3308 | G18: 3486 | H18: 3130.927 | I18: 3480.17 | J18: =150.93*2025-301695 -> 3938.25 | K18: =190.51*2026-381967 -> 4006.26 | L18: =191.52*2027-384010 -> 4201.04 | P18: GOAL
B19: Present value of FCF | H19: =H18/(1+$F$26)^((1+$F$27)^H4) -> 2887.8597 | I19: =I18/(1+$F$26)^((1+$F$27)^I4) -> 3198.5698 | J19: =J18/(1+$F$26)^((1+$F$27)^J4) -> 3606.1404 | K19: =K18/(1+$F$26)^((1+$F$27)^K4) -> 3654.1905 | L19: =L18/(1+$F$26)^((1+$F$27)^L4) -> 3816.3409 | O19: Python -> | P19: 39.38 | Q19: 44.282
B21: Terminal Value in Y5 | C21: =fcff*(1+tgr)/(wacc-tgr) -> 80766.39 | E21: % Debt | F21: =C25/F30 -> 0.59572833 | H21: WACC (% Equity x Cost of Equity) + (% Debt x Cost of Debt x (1 -Tax rate)) | I21: =Summary!BC14/100 -> 0.073055 | J21: ← from Bloomberg | N21: Share Price on | O21: 45249 | P21: 31.63
B22: Present value of TV | C22: =C21/(1+$F$26)^((1+$F$27)^4.5) -> 73370.422 | E22: Cost of Debt | F22: =Summary!$BC$9/100 -> 0.041244 | H22: TGR | I22: 0.02 | O22: Upside in 2026 | P22: =P19/P21-1 -> 0.24502055
B23: Enterprise Value | C23: =SUM(H19:L19,C22) -> 90533.523 | E23: Tax Rate | F23: 0.2487
B24: + Cash | C24: =Summary!G6 -> 2087 | E24: Equity Value | F24: =BS!G72 -> 12625
B25: - Debt | C25: =Summary!G8 -> 18604 | E25: % Equity | F25: =F24/F30 -> 0.40427167 | P25: Terminal Growth Rate
B26: Equity Value | C26: =C23+C24-C25 -> 74016.523 | E26: Cost of Equity Risk Free Rate + (Beta x (Expected Market Return - Risk Free Rate)) | F26: =Summary!$BC$6/100 -> 0.0823 | P26: =Q26-0.005 -> 0.01 | Q26: =R26-0.005 -> 0.015 | R26: =tgr -> 0.02 | S26: =R26+0.005 -> 0.025 | T26: =S26+0.005 -> 0.03
B27: Shares | C27: 1976 | E27: Risk Free Rate | F27: 0.0441 | G27: from US10Y | N27: WACC | O27: =O28+0.005 -> 0.083055 | P27: =TEXT(((((((fcff*(1+P$26))/ABS($O27-P$26))/(1+$F$26)^((1+$F$27)^4.5))+SUM($H$19:$L$19)-$C$25+$C$24)/$C$27/$P$21)-1),"0.0%") &" / "& TEXT(((((fcff*(1+P$26))/ABS($O27-P$26))/(1+$F$26)^((1+$F$27)^4.5))+SUM($H$19:$L$19)-$C$25+$C$24)/$C$27,"$0.00") -> -14.5% / $27.03 | Q27: =TEXT(((((((fcff*(1+Q$26))/ABS($O27-Q$26))/(1+$F$26)^((1+$F$27)^4.5))+SUM($H$19:$L$19)-$C$25+$C$24)/$C$27/$P$21)-1),"0.0%") &" / "& TEXT(((((fcff*(1+Q$26))/ABS($O27-Q$26))/(1+$F$26)^((1+$F$27)^4.5))+SUM($H$19:$L$19)-$C$25+$C$24)/$C$27,"$0.00") -> -7.9% / $29.13 | R27: =TEXT(((((((fcff*(1+R$26))/ABS($O27-R$26))/(1+$F$26)^((1+$F$27)^4.5))+SUM($H$19:$L$19)-$C$25+$C$24)/$C$27/$P$21)-1),"0.0%") &" / "& TEXT(((((fcff*(1+R$26))/ABS($O27-R$26))/(1+$F$26)^((1+$F$27)^4.5))+SUM($H$19:$L$19)-$C$25+$C$24)/$C$27,"$0.00") -> -0.2% / $31.57 | S27: =TEXT(((((((fcff*(1+S$26))/ABS($O27-S$26))/(1+$F$26)^((1+$F$27)^4.5))+SUM($H$19:$L$19)-$C$25+$C$24)/$C$27/$P$21)-1),"0.0%") &" / "& TEXT(((((fcff*(1+S$26))/ABS($O27-S$26))/(1+$F$26)^((1+$F$27)^4.5))+SUM($H$19:$L$19)-$C$25+$C$24)/$C$27,"$0.00") -> 8.8% / $34.43 | T27: =TEXT(((((((fcff*(1+T$26))/ABS($O27-T$26))/(1+$F$26)^((1+$F$27)^4.5))+SUM($H$19:$L$19)-$C$25+$C$24)/$C$27/$P$21)-1),"0.0%") &" / "& TEXT(((((fcff*(1+T$26))/ABS($O27-T$26))/(1+$F$26)^((1+$F$27)^4.5))+SUM($H$19:$L$19)-$C$25+$C$24)/$C$27,"$0.00") -> 19.6% / $37.82
B28: Share Price | C28: =C26/C27 -> 37.457755 | E28: Beta | F28: 0.986 | O28: =O29+0.005 -> 0.078055 | P28: =TEXT(((((((fcff*(1+P$26))/ABS($O28-P$26))/(1+$F$26)^((1+$F$27)^4.5))+SUM($H$19:$L$19)-$C$25+$C$24)/$C$27/$P$21)-1),"0.0%") &" / "& TEXT(((((fcff*(1+P$26))/ABS($O28-P$26))/(1+$F$26)^((1+$F$27)^4.5))+SUM($H$19:$L$19)-$C$25+$C$24)/$C$27,"$0.00") -> -8.3% / $28.99 | Q28: =TEXT(((((((fcff*(1+Q$26))/ABS($O28-Q$26))/(1+$F$26)^((1+$F$27)^4.5))+SUM($H$19:$L$19)-$C$25+$C$24)/$C$27/$P$21)-1),"0.0%") &" / "& TEXT(((((fcff*(1+Q$26))/ABS($O28-Q$26))/(1+$F$26)^((1+$F$27)^4.5))+SUM($H$19:$L$19)-$C$25+$C$24)/$C$27,"$0.00") -> -0.7% / $31.42 | R28: =TEXT(((((((fcff*(1+R$26))/ABS($O28-R$26))/(1+$F$26)^((1+$F$27)^4.5))+SUM($H$19:$L$19)-$C$25+$C$24)/$C$27/$P$21)-1),"0.0%") &" / "& TEXT(((((fcff*(1+R$26))/ABS($O28-R$26))/(1+$F$26)^((1+$F$27)^4.5))+SUM($H$19:$L$19)-$C$25+$C$24)/$C$27,"$0.00") -> 8.3% / $34.26 | S28: =TEXT(((((((fcff*(1+S$26))/ABS($O28-S$26))/(1+$F$26)^((1+$F$27)^4.5))+SUM($H$19:$L$19)-$C$25+$C$24)/$C$27/$P$21)-1),"0.0%") &" / "& TEXT(((((fcff*(1+S$26))/ABS($O28-S$26))/(1+$F$26)^((1+$F$27)^4.5))+SUM($H$19:$L$19)-$C$25+$C$24)/$C$27,"$0.00") -> 19.0% / $37.64 | T28: =TEXT(((((((fcff*(1+T$26))/ABS($O28-T$26))/(1+$F$26)^((1+$F$27)^4.5))+SUM($H$19:$L$19)-$C$25+$C$24)/$C$27/$P$21)-1),"0.0%") &" / "& TEXT(((((fcff*(1+T$26))/ABS($O28-T$26))/(1+$F$26)^((1+$F$27)^4.5))+SUM($H$19:$L$19)-$C$25+$C$24)/$C$27,"$0.00") -> 31.9% / $41.72
E29: Market Risk Premium = Market return - Risk free return | F29: =G29-F27 -> 0.0323 | G29: 0.0764 | O29: =wacc -> 0.073055 | P29: =TEXT(((((((fcff*(1+P$26))/ABS($O29-P$26))/(1+$F$26)^((1+$F$27)^4.5))+SUM($H$19:$L$19)-$C$25+$C$24)/$C$27/$P$21)-1),"0.0%") &" / "& TEXT(((((fcff*(1+P$26))/ABS($O29-P$26))/(1+$F$26)^((1+$F$27)^4.5))+SUM($H$19:$L$19)-$C$25+$C$24)/$C$27,"$0.00") -> -1.2% / $31.26 | Q29: =TEXT(((((((fcff*(1+Q$26))/ABS($O29-Q$26))/(1+$F$26)^((1+$F$27)^4.5))+SUM($H$19:$L$19)-$C$25+$C$24)/$C$27/$P$21)-1),"0.0%") &" / "& TEXT(((((fcff*(1+Q$26))/ABS($O29-Q$26))/(1+$F$26)^((1+$F$27)^4.5))+SUM($H$19:$L$19)-$C$25+$C$24)/$C$27,"$0.00") -> 7.8% / $34.09 | R29: =TEXT(((((((fcff*(1+R$26))/ABS($O29-R$26))/(1+$F$26)^((1+$F$27)^4.5))+SUM($H$19:$L$19)-$C$25+$C$24)/$C$27/$P$21)-1),"0.0%") &" / "& TEXT(((((fcff*(1+R$26))/ABS($O29-R$26))/(1+$F$26)^((1+$F$27)^4.5))+SUM($H$19:$L$19)-$C$25+$C$24)/$C$27,"$0.00") -> 18.4% / $37.46 | S29: =TEXT(((((((fcff*(1+S$26))/ABS($O29-S$26))/(1+$F$26)^((1+$F$27)^4.5))+SUM($H$19:$L$19)-$C$25+$C$24)/$C$27/$P$21)-1),"0.0%") &" / "& TEXT(((((fcff*(1+S$26))/ABS($O29-S$26))/(1+$F$26)^((1+$F$27)^4.5))+SUM($H$19:$L$19)-$C$25+$C$24)/$C$27,"$0.00") -> 31.3% / $41.52 | T29: =TEXT(((((((fcff*(1+T$26))/ABS($O29-T$26))/(1+$F$26)^((1+$F$27)^4.5))+SUM($H$19:$L$19)-$C$25+$C$24)/$C$27/$P$21)-1),"0.0%") &" / "& TEXT(((((fcff*(1+T$26))/ABS($O29-T$26))/(1+$F$26)^((1+$F$27)^4.5))+SUM($H$19:$L$19)-$C$25+$C$24)/$C$27,"$0.00") -> 47.1% / $46.53
E30: Debt + Equity | F30: =C25+F24 -> 31229 | O30: =O29-0.005 -> 0.068055 | P30: =TEXT(((((((fcff*(1+P$26))/ABS($O30-P$26))/(1+$F$26)^((1+$F$27)^4.5))+SUM($H$19:$L$19)-$C$25+$C$24)/$C$27/$P$21)-1),"0.0%") &" / "& TEXT(((((fcff*(1+P$26))/ABS($O30-P$26))/(1+$F$26)^((1+$F$27)^4.5))+SUM($H$19:$L$19)-$C$25+$C$24)/$C$27,"$0.00") -> 7.3% / $33.93 | Q30: =TEXT(((((((fcff*(1+Q$26))/ABS($O30-Q$26))/(1+$F$26)^((1+$F$27)^4.5))+SUM($H$19:$L$19)-$C$25+$C$24)/$C$27/$P$21)-1),"0.0%") &" / "& TEXT(((((fcff*(1+Q$26))/ABS($O30-Q$26))/(1+$F$26)^((1+$F$27)^4.5))+SUM($H$19:$L$19)-$C$25+$C$24)/$C$27,"$0.00") -> 17.8% / $37.28 | R30: =TEXT(((((((fcff*(1+R$26))/ABS($O30-R$26))/(1+$F$26)^((1+$F$27)^4.5))+SUM($H$19:$L$19)-$C$25+$C$24)/$C$27/$P$21)-1),"0.0%") &" / "& TEXT(((((fcff*(1+R$26))/ABS($O30-R$26))/(1+$F$26)^((1+$F$27)^4.5))+SUM($H$19:$L$19)-$C$25+$C$24)/$C$27,"$0.00") -> 30.6% / $41.32 | S30: =TEXT(((((((fcff*(1+S$26))/ABS($O30-S$26))/(1+$F$26)^((1+$F$27)^4.5))+SUM($H$19:$L$19)-$C$25+$C$24)/$C$27/$P$21)-1),"0.0%") &" / "& TEXT(((((fcff*(1+S$26))/ABS($O30-S$26))/(1+$F$26)^((1+$F$27)^4.5))+SUM($H$19:$L$19)-$C$25+$C$24)/$C$27,"$0.00") -> 46.4% / $46.31 | T30: =TEXT(((((((fcff*(1+T$26))/ABS($O30-T$26))/(1+$F$26)^((1+$F$27)^4.5))+SUM($H$19:$L$19)-$C$25+$C$24)/$C$27/$P$21)-1),"0.0%") &" / "& TEXT(((((fcff*(1+T$26))/ABS($O30-T$26))/(1+$F$26)^((1+$F$27)^4.5))+SUM($H$19:$L$19)-$C$25+$C$24)/$C$27,"$0.00") -> 66.3% / $52.60
O31: =O30-0.005 -> 0.063055 | P31: =TEXT(((((((fcff*(1+P$26))/ABS($O31-P$26))/(1+$F$26)^((1+$F$27)^4.5))+SUM($H$19:$L$19)-$C$25+$C$24)/$C$27/$P$21)-1),"0.0%") &" / "& TEXT(((((fcff*(1+P$26))/ABS($O31-P$26))/(1+$F$26)^((1+$F$27)^4.5))+SUM($H$19:$L$19)-$C$25+$C$24)/$C$27,"$0.00") -> 17.3% / $37.09 | Q31: =TEXT(((((((fcff*(1+Q$26))/ABS($O31-Q$26))/(1+$F$26)^((1+$F$27)^4.5))+SUM($H$19:$L$19)-$C$25+$C$24)/$C$27/$P$21)-1),"0.0%") &" / "& TEXT(((((fcff*(1+Q$26))/ABS($O31-Q$26))/(1+$F$26)^((1+$F$27)^4.5))+SUM($H$19:$L$19)-$C$25+$C$24)/$C$27,"$0.00") -> 30.0% / $41.12 | R31: =TEXT(((((((fcff*(1+R$26))/ABS($O31-R$26))/(1+$F$26)^((1+$F$27)^4.5))+SUM($H$19:$L$19)-$C$25+$C$24)/$C$27/$P$21)-1),"0.0%") &" / "& TEXT(((((fcff*(1+R$26))/ABS($O31-R$26))/(1+$F$26)^((1+$F$27)^4.5))+SUM($H$19:$L$19)-$C$25+$C$24)/$C$27,"$0.00") -> 45.7% / $46.08 | S31: =TEXT(((((((fcff*(1+S$26))/ABS($O31-S$26))/(1+$F$26)^((1+$F$27)^4.5))+SUM($H$19:$L$19)-$C$25+$C$24)/$C$27/$P$21)-1),"0.0%") &" / "& TEXT(((((fcff*(1+S$26))/ABS($O31-S$26))/(1+$F$26)^((1+$F$27)^4.5))+SUM($H$19:$L$19)-$C$25+$C$24)/$C$27,"$0.00") -> 65.5% / $52.35 | T31: =TEXT(((((((fcff*(1+T$26))/ABS($O31-T$26))/(1+$F$26)^((1+$F$27)^4.5))+SUM($H$19:$L$19)-$C$25+$C$24)/$C$27/$P$21)-1),"0.0%") &" / "& TEXT(((((fcff*(1+T$26))/ABS($O31-T$26))/(1+$F$26)^((1+$F$27)^4.5))+SUM($H$19:$L$19)-$C$25+$C$24)/$C$27,"$0.00") -> 91.3% / $60.51

Sheet CCA
C2: Comparable Company Analysis | G2: CSX Corp. (CSX)
H4: Revenue (in million USDs) | K4: EBITDA (in million USDs) | M4: Net Income (in millions)
B5: Ticker | C5: Company | D5: Share Price | E5: nbr of Shares | F5: Enterprise Value | G5: Market Cap | H5: 2021 | I5: 2022 | J5: 2023 | K5: 2022 | L5: 2023 | M5: 2022 | N5: 2023
B6: WAB | C6: WAB Tech | D6: =DCF!P21 -> 31.63 | E6: =DCF!C27 -> 1976 | F6: =Summary!G9 -> 80543.05 | G6: =Summary!G5 -> 64016.05 | H6: =Summary!F11 -> 12522 | I6: =Summary!G11 -> 14853 | J6: =Summary!I11 -> 14614.154 | K6: =Summary!G15 -> 7394 | L6: =Summary!I15 -> 7149.182 | M6: =Summary!G17 -> 3907.98 | N6: =Summary!I17 -> 3695.192
B7: JBHT | C7: `J.B. Hunt | D7: 183.05 | E7: 103.14 | F7: 20250 | G7: 18800 | H7: 12168 | I7: 12341 | J7: 10900 | K7: 1331 | L7: 1778 | M7: 969 | N7: 776
B8: KTK | C8: KTK Group | D8: 1.31 | E8: 783 | F8: 1132 | G8: 1028 | H8: 588 | I8: 525.6 | J8: 523.7 | K8: 47.5 | L8: 52.9 | M8: 26.3 | N8: 35.2
B9: ODFL | C9: Old Dominion Freight Line | D9: 404.32 | E9: 109.11 | F9: 43990 | G9: 44120 | H9: 5256 | I9: 6260 | J9: 5862 | K9: 1842 | L9: 1655 | M9: 1377 | N9: 1240
B10: SRAIL | C10: Stadler Rail | D10: 35.92 | E10: 100 | F10: 3815 | G10: 3592 | H10: 3976 | I10: 3930 | J10: 4317 | K10: 322 | L10: 367 | M10: 75 | N10: 163
B11: CP | C11: Canadian Pacific | D11: 72.19 | E11: 932 | F11: 83310 | G11: 66540 | H11: 7995 | I11: 8814 | J11: 11241 | K11: 5650 | L11: -937 | M11: 3517 | N11: 4163
B12: CNR | C12: Canadian National Railways | D12: 157.24 | E12: 647.7 | F12: 120040 | G12: 101840 | H12: 14477 | I12: 17107 | J12: 16899 | K12: 9040 | L12: 8978 | M12: 5118 | N12: 4915
B13: NSC | C13: Norfolk Southern | D13: 199.07 | E13: 226.14 | F13: 60090 | G13: 45017 | H13: 11142 | I13: 12745 | J13: 12320 | K13: 6043 | L13: 4688 | M13: 3270 | N13: 2090
B14: TRN | C14: Trinity Industres | D14: 23.32 | E14: 81.87 | F14: 7580 | G14: 1909 | H14: 1516 | I14: 1977 | J14: 2451 | K14: 334 | L14: 658 | M14: 86 | N14: 94
B15: UNP | C15: Union Pacific | D15: 215.33 | E15: 609.6 | F15: 161370 | G15: 127650 | H15: 21804 | I15: 24875 | J15: 24140 | K15: 12589 | L15: 11860 | M15: 6998 | N15: 6365
B16: GET | C16: Getlink | D16: 16.09 | E16: 540 | F16: 12620 | G16: 8490 | H16: 774 | I16: 1606 | J16: 1962 | K16: 460 | L16: 617 | M16: 252 | N16: 358
B18: Ticker | C18: Revenue Growth | E18: EBITDA Margin | G18: Profit Margin | I18: EV / Revenue | K18: EV / EBITDA | M18: P / E
C19: 2022 | D19: 2023 | E19: 2022 | F19: 2023 | G19: 2022 | H19: 2023 | I19: 2022 | J19: 2023 | K19: 2022 | L19: 2023 | M19: 2022 | N19: 2023
B20: WAB | C20: =I6/H6-1 -> 0.18615237 | D20: =J6/I6-1 -> -0.016080657 | E20: =K6/I6 -> 0.49781189 | F20: =L6/J6 -> 0.48919575 | G20: =M6/I6 -> 0.26311048 | H20: =N6/J6 -> 0.25285022 | I20: =$F6/I6 -> 5.4226789 | J20: =$F6/J6 -> 5.5113043 | K20: =$F6/K6 -> 10.893028 | L20: =$F6/L6 -> 11.266051 | M20: =$G6/M6 -> 16.380854 | N20: =$G6/N6 -> 17.324147
B21: JBHT | C21: =I7/H7-1 -> 0.01421762 | D21: =J7/I7-1 -> -0.11676525 | E21: =K7/I7 -> 0.10785188 | F21: =L7/J7 -> 0.16311927 | G21: =M7/I7 -> 0.078518759 | H21: =N7/J7 -> 0.071192661 | I21: =$F7/I7 -> 1.6408719 | J21: =$F7/J7 -> 1.8577982 | K21: =$F7/K7 -> 15.214125 | L21: =$F7/L7 -> 11.389201 | M21: =$G7/M7 -> 19.401445 | N21: =$G7/N7 -> 24.226804
B22: KTK | C22: =I8/H8-1 -> -0.10612245 | D22: =J8/I8-1 -> -0.0036149163 | E22: =K8/I8 -> 0.090372907 | F22: =L8/J8 -> 0.10101203 | G22: =M8/I8 -> 0.050038052 | H22: =N8/J8 -> 0.067214054 | I22: =$F8/I8 -> 2.1537291 | J22: =$F8/J8 -> 2.1615429 | K22: =$F8/K8 -> 23.831579 | L22: =$F8/L8 -> 21.398866 | M22: =$G8/M8 -> 39.087452 | N22: =$G8/N8 -> 29.204545
B23: ODFL | C23: =I9/H9-1 -> 0.19101979 | D23: =J9/I9-1 -> -0.063578275 | E23: =K9/I9 -> 0.2942492 | F23: =L9/J9 -> 0.28232685 | G23: =M9/I9 -> 0.21996805 | H23: =N9/J9 -> 0.2115319 | I23: =$F9/I9 -> 7.0271565 | J23: =$F9/J9 -> 7.5042648 | K23: =$F9/K9 -> 23.88165 | L23: =$F9/L9 -> 26.58006 | M23: =$G9/M9 -> 32.040668 | N23: =$G9/N9 -> 35.580645
B24: SRAIL | C24: =I10/H10-1 -> -0.011569416 | D24: =J10/I10-1 -> 0.098473282 | E24: =K10/I10 -> 0.081933842 | F24: =L10/J10 -> 0.08501274 | G24: =M10/I10 -> 0.019083969 | H24: =N10/J10 -> 0.037757702 | I24: =$F10/I10 -> 0.97073791 | J24: =$F10/J10 -> 0.88371554 | K24: =$F10/K10 -> 11.847826 | L24: =$F10/L10 -> 10.395095 | M24: =$G10/M10 -> 47.893333 | N24: =$G10/N10 -> 22.03681
B25: CP | C25: =I11/H11-1 -> 0.10243902 | D25: =J11/I11-1 -> 0.27535739 | E25: =K11/I11 -> 0.64102564 | F25: =L11/J11 -> -0.083355573 | G25: =M11/I11 -> 0.39902428 | H25: =N11/J11 -> 0.37034072 | I25: =$F11/I11 -> 9.4520082 | J25: =$F11/J11 -> 7.4112623 | K25: =$F11/K11 -> 14.745133 | L25: =$F11/L11 -> -88.911419 | M25: =$G11/M11 -> 18.919534 | N25: =$G11/N11 -> 15.983666
B26: CNR | C26: =I12/H12-1 -> 0.18166747 | D26: =J12/I12-1 -> -0.012158765 | E26: =K12/I12 -> 0.52843865 | F26: =L12/J12 -> 0.53127404 | G26: =M12/I12 -> 0.29917578 | H26: =N12/J12 -> 0.29084561 | I26: =$F12/I12 -> 7.0170106 | J26: =$F12/J12 -> 7.1033789 | K26: =$F12/K12 -> 13.278761 | L26: =$F12/L12 -> 13.370461 | M26: =$G12/M12 -> 19.898398 | N26: =$G12/N12 -> 20.720244
B27: NSC | C27: =I13/H13-1 -> 0.14387004 | D27: =J13/I13-1 -> -0.03334641 | E27: =K13/I13 -> 0.47414672 | F27: =L13/J13 -> 0.38051948 | G27: =M13/I13 -> 0.2565712 | H27: =N13/J13 -> 0.16964286 | I27: =$F13/I13 -> 4.7147901 | J27: =$F13/J13 -> 4.8774351 | K27: =$F13/K13 -> 9.9437366 | L27: =$F13/L13 -> 12.817833 | M27: =$G13/M13 -> 13.766667 | N27: =$G13/N13 -> 21.539234
B28: TRN | C28: =I14/H14-1 -> 0.30408971 | D28: =J14/I14-1 -> 0.23975721 | E28: =K14/I14 -> 0.16894284 | F28: =L14/J14 -> 0.26846185 | G28: =M14/I14 -> 0.043500253 | H28: =N14/J14 -> 0.038351693 | I28: =$F14/I14 -> 3.8340921 | J28: =$F14/J14 -> 3.0926153 | K28: =$F14/K14 -> 22.694611 | L28: =$F14/L14 -> 11.519757 | M28: =$G14/M14 -> 22.197674 | N28: =$G14/N14 -> 20.308511
B29: UNP | C29: =I15/H15-1 -> 0.14084572 | D29: =J15/I15-1 -> -0.029547739 | E29: =K15/I15 -> 0.50609045 | F29: =L15/J15 -> 0.49130075 | G29: =M15/I15 -> 0.28132663 | H29: =N15/J15 -> 0.26367026 | I29: =$F15/I15 -> 6.4872362 | J29: =$F15/J15 -> 6.6847556 | K29: =$F15/K15 -> 12.818333 | L29: =$F15/L15 -> 13.606239 | M29: =$G15/M15 -> 18.240926 | N29: =$G15/N15 -> 20.054988
B30: GET | C30: =I16/H16-1 -> 1.0749354 | D30: =J16/I16-1 -> 0.22166874 | E30: =K16/I16 -> 0.2864259 | F30: =L16/J16 -> 0.31447503 | G30: =M16/I16 -> 0.15691158 | H30: =N16/J16 -> 0.18246687 | I30: =$F16/I16 -> 7.8580324 | J30: =$F16/J16 -> 6.432212 | K30: =$F16/K16 -> 27.434783 | L30: =$F16/L16 -> 20.453809 | M30: =$G16/M16 -> 33.690476 | N30: =$G16/N16 -> 23.715084
D32: 2023 Trading Multiple | G32: Enterprise Value | J32: Equity Value | M32: Implied Share Price
D33: Revenue | E33: EBITDA | F33: P/E | G33: Revenue | H33: EBITDA | I33: Net Income | J33: Revenue | K33: EBITDA | L33: Net Income | M33: Share Price
C34: Minimum | D34: =MIN(reve) -> 1.8577982 | E34: =MIN(ebi) -> 10.395095 | F34: =MIN(N20:N30) -> 15.983666 | G34: =D34*$J$6 -> 27150.148 | H34: =E34*$L$6 -> 74316.429 | I34: =N$6*F34 -> 59062.713 | J34: =G34+cash-debt -> 10633.148 | K34: =H34+cash-debt -> 57799.429 | L34: =I34+cash-debt -> 42545.713 | M34: =K34/E$6 -> 29.250723
C35: 1st Quartile | D35: =QUARTILE(reve,1) -> 3.5388202 | E35: =QUARTILE(ebi,1) -> 11.42184 | F35: =QUARTILE(N20:N30,1) -> 20.181749 | G35: =D35*$J$6 -> 51716.864 | H35: =E35*$L$6 -> 81656.815 | I35: =N$6*F35 -> 74575.439 | J35: =G35+cash-debt -> 35199.864 | K35: =H35+cash-debt -> 65139.815 | L35: =I35+cash-debt -> 58058.439 | M35: =K35/E$6 -> 32.965493
C36: Lower Limit 75% | D36: =D37-0.674*_xlfn.STDEV.S(reve)/SQRT(11) -> 4.8217943 | E36: =E37-0.674*_xlfn.STDEV.S(ebi)/SQRT(11) -> 14.15914 | F36: =F37-0.674*_xlfn.STDEV.S(N20:N30)/SQRT(11) -> 21.670098 | G36: =D36*$J$6 -> 70466.445 | H36: =E36*$L$6 -> 101226.27 | I36: =N$6*F36 -> 80075.172 | J36: =G36+cash-debt -> 53949.445 | K36: =H36+cash-debt -> 84709.268 | L36: =I36+cash-debt -> 63558.172 | M36: =K36/E$6 -> 42.869063
C37: Mean | D37: =AVERAGE(reve) -> 5.2636569 | E37: =AVERAGE(ebi) -> 15.279737 | F37: =AVERAGE(N20:N30) -> 22.790425 | G37: =D37*$J$6 -> 76923.893 | H37: =E37*$L$6 -> 109237.62 | I37: =N$6*F37 -> 84214.997 | J37: =G37+cash-debt -> 60406.893 | K37: =H37+cash-debt -> 92720.623 | L37: =I37+cash-debt -> 67697.997 | M37: =K37/E$6 -> 46.923392
C38: Upper Limit 75% | D38: =D37+0.674*_xlfn.STDEV.S(reve)/SQRT(11) -> 5.7055195 | E38: =E37+0.674*_xlfn.STDEV.S(ebi)/SQRT(11) -> 16.400335 | F38: =F37+0.674*_xlfn.STDEV.S(N20:N30)/SQRT(11) -> 23.910753 | G38: =D38*$J$6 -> 83381.341 | H38: =E38*$L$6 -> 117248.98 | I38: =N$6*F38 -> 88354.823 | J38: =G38+cash-debt -> 66864.341 | K38: =H38+cash-debt -> 100731.98 | L38: =I38+cash-debt -> 71837.823 | M38: =K38/E$6 -> 50.977721
C39: 3rd Quartile | D39: =QUARTILE(reve,3) -> 6.9987231 | E39: =QUARTILE(ebi,3) -> 18.741916 | F39: =QUARTILE(N20:N30,3) -> 23.970944 | G39: =D39*$J$6 -> 102280.42 | H39: =E39*$L$6 -> 133989.37 | I39: =N$6*F39 -> 88577.24 | J39: =G39+cash-debt -> 85763.417 | K39: =H39+cash-debt -> 117472.37 | L39: =I39+cash-debt -> 72060.24 | M39: =K39/E$6 -> 59.449581
C40: Maximum | D40: =MAX(J21:J30) -> 7.5042648 | E40: =MAX(L21:L30) -> 26.58006 | F40: =MAX(N20:N30) -> 35.580645 | G40: =D40*$J$6 -> 109668.48 | H40: =E40*$L$6 -> 190025.69 | I40: =N$6*F40 -> 131477.32 | J40: =G40+cash-debt -> 93151.481 | K40: =H40+cash-debt -> 173508.69 | L40: =I40+cash-debt -> 114960.32 | M40: =K40/E$6 -> 87.808041

Sheet Summary
A1: CSX Corp (CSX US) - BBG Adj Highlights | O1: CSX Corp (CSX US) - Growth | BA1: CSX Corp (CSX US) - L#1518025
A3: In Millions of USD | C3: FY 2018 | D3: FY 2019 | E3: FY 2020 | F3: FY 2021 | G3: FY 2022 | H3: Current/LTM | I3: FY 2023 Est | J3: FY 2024 Est | O3: In Millions of USD except Per Share | Q3: FY 1988 | R3: FY 1989 | S3: FY 1990 | T3: FY 1991 | U3: FY 1992 | V3: FY 1993 | W3: FY 1994 | X3: FY 1995 | Y3: FY 1996 | Z3: FY 1997 | AA3: FY 1998 | AB3: FY 1999 | AC3: FY 2000 | AD3: FY 2001 | AE3: FY 2002 | AF3: FY 2003 | AG3: FY 2004 | AH3: FY 2005 | AI3: FY 2006 | AJ3: FY 2007 | AK3: FY 2008 | AL3: FY 2009 | AM3: FY 2010 | AN3: FY 2011 | AO3: FY 2012 | AP3: FY 2013 | AQ3: FY 2014 | AR3: FY 2015 | AS3: FY 2016 | AT3: FY 2017 | AU3: FY 2018 | AV3: FY 2019 | AW3: FY 2020 | AX3: FY 2021 | AY3: FY 2022 | BA3: WACC History | BC3: FY 2022 | BD3: FY 2021 | BE3: FY 2020 | BF3: FY 2019 | BG3: FY 2018 | BH3: FY 2017 | BI3: FY 2016 | BJ3: FY 2015 | BK3: FY 2014 | BL3: FY 2013 | BM3: FY 2012 | BN3: FY 2011 | BO3: FY 2010 | BP3: FY 2009 | BQ3: FY 2008 | BR3: FY 2007 | BS3: FY 2006 | BT3: FY 2005 | BU3: FY 2004 | BV3: FY 2003
A4: 12 Months Ending | C4: 12/31/2018 | D4: 12/31/2019 | E4: 12/31/2020 | F4: 12/31/2021 | G4: 12/31/2022 | H4: 09/30/2023 | I4: 12/31/2023 | J4: 12/31/2024 | O4: 12 Months Ending | Q4: 12/31/1988 | R4: 12/31/1989 | S4: 12/31/1990 | T4: 12/31/1991 | U4: 12/31/1992 | V4: 12/31/1993 | W4: 12/30/1994 | X4: 12/30/1995 | Y4: 12/31/1996 | Z4: 12/26/1997 | AA4: 12/31/1998 | AB4: 12/31/1999 | AC4: 12/29/2000 | AD4: 12/28/2001 | AE4: 12/27/2002 | AF4: 12/26/2003 | AG4: 12/31/2004 | AH4: 12/30/2005 | AI4: 12/29/2006 | AJ4: 12/28/2007 | AK4: 12/26/2008 | AL4: 12/25/2009 | AM4: 12/31/2010 | AN4: 12/30/2011 | AO4: 12/28/2012 | AP4: 12/27/2013 | AQ4: 12/26/2014 | AR4: 12/25/2015 | AS4: 12/30/2016 | AT4: 12/31/2017 | AU4: 12/31/2018 | AV4: 12/31/2019 | AW4: 12/31/2020 | AX4: 12/31/2021 | AY4: 12/31/2022 | BA4: 12 Months Ending | BC4: 12/31/2022 | BD4: 12/31/2021 | BE4: 12/31/2020 | BF4: 12/31/2019 | BG4: 12/31/2018 | BH4: 12/31/2017 | BI4: 12/30/2016 | BJ4: 12/25/2015 | BK4: 12/26/2014 | BL4: 12/27/2013 | BM4: 12/28/2012 | BN4: 12/30/2011 | BO4: 12/31/2010 | BP4: 12/25/2009 | BQ4: 12/26/2008 | BR4: 12/28/2007 | BS4: 12/29/2006 | BT4: 12/30/2005 | BU4: 12/31/2004 | BV4: 12/26/2003
A5: Market Capitalization | B5: HISTORICAL_MARKET_CAP | C5: 50833.523 | D5: 55968.362 | E5: 207598.52 | F5: 82787.191 | G5: 64016.05 | H5: 63866.579 | O5: 1 Year Growth | Q5: {=GEOMEAN(Q6:AY6/100+1)-1} -> 0.017680203 | BA5: Equity
A6: - Cash & Equivalents | B6: CASH_AND_MARKETABLE_SECURITIES | C6: 1111 | D6: 1954 | E6: 3131 | F6: 2316 | G6: 2087 | H6: 1439 | O6: Revenue | P6: SALES_GROWTH | Q6: -5.6074 | R6: 2.0153 | S6: 5.9393 | T6: 5.2529 | U6: 1.1348 | V6: 2.3586 | W6: 7.472 | X6: 9.3256 | Y6: 0.3046 | Z6: 0.8068 | AA6: -7.0897 | AB6: 5.1378 | AC6: -21.0506 | AD6: -0.9889 | AE6: 0.5179 | AF6: -7.1884 | AG6: 6.2649 | AH6: 7.1891 | AI6: 11.0002 | AJ6: 4.8505 | AK6: 12.2134 | AL6: -19.6713 | AM6: 17.6419 | AN6: 10.897 | AO6: -0.3306 | AP6: 2.2967 | AQ6: 5.3467 | AR6: -6.7724 | AS6: -6.2823 | AT6: 3.0626 | AU6: 7.3808 | AV6: -2.5551 | AW6: -11.3429 | AX6: 18.3218 | AY6: 18.6152 | BA6: Cost of Equity | BB6: WACC_COST_EQUITY | BC6: 8.23 | BD6: 9.9753 | BE6: 8.8113 | BF6: 9.0663 | BG6: 11.8505 | BH6: 10.1221 | BI6: 10.5031 | BJ6: 10.7549 | BK6: 9.9474 | BL6: 11.2585 | BM6: 12.3654 | BN6: 13.0941 | BO6: 15.0257 | BP6: 11.5097 | BQ6: 11.7515 | BR6: 11.9134 | BS6: 11.6332 | BT6: 10.9957 | BU6: 9.3144 | BV6: 9.0797
A7: + Preferred & Other | B7: PFD_EQTY_MINORTY_INTEREST | C7: 17 | D7: 15 | E7: 9 | F7: 10 | G7: 10 | H7: 4 | O7: EBITDA | P7: EBITDA_GROWTH | Q7: -4.378 | R7: -4.3605 | S7: -2.1277 | T7: 5.2019 | U7: 10.1107 | V7: -0.4692 | W7: 21.8182 | X7: 12.1614 | Y7: 5.5692 | Z7: 6.0224 | AA7: -22.5011 | AB7: -32.1591 | AC7: 17.6717 | AD7: 12.3843 | AE7: 12.4763 | AF7: -34.5158 | AG7: 48.7532 | AH7: 37.7457 | AI7: 26.1016 | AJ7: 4.6922 | AK7: 17.1647 | AL7: -13.9175 | AM7: 26.6309 | AN7: 10.6521 | AO7: 1.5744 | AP7: 1.3508 | AQ7: 4.0856 | AR7: 0.5877 | AS7: -2.1285 | AT7: 7.3561 | AU7: 23.138 | AV7: 3.1935 | AW7: -8.9247 | AX7: 21.8981 | AY7: 7.4476 | BA7: Weight of Equity | BB7: WACC_WEIGHT_OF_EQUITY | BC7: 77.4825 | BD7: 83.0403 | BE7: 92.3467 | BF7: 76.9257 | BG7: 77.5013 | BH7: 80.5644 | BI7: 74.7035 | BJ7: 70.5429 | BK7: 78.8739 | BL7: 74.9184 | BM7: 66.851 | BN7: 70.5102 | BO7: 73.3986 | BP7: 71.21 | BQ7: 61.0998 | BR7: 71.3311 | BS7: 71.6557 | BT7: 64.7537 | BU7: 54.0901 | BV7: 51.1861
A8: + Total Debt | B8: SHORT_AND_LONG_TERM_DEBT | C8: 14757 | D8: 16788 | E8: 17205 | F8: 16908 | G8: 18604 | H8: 18949 | O8: Operating Income | P8: OPER_INC_GROWTH | Q8: 1.5642 | R8: -4.4004 | S8: -6.214 | T8: 4.7853 | U8: 12.9977 | V8: -5.3886 | W8: 34.9398 | X8: 15.9903 | Y8: 6.508 | Z8: 4.0079 | AA8: -28.6166 | AB8: -49.292 | AC8: 40.4887 | AD8: 18.882 | AE8: 17.7638 | AF8: -53.8598 | AG8: 92.3077 | AH8: 55 | AI8: 37.9355 | AJ8: 5.5192 | AK8: 22.695 | AL8: -17.9913 | AM8: 35.2863 | AN8: 12.9925 | AO8: -0.3746 | AP8: 0.4628 | AQ8: 4.0311 | AR8: -0.8027 | AS8: -5.4408 | AT8: 9.7669 | AU8: 30.8871 | AV8: 1.9717 | AW8: -12.145 | AX8: 28.2439 | AY8: 7.6689 | BA8: + Debt
A9: Enterprise Value | B9: ENTERPRISE_VALUE | C9: 64496.523 | D9: 70817.362 | E9: 221681.52 | F9: 97389.191 | G9: 80543.05 | H9: 81380.579 | O9: Net Income to Common | P9: EARN_FOR_COM_GROWTH | Q9: 0.7353 | R9: 220.438 | S9: -7.2893 | T9: — | U9: — | V9: 1695 | W9: 81.6156 | X9: -5.2147 | Y9: 38.3495 | Z9: -6.5497 | AA9: -32.791 | AB9: -99.6276 | AC9: 28150 | AD9: -48.1416 | AE9: 44.7099 | AF9: -41.9811 | AG9: 37.8049 | AH9: 237.7581 | AI9: 14.4105 | AJ9: 1.9847 | AK9: 2.1707 | AL9: -16.2637 | AM9: 36.7454 | AN9: 18.682 | AO9: 0.2156 | AP9: 0.2152 | AQ9: 3.3816 | AR9: 2.1288 | AS9: -12.9131 | AT9: 219.3228 | AU9: -39.5247 | AV9: 0.6953 | AW9: -16.9919 | AX9: 36.745 | AY9: 10.1825 | BA9: Cost of Debt | BB9: WACC_COST_DEBT | BC9: 4.1244 | BD9: 1.5807 | BE9: 0.9397 | BF9: 2.0369 | BG9: 2.8496 | BH9: 3.3206 | BI9: 2.079 | BJ9: 1.9388 | BK9: 1.936 | BL9: 2.5144 | BM9: 1.4206 | BN9: 1.6093 | BO9: 2.8116 | BP9: 3.5887 | BQ9: 1.9549 | BR9: 3.7171 | BS9: 4.7908 | BT9: 4.3609 | BU9: 3.7945 | BV9: 4.0281
O10: EPS Diluted | P10: DILUTED_EPS_AFT_XO_ITEMS_GROWTH | Q10: 5.6818 | R10: 366.6667 | S10: -4.3779 | T10: — | U10: — | V10: 1721.0526 | W10: 80.0578 | X10: -5.618 | Y10: 34.6939 | Z10: -6.0606 | AA10: -32.5269 | AB10: -99.6016 | AC10: 26600 | AD10: -48.3146 | AE10: 44.2029 | AF10: -44.2211 | AG10: 36.9369 | AH10: 231.5789 | AI10: 11.9048 | AJ10: 6.0284 | AK10: 11.7057 | AL10: -13.4731 | AM10: 40.1384 | AN10: 25.9259 | AO10: 5.2941 | AP10: 2.2346 | AQ10: 4.918 | AR10: 4.1667 | AS10: -9.5 | AT10: 230.9392 | AU10: -35.8932 | AV10: 8.5938 | AW10: -71.223 | AX10: 320 | AY10: 16.0714 | BA10: Weight of Debt | BB10: WACC_WEIGHT_OF_DEBT | BC10: 22.5175 | BD10: 16.9597 | BE10: 7.6533 | BF10: 23.0743 | BG10: 22.4987 | BH10: 19.4356 | BI10: 25.2965 | BJ10: 29.4571 | BK10: 21.1261 | BL10: 25.0816 | BM10: 33.149 | BN10: 29.4898 | BO10: 26.6014 | BP10: 28.79 | BQ10: 38.9002 | BR10: 28.6689 | BS10: 28.3443 | BT10: 35.2463 | BU10: 45.9099 | BV10: 48.8139
A11: Revenue, Adj | B11: SALES_REV_TURN | C11: 12250 | D11: 11937 | E11: 10583 | F11: 12522 | G11: 14853 | H11: 14707 | I11: 14614.154 | J11: 14995.846 | O11: EPS Diluted before XO | P11: DILUTED_EPS_BEF_XO_ITEMS_GROWTH | Q11: — | R11: — | S11: -11.2469 | T11: — | U11: — | V11: 1721.0526 | W11: 80.0578 | X11: -5.618 | Y11: 34.6939 | Z11: -6.0606 | AA11: -32.5269 | AB11: -90.4382 | AC11: 265.1921 | AD11: 57.4514 | AE11: 58.6957 | AF11: -71.2329 | AG11: 196.8254 | AH11: 69.5187 | AI11: 77.918 | AJ11: -2.8369 | AK11: 33.5766 | AL11: -22.1311 | AM11: 42.1053 | AN11: 25.9259 | AO11: 5.2941 | AP11: 2.2346 | AQ11: 4.918 | AR11: 4.1667 | AS11: -9.5 | AT11: 230.9392 | AU11: -35.8932 | AV11: 8.5938 | AW11: -71.223 | AX11: 320 | AY11: 16.0714 | BA11: + Preferred Equity
A12: Growth %, YoY | B12: SALES_GROWTH | C12: 7.3808 | D12: -2.5551 | E12: -11.3429 | F12: 18.3218 | G12: 18.6152 | H12: 1.0790378 | I12: -1.6080657 | J12: 2.6117968 | O12: EPS Diluted before Abnormal | P12: RR_DIL_EPS_CONT_OPS_GROWTH | Q12: — | R12: — | S12: -11.2469 | T12: — | U12: — | V12: 1721.0526 | W12: 80.0578 | X12: -5.618 | Y12: 34.6939 | Z12: 5.303 | AA12: -52.0384 | AB12: -92.5 | AC12: 486.6667 | AD12: 56.8182 | AE12: 44.2029 | AF12: -42.7136 | AG12: 64.0351 | AH12: 69.5187 | AI12: 77.918 | AJ12: -4.2553 | AK12: 35.5556 | AL12: -22.1311 | AM12: 45.3434 | AN12: 23.1204 | AO12: -0.625 | AP12: 5.0118 | AQ12: 10.2385 | AR12: -0.7736 | AS12: -7.2455 | AT12: 24.7399 | AU12: 65.4584 | AV12: 7.7674 | AW12: -70.326 | AX12: 279.1495 | AY12: 21.849 | BA12: Cost of Pref. Equity | BB12: WACC_COST_PFD | BC12: 0 | BD12: 0 | BE12: 0 | BF12: 0 | BG12: 0 | BH12: 0 | BI12: 0 | BJ12: 0 | BK12: 0 | BL12: 0 | BM12: 0 | BN12: 0 | BO12: 0 | BP12: 0 | BQ12: 0 | BR12: 0 | BS12: 0 | BT12: 0 | BU12: 0 | BV12: 0
A13: Gross Profit, Adj | B13: GROSS_PROFIT | C13: — | D13: — | E13: — | F13: — | G13: — | I13: 5557.1782 | J13: 5787.6468 | O13: Dividend per Share | P13: DIVIDEND_PER_SHARE_1_YEAR_GROWTH | Q13: 11.2069 | R13: -0.7752 | S13: 9.375 | T13: 2.1429 | U13: 6.2937 | V13: 3.9474 | W13: 11.3924 | X13: 4.5455 | Y13: 13.0435 | Z13: 3.8462 | AA13: 11.1111 | AB13: 0 | AC13: 0 | AD13: -33.3333 | AE13: -50 | AF13: 0 | AG13: 0 | AH13: 7.5 | AI13: 53.4884 | AJ13: 63.6364 | AK13: 42.5926 | AL13: 14.2857 | AM13: 12.5 | AN13: 36.3636 | AO13: 20 | AP13: 9.2593 | AQ13: 6.7797 | AR13: 11.1111 | AS13: 2.8571 | AT13: 8.3333 | AU13: 12.8205 | AV13: 227.2727 | AW13: -87.9167 | AX13: 220.6896 | AY13: 7.5269 | BA13: Weight of Pref. Equity | BB13: WACC_WEIGHT_OF_PREFERRED_EQUITY | BC13: 0 | BD13: 0 | BE13: 0 | BF13: 0 | BG13: 0 | BH13: 0 | BI13: 0 | BJ13: 0 | BK13: 0 | BL13: 0 | BM13: 0 | BN13: 0 | BO13: 0 | BP13: 0 | BQ13: 0 | BR13: 0 | BS13: 0 | BT13: 0 | BU13: 0 | BV13: 0
A14: Margin % | B14: GROSS_PROFIT | C14: — | D14: — | E14: — | F14: — | G14: — | I14: 38.026 | J14: 38.595 | BA14: WACC | BB14: WACC | BC14: 7.3055 | BD14: 8.5516 | BE14: 8.2089 | BF14: 7.4443 | BG14: 9.8254 | BH14: 8.8002 | BI14: 8.3721 | BJ14: 8.158 | BK14: 8.2549 | BL14: 9.0653 | BM14: 8.7373 | BN14: 9.7072 | BO14: 11.7766 | BP14: 9.2292 | BQ14: 7.9406 | BR14: 9.5636 | BS14: 9.6938 | BT14: 8.6572 | BU14: 6.7802 | BV14: 6.6139
A15: EBITDA, Adj | B15: EBITDA | C15: 6046 | D15: 6269 | E15: 5792 | F15: 6649 | G15: 7394 | H15: 7206 | I15: 7149.182 | J15: 7417.5 | O15: Accounts Receivable | P15: ACCOUNTS_RECEIVABLE_GROWTH | Q15: 2.2831 | R15: -28.0134 | S15: 12.8682 | T15: 0 | U15: -16.8956 | V15: 10.4132 | W15: 5.6886 | X15: 17.847 | Y15: 7.4519 | Z15: 10.4027 | AA15: -9.0172 | AB15: 26.392 | AC15: -25.1101 | AD15: 3.2941 | AE15: -8.9977 | AF15: 45.5569 | AG15: -0.3439 | AH15: 3.7101 | AI15: -2.3295 | AJ15: 0 | AK15: -5.707 | AL15: -10.1174 | AM15: -0.201 | AN15: 0.7049 | AO15: -3.8 | AP15: 9.3555 | AQ15: 7.3194 | AR15: -13.0204 | AS15: -4.4807 | AT15: 3.4115 | AU15: 4.1237 | AV15: -2.3762 | AW15: -7.5051 | AX15: 25.8772 | AY15: 14.3728
A16: Margin % | B16: EBITDA | C16: 49.355102 | D16: 52.517383 | E16: 54.729283 | F16: 53.098547 | G16: 49.781189 | H16: 48.997076 | I16: 48.919575 | J16: 49.463698 | O16: Inventory | P16: INVENTORY_GROWTH | Q16: -33.6088 | R16: -1.6598 | S16: 8.4388 | T16: -19.8444 | U16: -8.2524 | V16: 5.291 | W16: 6.0302 | X16: 4.2654 | Y16: 4.0909 | Z16: -0.8734 | AA16: -0.8811 | AB16: -2.2222 | AC16: 11.3636 | AD16: -15.9184 | AE16: -12.6214 | AF16: -5.5556 | AG16: -2.9412 | AH16: 20.6061 | AI16: 2.5126 | AJ16: 17.6471 | AK16: -9.5833 | AL16: -6.4516 | AM16: 7.3892 | AN16: 10.0917 | AO16: 14.1667 | AP16: -8.0292 | AQ16: 8.3333 | AR16: 28.2051 | AS16: 16.2857 | AT16: -8.5995 | AU16: -29.3011 | AV16: -0.7605 | AW16: 15.7088 | AX16: 12.2517 | AY16: 0.59 | BA16: Capital Structure | BV16: {=GEOMEAN(BC15:BR15/100+1)-1} -> 0
A17: Net Income, Adj | B17: EARN_FOR_COMMON | C17: 3200.34 | D17: 3198.09 | E17: 2737.35 | F17: 3378.34 | G17: 3907.98 | H17: 3750.01 | I17: 3695.192 | J17: 3837.577 | O17: Fixed Assets | P17: NET_FIXED_ASSETS_1_YEAR_GROWTH | Q17: -5.2253 | R17: 0.218 | S17: 3.5122 | T17: 1.8617 | U17: 4.5102 | V17: 1.4291 | W17: 2.373 | X17: 2.2908 | Y17: 5.3908 | Z17: 4.1996 | AA17: 1.9265 | AB17: -3.0684 | AC17: 3.1411 | AD17: 2.6103 | AE17: 2.4206 | AF17: 3.3419 | AG17: 45.2658 | AH17: 1.093 | AI17: 3.7693 | AJ17: 4.096 | AK17: 4.169 | AL17: 1.6573 | AM17: 3.1868 | AN17: 4.9372 | AO17: 4.3085 | AP17: 4.7639 | AQ17: 4.7378 | AR17: 5.5626 | AS17: 3.2346 | AT17: 1.9711 | AU17: 0.7367 | AV17: 2.1939 | AW17: 0.6606 | AX17: 1.8228 | AY17: 3.6729 | BA17: + Historical Market Cap | BB17: HISTORICAL_MARKET_CAP | BC17: 64016.05 | BD17: 82787.191 | BE17: 207598.52 | BF17: 55968.362 | BG17: 50833.523 | BH17: 48950.704 | BI17: 33349.507 | BJ17: 25228.881 | BK17: 36371.558 | BL17: 28540.649 | BM17: 19828.024 | BN17: 22095.246 | BO17: 23905.7 | BP17: 19807.2 | BQ17: 12301.569 | BR17: 18056.139 | BS17: 15072.215 | BT17: 11078.166 | BU17: 8638.4023 | BV17: 7669.4319
A18: Margin % | B18: EARN_FOR_COMMON | C18: 26.125224 | D18: 26.791405 | E18: 25.865539 | F18: 26.979237 | G18: 26.311048 | H18: 25.49813 | I18: 25.285022 | J18: 25.590934 | O18: Total Assets | P18: ASSET_GROWTH | Q18: -1.5494 | R18: -5.5888 | S18: 4.1145 | T18: -0.0469 | U18: 1.9612 | V18: 2.8431 | W18: 2.2653 | X18: 4.0659 | Y18: 18.7859 | Z18: 17.6363 | AA18: 2.3551 | AB18: 1.4344 | AC18: -1.1052 | AD18: 1.5129 | AE18: 0.7211 | AF18: 3.8614 | AG18: 13.0744 | AH18: -1.516 | AI18: 3.7017 | AJ18: 1.6117 | AK18: 2.9529 | AL18: 2.2786 | AM18: 4.664 | AN18: 4.2749 | AO18: 4.1814 | AP18: 3.9613 | AQ18: 3.9991 | AR18: 5.1191 | AS18: 1.9255 | AT18: 0.9177 | AU18: 2.7701 | AV18: 4.1602 | AW18: 4.015 | AX18: 1.8546 | AY18: 3.4073 | BA18: + Short Term Debt | BB18: BS_ST_BORROW | BC18: 220 | BD18: 245 | BE18: 446 | BF18: 302 | BG18: 18 | BH18: 19 | BI18: 331 | BJ18: 20 | BK18: 228 | BL18: 533 | BM18: 780 | BN18: 507 | BO18: 613 | BP18: 113 | BQ18: 320 | BR18: 787 | BS18: 600 | BT18: 937 | BU18: 1084 | BV18: 428
A19: EPS, Adj | B19: IS_DIL_EPS_CONT_OPS | C19: 1.2383 | D19: 1.3345 | E19: 0.396 | F19: 1.5014 | G19: 1.8295 | H19: 1.83146 | I19: 1.833 | J19: 1.984 | O19: Modified Working Capital | P19: MODIFIED_WORK_CAP_GROWTH | Q19: -30.4167 | R19: -92.8144 | S19: — | T19: — | U19: — | V19: 53.271 | W19: 82 | X19: -666.6667 | Y19: 4.3478 | Z19: — | AA19: — | AB19: — | AC19: -89.8734 | AD19: 637.5 | AE19: 50 | AF19: 185.8757 | AG19: -10.2767 | AH19: -1.5419 | AI19: -9.6197 | AJ19: 8.4158 | AK19: -19.863 | AL19: -34.188 | AM19: -28.5714 | AN19: 34.5455 | AO19: 0 | AP19: 56.3063 | AQ19: 60.5187 | AR19: 1.9749 | AS19: -5.1056 | AT19: -8.1633 | AU19: -34.5455 | AV19: -37.037 | AW19: 98.5294 | AX19: 29.3827 | AY19: 0 | BA19: + Long Term Debt | BB19: BS_LT_BORROW | BC19: 18384 | BD19: 16663 | BE19: 16759 | BF19: 16486 | BG19: 14739 | BH19: 11790 | BI19: 10962 | BJ19: 10515 | BK19: 9514 | BL19: 9022 | BM19: 9052 | BN19: 8734 | BO19: 8051 | BP19: 7895 | BQ19: 7512 | BR19: 6470 | BS19: 5362 | BT19: 5093 | BU19: 6248 | BV19: 6886
A20: Growth %, YoY | B20: IS_DIL_EPS_CONT_OPS | C20: 65.458561 | D20: 7.7673784 | E20: -70.326001 | F20: 279.1498 | G20: 21.849002 | H20: 3.2091622 | I20: 0.19207581 | J20: 8.2378614 | O20: Working Capital | P20: WORK_CAP_GROWTH | Q20: — | R20: 0.9585 | S20: 6.7742 | T20: -62.9758 | U20: 8.811 | V20: 18.0442 | W20: -19.3182 | X20: -25.7143 | Y20: 35.1326 | Z20: 22.3358 | AA20: -15.7895 | AB20: -47.7273 | AC20: -35.6044 | AD20: 0.4052 | AE20: 45.891 | AF20: 53.8346 | AG20: -2.2801 | AH20: -93.3121 | AI20: — | AJ20: — | AK20: 92.7778 | AL20: — | AM20: -54.8936 | AN20: -22.0126 | AO20: -29.8387 | AP20: 2.2989 | AQ20: 161.236 | AR20: 90.9677 | AS20: -49.6622 | AT20: -95.302 | AU20: 2995.2381 | AV20: 73.3846 | AW20: 114.9068 | AX20: -32.2874 | AY20: -15.9756 | BA20: + Preferred Equity and Hybrid Capital | BB20: PFD_EQTY_HYBRID_CAPITAL | BC20: 0 | BD20: 0 | BE20: 0 | BF20: 0 | BG20: 0 | BH20: 0 | BI20: 0 | BJ20: 0 | BK20: 0 | BL20: 0 | BM20: 0 | BN20: 0 | BO20: 0 | BP20: 0 | BQ20: 0 | BR20: — | BS20: 0 | BT20: 0 | BU20: 0 | BV20: 0
O21: Employees | P21: EMPL_GROWTH | Q21: -3.3611 | R21: -1.6139 | S21: -3.1264 | T21: -2.9162 | U21: -4.6839 | V21: -1.124 | W21: -9.738 | X21: 10.6403 | Y21: 0.6681 | Z21: -0.8518 | AA21: -1.6286 | AB21: — | AC21: — | AD21: -3.8717 | AE21: — | AF21: — | AG21: -4.4488 | AH21: -2.3628 | AI21: 2.8571 | AJ21: -2.7778 | AK21: -2.8571 | AL21: -11.5059 | AM21: -0.2925 | AN21: 3.3333 | AO21: 3.2258 | AP21: -3.125 | AQ21: 3.2258 | AR21: -9.375 | AS21: -6.8966 | AT21: -11.1111 | AU21: -6.25 | AV21: -6.6667 | AW21: -8.181 | AX21: 8.4898 | AY21: 7.7585 | BA21: Total Capital | BB21: WACC_TOTAL_CAPITAL | BC21: 82620.05 | BD21: 99695.191 | BE21: 224803.52 | BF21: 72756.362 | BG21: 65590.523 | BH21: 60759.704 | BI21: 44642.507 | BJ21: 35763.881 | BK21: 46113.558 | BL21: 38095.649 | BM21: 29660.024 | BN21: 31336.246 | BO21: 32569.7 | BP21: 27815.2 | BQ21: 20133.569 | BR21: 25313.139 | BS21: 21034.214 | BT21: 17108.166 | BU21: 15970.402 | BV21: 14983.432
A22: Cash from Operations | B22: CF_CASH_FROM_OPER | C22: 4641 | D22: 4850 | E22: 4263 | F22: 5099 | G22: 5619 | H22: 5413 | O22: Accounts Payable | P22: ACCOUNTS_PAYABLE_GROWTH_1YR | Q22: 5.7971 | R22: 6.8493 | S22: 20.2797 | T22: -10.2713 | U22: -2.6998 | V22: 1.7758 | W22: 0.9815 | X22: 21.0583 | Y22: 6.066 | Z22: -0.841 | AA22: 3.1383 | AB22: -1.5625 | AC22: -9.858 | AD22: -10.4727 | AE22: -16.9772 | AF22: 3.1172 | AG22: 5.1995 | AH22: 9.6552 | AI22: 2.0964 | AJ22: 0.2053 | AK22: -0.3074 | AL22: -0.6166 | AM22: 8.1696 | AN22: -2.6769 | AO22: -0.3929 | AP22: -5.6213 | AQ22: -11.7032 | AR22: -9.5858 | AS22: 5.4974 | AT22: 5.0868 | AU22: 12.0425 | AV22: 9.9052 | AW22: -22.4353 | AX22: 19.0358 | AY22: 17.3416
A23: Capital Expenditures | B23: CAPITAL_EXPEND | C23: -1745 | D23: -1657 | E23: -1626 | F23: -1791 | G23: -2133 | H23: -2286 | I23: -2279.619 | J23: -2244.048 | O23: Short-Term Debt | P23: SHORT_TERM_DEBT_1_YEAR_GROWTH | Q23: 270.2786 | R23: -61.204 | S23: -23.0603 | T23: 11.4846 | U23: -46.2312 | V23: 44.8598 | W23: 65.4839 | X23: 23.5867 | Y23: -31.2303 | Z23: -18.578 | AA23: -19.1549 | AB23: 221.6028 | AC23: -0.2167 | AD23: 37.785 | AE23: -57.9196 | AF23: -19.8502 | AG23: 153.271 | AH23: -13.5609 | AI23: -35.9658 | AJ23: 31.1667 | AK23: -59.3393 | AL23: -64.6875 | AM23: 442.4779 | AN23: -17.292 | AO23: 53.8462 | AP23: -31.6667 | AQ23: -57.2233 | AR23: -91.2281 | AS23: 1555 | AT23: -94.2598 | AU23: -5.2632 | AV23: 1577.7778 | AW23: 47.6821 | AX23: -45.0673 | AY23: -10.2041 | BA23: EVA
A24: Free Cash Flow | B24: CF_FREE_CASH_FLOW | C24: 2896 | D24: 3193 | E24: 2637 | F24: 3308 | G24: 3486 | H24: 3127 | I24: 3130.927 | J24: 3480.17 | O24: Total Debt | P24: TOTAL_DEBT_1_YEAR_GROWTH | Q24: 21.3199 | R24: -24.527 | S24: 5.9856 | T24: -5.3223 | U24: 8.0262 | V24: -0.4626 | W24: -9.0619 | X24: -8.7831 | Y24: 66.9118 | Z24: 42.039 | AA24: -0.768 | AB24: 5.9533 | AC24: -5.4502 | AD24: 5.601 | AE24: -0.7738 | AF24: 3.7006 | AG24: 0.2461 | AH24: -17.7578 | AI24: -1.1277 | AJ24: 21.7209 | AK24: 7.9234 | AL24: 2.2472 | AM24: 8.1918 | AN24: 6.6597 | AO24: 6.3954 | AP24: -2.8173 | AQ24: 1.9571 | AR24: 8.14 | AS24: 7.1951 | AT24: 4.5692 | AU24: 24.964 | AV24: 13.763 | AW24: 2.4839 | AX24: -1.7262 | AY24: 10.0308 | BA24: + Net Op. Profit | BB24: WACC_NET_OPER_PROFIT | BC24: 5949 | BD24: 5536 | BE24: 4322 | BF24: 4927 | BG24: 4825 | BH24: 3753 | BI24: 3398 | BJ24: 3613 | BK24: 3693 | BL24: 3517 | BM24: 3496 | BN24: 3503 | BO24: 3086 | BP24: 2273 | BQ24: 2767 | BR24: 2287 | BS24: 2164 | BT24: 1562 | BU24: 1005 | BV24: 513
A25: Source: Bloomberg | O25: Total Equity | P25: TOTAL_EQUITY_1_YEAR_GROWTH | Q25: -32.3563 | R25: 0.3706 | S25: 0.568 | T25: -10.1384 | U25: -6.5053 | V25: 6.8908 | W25: 17.327 | X25: 13.6961 | Y25: 17.7511 | Z25: 15.4354 | AA25: 1.9771 | AB25: -2.1088 | AC25: 4.5344 | AD25: 1.7118 | AE25: 1.9771 | AF25: 3.3969 | AG25: 5.5478 | AH25: 16.7817 | AI25: 12.4214 | AJ25: -2.8741 | AK25: -7.3345 | AL25: 8.9463 | AM25: -0.7755 | AN25: -2.6667 | AO25: 6.3061 | AP25: 16.6852 | AQ25: 6.3976 | AR25: 4.4023 | AS25: 0.2228 | AT25: 25.8851 | AU25: -14.5438 | AV25: -5.6995 | AW25: 10.5117 | AX25: 2.9748 | AY25: -6.4815 | BA25: - Cash Op. Taxes | BB25: WACC_CASH_OPER_TAXES | BC25: 1202.3827 | BD25: 1106.9511 | BE25: 829.6816 | BF25: 862.1152 | BG25: 853.6169 | BH25: 849 | BI25: 852.7931 | BJ25: 874.2906 | BK25: 1115.7953 | BL25: 727.5065 | BM25: 730.7939 | BN25: 723.7755 | BO25: 694.7003 | BP25: 465.4708 | BQ25: 816.3312 | BR25: 841.3975 | BS25: 615.6638 | BT25: 625.7799 | BU25: -2051.2009 | BV25: -22.3333
O26: Capital | P26: GROWTH_IN_CAP | Q26: -10.7831 | R26: -13.2368 | S26: 3.1436 | T26: -7.7856 | U26: 0.7832 | V26: 2.9375 | W26: 3.6086 | X26: 3.4392 | Y26: 37.5317 | Z26: 28.4266 | AA26: 0.4945 | AB26: 2.1907 | AC26: -0.9864 | AD26: 3.7653 | AE26: 0.4989 | AF26: 3.558 | AG26: 2.7312 | AH26: -1.1242 | AI26: 6.5789 | AJ26: 6.9646 | AK26: -0.3889 | AL26: 5.6423 | AM26: 3.505 | AN26: 1.9869 | AO26: 6.3527 | AP26: 6.5042 | AQ26: 4.2824 | AR26: 6.143 | AS26: 3.5311 | AT26: 15.4131 | AU26: 3.0418 | AV26: 4.8067 | AW26: 5.8078 | AX26: 0.3068 | AY26: 2.6999 | BA26: + NOPAT | BB26: WACC_NOPAT | BC26: 4746.6173 | BD26: 4429.0489 | BE26: 3492.3184 | BF26: 4064.8848 | BG26: 3971.3831 | BH26: 2904 | BI26: 2545.2069 | BJ26: 2738.7094 | BK26: 2577.2047 | BL26: 2789.4935 | BM26: 2765.2061 | BN26: 2779.2245 | BO26: 2391.2997 | BP26: 1807.5292 | BQ26: 1950.6688 | BR26: 1445.6025 | BS26: 1548.3362 | BT26: 936.2201 | BU26: 3056.2009 | BV26: 535.3333
O27: Book Value per Share | P27: BVPS_GROWTH | Q27: -2.7611 | R27: 9.3674 | S27: 8.1205 | T27: -13.5072 | U27: -7.4974 | V27: 6.1532 | W27: 16.7366 | X27: 13.1284 | Y27: 14.2818 | Z27: 14.6819 | AA27: 2.5365 | AB27: -2.7026 | AC27: 7.3382 | AD27: 1.2596 | AE27: 1.5026 | AF27: 3.2123 | AG27: 5.3235 | AH27: 15.3506 | AI27: 12.0727 | AJ27: 4.2461 | AK27: -3.2205 | AL27: 8.0876 | AM27: 5.3911 | AN27: 2.9855 | AO27: 9.2907 | AP27: 17.9772 | AQ27: 8.2344 | AR27: 7.3054 | AS27: 4.2633 | AT27: 31.3331 | AU27: -7.0827 | AV27: -0.24 | AW27: -62.6126 | AX27: 220.9453 | AY27: -0.3578 | BA27: Total Invested Capital | BB27: WACC_TOTAL_INV_CAPITAL | BC27: 38983 | BD27: 37959 | BE27: 37841 | BF27: 36008 | BG27: 34486 | BH27: 33300 | BI27: 33077 | BJ27: 32078 | BK27: 30337 | BL27: 28869 | BM27: 27592 | BN27: 26118 | BO27: 24984 | BP27: 23919 | BQ27: 22849 | BR27: 22431 | BS27: 21523 | BT27: 20594 | BU27: 20902 | BV27: 18042
BA28: WACC | BB28: WACC | BC28: 7.3055 | BD28: 8.5516 | BE28: 8.2089 | BF28: 7.4443 | BG28: 9.8254 | BH28: 8.8002 | BI28: 8.3721 | BJ28: 8.158 | BK28: 8.2549 | BL28: 9.0653 | BM28: 8.7373 | BN28: 9.7072 | BO28: 11.7766 | BP28: 9.2292 | BQ28: 7.9406 | BR28: 9.5636 | BS28: 9.6938 | BT28: 8.6572 | BU28: 6.7802 | BV28: 6.6139
O29: Cash From Operations | P29: CASH_FLOW_GROWTH | Q29: -32.9198 | R29: 24.1677 | S29: -11.718 | T29: -2.5872 | U29: 8.4296 | V29: 2.4494 | W29: 37.8378 | X29: 18.175 | Y29: -8.1047 | Z29: 8.1944 | AA29: -35.8151 | AB29: 7.1 | AC29: -33.7068 | AD29: 16.4789 | AE29: 36.2757 | AF29: -28.6602 | AG29: 79.8507 | AH29: -23.2365 | AI29: 85.4054 | AJ29: 6.1224 | AK29: 33.4249 | AL29: -30.0275 | AM29: 59.9313 | AN29: 7.0531 | AO29: -15.6116 | AP29: 10.8961 | AQ29: 2.3263 | AR29: 0.8077 | AS29: -9.7626 | AT29: 14.173 | AU29: 33.6694 | AV29: 4.5033 | AW29: -12.1031 | AX29: 19.6106 | AY29: 10.1981 | BA29: - Capital Charge | BB29: WACC_CAPITAL_CHARGE | BC29: 2847.8995 | BD29: 3246.1049 | BE29: 3106.3292 | BF29: 2680.559 | BG29: 3388.3884 | BH29: 2930.4646 | BI29: 2769.2336 | BJ29: 2616.9094 | BK29: 2504.2848 | BL29: 2617.0651 | BM29: 2410.7886 | BN29: 2535.3354 | BO29: 2942.2646 | BP29: 2207.5388 | BQ29: 1814.3501 | BR29: 2145.2112 | BS29: 2086.3874 | BT29: 1782.8579 | BU29: 1417.1948 | BV29: 1193.2711
O30: Capital Expenditures | P30: TOT_CAP_EXPEND_GROWTH | Q30: 49.5695 | R30: 7.2368 | S30: -9.0491 | T30: -27.1501 | U30: 20.4861 | V30: -26.2248 | W30: 13.9323 | X30: 32.1143 | Y30: 5.7958 | Z30: -8.0131 | AA30: 31.4667 | AB30: 2.5693 | AC30: -39.8154 | AD30: 1.862 | AE30: 16.129 | AF30: -1.9444 | AG30: -2.7384 | AH30: 10.2913 | AI30: 44.2782 | AJ30: 8.1757 | AK30: -1.8613 | AL30: -18.046 | AM30: 29.0323 | AN30: 24.837 | AO30: 1.9155 | AP30: -1.1961 | AQ30: 5.8798 | AR30: 4.6141 | AS30: -6.4012 | AT30: -14.9291 | AU30: -14.4608 | AV30: -5.043 | AW30: -1.8709 | AX30: 10.1476 | AY30: 19.0955 | BA30: Economic Value Added | BB30: WACC_ECON_VALUE_ADDED | BC30: 1898.7178 | BD30: 1182.944 | BE30: 385.9893 | BF30: 1384.3258 | BG30: 582.9947 | BH30: -26.4646 | BI30: -224.0267 | BJ30: 121.7999 | BK30: 72.9199 | BL30: 172.4284 | BM30: 354.4175 | BN30: 243.8891 | BO30: -550.965 | BP30: -400.0096 | BQ30: 136.3186 | BR30: -699.6087 | BS30: -538.0512 | BT30: -846.6378 | BU30: 1639.0061 | BV30: -657.9377
O31: Net Change In Cash | P31: NET_CHANGE_IN_CASH_1_YEAR_GROWTH | Q31: — | R31: — | S31: — | T31: 88.8889 | U31: — | V31: — | W31: 56.5789 | X31: — | Y31: -12.7273 | Z31: — | AA31: -24.7863 | AB31: — | AC31: — | AD31: 66.3934 | AE31: 91.8699 | AF31: — | AG31: 33.7278 | AH31: — | AI31: — | AJ31: — | AK31: — | AL31: 19.6013 | AM31: -26.9444 | AN31: — | AO31: — | AP31: — | AQ31: — | AR31: — | AS31: 39.0244 | AT31: -708 | AU31: — | AV31: -78.1182 | AW31: 2071 | AX31: — | AY31: 68.427 | BA31: ROIC | BB31: WACC_RETURN_ON_INV_CAPITAL | BC31: 12.1761 | BD31: 11.668 | BE31: 9.2289 | BF31: 11.2888 | BG31: 11.5159 | BH31: 8.7207 | BI31: 7.6948 | BJ31: 8.5377 | BK31: 8.4953 | BL31: 9.6626 | BM31: 10.0218 | BN31: 10.641 | BO31: 9.5713 | BP31: 7.5569 | BQ31: 8.5372 | BR31: 6.4447 | BS31: 7.1939 | BT31: 4.5461 | BU31: 14.6216 | BV31: 2.9672
O32: Free Cash Flow | P32: FREE_CASH_FLOW_1_YEAR_GROWTH | Q32: — | R32: 26.6667 | S32: 0 | T32: — | U32: — | V32: — | W32: 132.4742 | X32: -8.8692 | Y32: -47.2019 | Z32: 99.5392 | AA32: — | AB32: 6.8894 | AC32: 54.4843 | AD32: 49.2611 | AE32: — | AF32: — | AG32: — | AH32: — | AI32: — | AJ32: -1.9093 | AK32: 185.6448 | AL32: -47.7853 | AM32: 131.8108 | AN32: -15.9747 | AO32: -49.33 | AP32: 57.686 | AQ32: -6.2893 | AR32: -9.6197 | AS32: -20.4208 | AT32: 122.7061 | AU32: 102.2346 | AV32: 10.2555 | AW32: -17.4131 | AX32: 25.4456 | AY32: 5.3809 | BA32: EVA Spread | BB32: WACC_EVA_SPREAD | BC32: 4.8706 | BD32: 3.1164 | BE32: 1.02 | BF32: 3.8445 | BG32: 1.6905 | BH32: -0.0795 | BI32: -0.6773 | BJ32: 0.3797 | BK32: 0.2404 | BL32: 0.5973 | BM32: 1.2845 | BN32: 0.9338 | BO32: -2.2053 | BP32: -1.6724 | BQ32: 0.5966 | BR32: -3.1189 | BS32: -2.4999 | BT32: -4.1111 | BU32: 7.8414 | BV32: -3.6467
O33: Cash Flow to Firm | P33: CASH_FLOW_TO_FIRM_1_YEAR_GROWTH | Q33: — | R33: — | S33: -9.3578 | T33: — | U33: — | V33: — | W33: 33.0147 | X33: 15.2637 | Y33: -7.6995 | Z33: 16.394 | AA33: -27.2717 | AB33: -9.3432 | AC33: -12.7258 | AD33: 8.4837 | AE33: 21.3293 | AF33: -22.395 | AG33: 57.7382 | AH33: -18.9131 | AI33: 66.4511 | AJ33: 4.779 | AK33: 32.4957 | AL33: -26.04 | AM33: 50.1543 | AN33: 6.5545 | AO33: -14.0165 | AP33: 9.831 | AQ33: 1.7239 | AR33: 0.6279 | AS33: -8.3022 | AT33: — | AU33: — | AV33: 5.5828 | AW33: -10.7219 | AX33: 16.7964 | AY33: 9.5494 | BA33: Source: Bloomberg | BC33: Right click to show data transparency (not supported for all values)
O34: Free Cash Flow to Firm | P34: FCF_TO_FIRM_1_YEAR_GROWTH | Q34: — | R34: — | S34: 4.3852 | T34: — | U34: — | V34: — | W34: 73.0784 | X34: -8.0246 | Y34: -34.4903 | Z34: 94.6433 | AA34: — | AB34: -136.5158 | AC34: — | AD34: 45.8919 | AE34: 41.8409 | AF34: -88.4367 | AG34: 1713.8476 | AH34: -61.7966 | AI34: 160.4462 | AJ34: -3.1976 | AK34: 122.6573 | AL34: -35.2864 | AM34: 81.0944 | AN34: -12.5271 | AO34: -37.7477 | AP34: 36.7211 | AQ34: -5.5999 | AR34: -7.251 | AS34: -12.5404 | AT34: — | AU34: — | AV34: 11.0568 | AW34: -14.6206 | AX34: 20.1624 | AY34: 5.1195
O36: 5 Year Growth
O37: Revenue | P37: GEO_GROW_NET_SALES | Q37: — | R37: — | S37: — | T37: — | U37: 1.6621 | V37: 3.3228 | W37: 4.4052 | X37: 5.0643 | Y37: 4.0573 | Z37: 3.9897 | AA37: 1.9949 | AB37: 1.5479 | AC37: -4.8527 | AD37: -5.0994 | AE37: -5.1538 | AF37: -5.174 | AG37: -4.9716 | AH37: 1.0215 | AI37: 3.3575 | AJ37: 4.2335 | AK37: 8.2669 | AL37: 2.3746 | AM37: 4.2976 | AN37: 4.2782 | AO37: 3.2266 | AP37: 1.334 | AQ37: 6.9806 | AR37: 2.1179 | AS37: -1.2625 | AT37: -0.5992 | AU37: 0.3698 | AV37: -1.1832 | AW37: -2.1717 | AX37: 2.4975 | AY37: 5.4195
O38: EBITDA | P38: GEO_GROW_EBITDA | Q38: — | R38: — | S38: — | T38: — | U38: 0.726 | V38: 1.5364 | W38: 6.5704 | X38: 9.5149 | Y38: 9.5913 | Z38: 8.7651 | AA38: 3.4564 | AB38: -7.9734 | AC38: -7.0865 | AD38: -5.9167 | AE38: -4.7982 | AF38: -7.9522 | AG38: 7.6982 | AH38: 11.1449 | AI38: 13.7346 | AJ38: 12.1149 | AK38: 25.9491 | AL38: 12.8976 | AM38: 11.0139 | AN38: 8.1496 | AO38: 7.4977 | AP38: 4.4252 | AQ38: 8.4677 | AR38: 3.5861 | AS38: 1.0743 | AT38: 2.1996 | AU38: 6.2581 | AV38: 6.0754 | AW38: 3.9886 | AX38: 8.656 | AY38: 8.6745
O39: Operating Income | P39: GEO_GROW_OPER_INC | Q39: — | R39: — | S39: — | T39: — | U39: 1.5175 | V39: 0.0879 | W39: 7.2305 | X39: 11.8858 | Y39: 12.2513 | Z39: 10.4055 | AA39: 4.357 | AB39: -14.1958 | AC39: -10.8436 | AD39: -8.862 | AE39: -6.5695 | AF39: -14.3781 | AG39: 11.7813 | AH39: 14.0006 | AI39: 17.4408 | AJ39: 14.8902 | AK39: 39.7116 | AL39: 17.8162 | AM39: 14.6541 | AN39: 10.1703 | AO39: 8.9111 | AP39: 4.6424 | AQ39: 9.7409 | AR39: 3.1377 | AS39: -0.4713 | AT39: 1.4773 | AU39: 6.9909 | AV39: 6.5639 | AW39: 4.0072 | AX39: 10.5427 | AY39: 10.1169
O40: Net Income to Common | P40: NET_INCOME_TO_COMMON_5_YR_GROWTH | Q40: — | R40: — | S40: — | T40: — | U40: -31.8449 | V40: 21.2481 | W40: 8.2322 | X40: 8.7123 | Y40: — | Z40: 109.0756 | AA40: 8.3867 | AB40: -68.5691 | AC40: -1.7773 | AD40: -19.2802 | AE40: -11.9025 | AF40: -14.4555 | AG40: 179.1476 | AH40: 15.1732 | AI40: 34.9214 | AJ40: 25.8022 | AK40: 40.8768 | AL40: 27.5174 | AM40: 6.4218 | AN40: 7.2049 | AO40: 6.8303 | AP40: 6.4182 | AQ40: 10.9998 | AR40: 4.7054 | AS40: -1.5802 | AT40: 24.0914 | AU40: 12.1684 | AV40: 11.5793 | AW40: 7.0479 | AX40: 17.1574 | AY40: -5.3008
O41: EPS Diluted | P41: 5Y_GEO_GROWTH_DILUTED_EPS | Q41: — | R41: — | S41: — | T41: — | U41: -26.404 | V41: 30.0525 | W41: 7.4978 | X41: 7.2175 | Y41: — | Z41: 108.2399 | AA41: 7.7272 | AB41: -68.2818 | AC41: -1.9082 | AD41: -19.009 | AE41: -11.7607 | AF41: -15.0566 | AG41: 173.1296 | AH41: 13.5491 | AI41: 32.5196 | AJ41: 24.6148 | AK41: 43.1827 | AL41: 30.6222 | AM41: 9.954 | AN41: 12.5808 | AO41: 12.4244 | AP41: 10.4499 | AQ41: 14.7902 | AR41: 8.1781 | AS41: 1.2619 | AT41: 27.3253 | AU41: 15.9781 | AV41: 16.7796 | AW41: -9.712 | AX41: 22.7299 | AY41: -0.4719
O42: EPS Diluted before XO | P42: 5Y_GEO_GROWTH_DILUTED_EPS_BEF_XO | Q42: — | R42: — | S42: — | T42: — | U42: — | V42: — | W42: 8.781 | X42: 10.1271 | Y42: — | Z42: 108.2399 | AA42: 7.7272 | AB42: -40.1105 | AC42: -21.4987 | AD42: -19.009 | AE42: -10.0543 | AF42: -24.1539 | AG42: 50.7739 | AH42: 29.3199 | AI42: 32.5196 | AJ42: 20.1344 | AK42: 63.318 | AL42: 24.9703 | AM42: 20.6383 | AN42: 12.5808 | AO42: 14.4049 | AP42: 8.4472 | AQ42: 15.1107 | AR42: 8.1781 | AS42: 1.2619 | AT42: 27.3253 | AU42: 15.9781 | AV42: 16.7796 | AW42: -9.712 | AX42: 22.7299 | AY42: -0.4719
...

Sheet IS
A1: CSX Corp (CSX US) - BBG Adjusted
A3: In Millions of USD except Per Share | C3: FY 2018 | D3: FY 2019 | E3: FY 2020 | F3: FY 2021 | G3: FY 2022 | H3: Last 12M | I3: FY 2023 Est | J3: FY 2024 Est
A4: 12 Months Ending | C4: 12/31/2018 | D4: 12/31/2019 | E4: 12/31/2020 | F4: 12/31/2021 | G4: 12/31/2022 | H4: 09/30/2023 | I4: 12/31/2023 | J4: 12/31/2024
A5: Revenue | B5: SALES_REV_TURN | C5: 12250 | D5: 11937 | E5: 10583 | F5: 12522 | G5: 14853 | H5: 14707 | I5: 14614.154 | J5: 14995.846
A6: + Sales & Services Revenue | B6: IS_SALES_AND_SERVICES_REVENUES | C6: 11668 | D6: 10809 | E6: 9810 | F6: 11120 | G6: 12430 | H6: 12692
A7: + Other Revenue | B7: IS_OTHER_REVENUE | C7: 582 | D7: 1128 | E7: 773 | F7: 1402 | G7: 2423 | H7: 2015
A8: Gross Profit | B8: GROSS_PROFIT | C8: — | D8: — | E8: — | F8: — | G8: — | I8: 5557.1782 | J8: 5787.6468
A9: + Other Operating Income | B9: IS_OTHER_OPER_INC | C9: 96 | D9: 0 | E9: 0 | F9: 0 | G9: 0 | H9: 0
A10: - Operating Expenses | B10: IS_OPERATING_EXPN | C10: 7631 | D10: 7101 | E10: 6256 | F10: 7382 | G10: 9068 | H10: 9088
A11: + Research & Development | B11: IS_OPERATING_EXPENSES_RD | C11: 0 | D11: 0 | E11: 0 | F11: 0 | G11: 0
A12: + Depreciation & Amortization | B12: IS_DEPRECIATION_AND_AMORTIZATION | C12: 1331 | D12: 1349 | E12: 1383 | F12: 1420 | G12: 1500 | H12: 1587
A13: + Other Operating Expense | B13: IS_OTHER_OPERATING_EXPENSES | C13: 6300 | D13: 5752 | E13: 4873 | F13: 5962 | G13: 7568 | H13: 7501
A14: Operating Income (Loss) | B14: IS_OPER_INC | C14: 4715 | D14: 4836 | E14: 4327 | F14: 5140 | G14: 5785 | H14: 5619 | I14: 5555.68 | J14: 5758.5
A15: - Non-Operating (Income) Loss | B15: IS_NONOP_INCOME_LOSS | C15: 565 | D15: 649 | E15: 735 | F15: 643 | G15: 609 | H15: 654
A16: + Interest Expense, Net | B16: IS_NET_INTEREST_EXPENSE | C16: 607 | D16: 689 | E16: 754 | F16: 722 | G16: 742
A17: + Interest Expense | B17: IS_INT_EXPENSE | C17: 639 | D17: 737 | E17: 754 | F17: 722 | G17: 742 | H17: 804
A18: - Interest Income | B18: IS_INT_INC | C18: 32 | D18: 48 | E18: 0 | F18: 0 | G18: 0
A19: + Foreign Exch (Gain) Loss | B19: IS_FOREIGN_EXCH_LOSS | C19: 0 | D19: 0 | E19: 0 | F19: 0 | G19: 0
A20: + Other Non-Op (Income) Loss | B20: IS_OTHER_NON_OPERATING_INC_LOSS | C20: -42 | D20: -40 | E20: -19 | F20: -79 | G20: -133 | H20: -150
A21: Pretax Income (Loss), Adjusted | B21: PRETAX_INC | C21: 4150 | D21: 4187 | E21: 3592 | F21: 4497 | G21: 5176 | H21: 4965 | I21: 4886.12 | J21: 5064.36
A22: - Abnormal Losses (Gains) | B22: IS_ABNORMAL_ITEM | C22: -154 | D22: -129 | E22: -35 | F22: -454 | G22: -238 | H22: -81
A23: + Disposal of Assets | B23: IS_GAIN_LOSS_DISPOSAL_ASSETS | C23: -154 | D23: -151 | E23: -35 | F23: -454 | G23: -238 | H23: -81
A24: + Early Extinguishment of Debt | B24: IS_G_L_ON_EXT_DBT_OR_SETTLE_DBT | C24: — | D24: — | E24: — | F24: — | G24: —
A25: + Asset Write-Down | B25: IS_IMPAIRMENT_ASSETS | C25: — | D25: 22 | E25: — | F25: — | G25: —
A26: + Restructuring | B26: IS_RESTRUCTURING_EXPENSES | C26: — | D26: — | E26: — | F26: — | G26: —
A27: + Other Abnormal Items | B27: IS_OTHER_ONE_TIME_ITEMS | C27: — | D27: — | E27: — | F27: — | G27: —
A28: Pretax Income (Loss), GAAP | B28: PRETAX_INC | C28: 4304 | D28: 4316 | E28: 3627 | F28: 4951 | G28: 5414 | H28: 5046 | I28: 4886.12 | J28: 5064.36
A29: - Income Tax Expense (Benefit) | B29: IS_INC_TAX_EXP | C29: 995 | D29: 985 | E29: 862 | F29: 1170 | G29: 1248 | H29: 1199
A30: + Current Income Tax | B30: IS_CURRENT_INCOME_TAX_BENEFIT | C30: 716 | D30: 712 | E30: 682 | F30: 1003 | G30: 1131
A31: + Deferred Income Tax | B31: IS_DEFERRED_INCOME_TAX_BENEFIT | C31: 279 | D31: 273 | E31: 180 | F31: 167 | G31: 117
A32: + Tax Allowance/Credit | B32: IS_TAX_VALN_ALLOWNCE_CREDITS | C32: — | D32: — | E32: — | F32: — | G32: —
A33: Income (Loss) from Cont Ops | B33: IS_INC_BEF_XO_ITEM | C33: 3309 | D33: 3331 | E33: 2765 | F33: 3781 | G33: 4166 | H33: 3847 | I33: 3699.095 | J33: 3857.476
A34: - Net Extraordinary Losses (Gains) | B34: XO_GL_NET_OF_TAX | C34: 0 | D34: 0 | E34: 0 | F34: 0 | G34: 0 | H34: 0
A35: + Discontinued Operations | B35: IS_DISCONTINUED_OPERATIONS | C35: 0 | D35: 0 | E35: 0 | F35: 0 | G35: 0 | H35: 0
A36: + XO & Accounting Changes | B36: EXTRAORD_ITEMS_ACCOUNTING_CHANGS | C36: 0 | D36: 0 | E36: 0 | F36: 0 | G36: 0 | H36: 0
A37: Income (Loss) Incl. MI | B37: NI_INCLUDING_MINORITY_INT_RATIO | C37: 3309 | D37: 3331 | E37: 2765 | F37: 3781 | G37: 4166 | H37: 3847
A38: Net Income, GAAP | B38: NET_INCOME | C38: 3309 | D38: 3331 | E38: 2765 | F38: 3781 | G38: 4166 | H38: 3847 | I38: 3699.095 | J38: 3857.476
A39: - Preferred Dividends | B39: IS_TOT_CASH_PFD_DVD | C39: 0 | D39: 0 | E39: 0 | F39: 0 | G39: 0 | H39: 0
A40: - Other Adjustments | B40: OTHER_ADJUSTMENTS | C40: 1 | D40: 0 | E40: 0 | F40: 0 | G40: 0 | H40: 0
A41: Net Income Avail to Common, GAAP | B41: EARN_FOR_COMMON | C41: 3308 | D41: 3331 | E41: 2765 | F41: 3781 | G41: 4166 | H41: 3847 | I41: 3699.095 | J41: 3857.476
...

Sheet BS
A1: CSX Corp (CSX US) - Standardized
A3: In Millions of USD except Per Share | C3: FY 2018 | D3: FY 2019 | E3: FY 2020 | F3: FY 2021 | G3: FY 2022
A4: 12 Months Ending | C4: 12/31/2018 | D4: 12/31/2019 | E4: 12/31/2020 | F4: 12/31/2021 | G4: 12/31/2022
A5: Total Assets
A6: + Cash, Cash Equivalents & STI | B6: CASH_CASH_EQTY_STI_DETAILED | C6: 1111 | D6: 1954 | E6: 3131 | F6: 2316 | G6: 2087
A7: + Cash & Cash Equivalents | B7: BS_CASH_NEAR_CASH_ITEM | C7: 858 | D7: 958 | E7: 3129 | F7: 2239 | G7: 1958
A8: + ST Investments | B8: BS_MKT_SEC_OTHER_ST_INVEST | C8: 253 | D8: 996 | E8: 2 | F8: 77 | G8: 129
A9: + Accounts & Notes Receiv | B9: BS_ACCT_NOTE_RCV | C9: 1010 | D9: 986 | E9: 912 | F9: 1148 | G9: 1313
A10: + Accounts Receivable, Net | B10: BS_ACCTS_REC_EXCL_NOTES_REC | C10: 1010 | D10: 986 | E10: 912 | F10: 1148 | G10: 1313
A11: + Notes Receivable, Net | B11: NOTES_RECEIVABLE | C11: 0 | D11: 0 | E11: 0 | F11: 0 | G11: 0
A12: + Inventories | B12: BS_INVENTORIES | C12: 263 | D12: 261 | E12: 302 | F12: 339 | G12: 341
A13: + Other ST Assets | B13: OTHER_CURRENT_ASSETS_DETAILED | C13: 181 | D13: 77 | E13: 96 | F13: 70 | G13: 108
A14: + Derivative & Hedging Assets | B14: BS_DERIV_HEDGING_ASST_ST | C14: 0 | D14: 0 | E14: 0 | F14: 0 | G14: 0
A15: + Misc ST Assets | B15: BS_OTHER_CUR_ASSET_LESS_PREPAY | C15: 181 | D15: 77 | E15: 96 | F15: 70 | G15: 108
A16: Total Current Assets | B16: BS_CUR_ASSET_REPORT | C16: 2565 | D16: 3278 | E16: 4441 | F16: 3873 | G16: 3849
A17: + Property, Plant & Equip, Net | B17: BS_NET_FIX_ASSET | C17: 31998 | D17: 32700 | E17: 32916 | F17: 33516 | G17: 34747
... A30: Total Assets | B30: BS_TOT_ASSET | C30: 36729 | D30: 38257 | E30: 39793 | F30: 40531 | G30: 41912
A32: Liabilities & Shareholders' Equity
A33: + Payables & Accruals | B33: ACCT_PAYABLE_ACCRUALS_DETAILED | C33: 1718 | D33: 1701 | E33: 1454 | F33: 1845 | G33: 2092
A34: + Accounts Payable | B34: BS_ACCT_PAYABLE | C34: 949 | D34: 1043 | E34: 809 | F34: 963 | G34: 1130
A35: + Accrued Taxes | B35: BS_TAXES_PAYABLE | C35: 106 | D35: 69 | E35: 73 | F35: 134 | G35: 111
A36: + Interest & Dividends Payable | B36: INTEREST_DIVIDENDS_PAYABLE | C36: 0 | D36: 0 | E36: 0 | F36: 0 | G36: 0
A37: + Other Payables & Accruals | B37: BS_ACCRUAL | C37: 663 | D37: 589 | E37: 572 | F37: 748 | G37: 851
A38: + ST Debt | B38: BS_ST_BORROW | C38: 18 | D38: 302 | E38: 446 | F38: 245 | G38: 220
A39: + ST Borrowings | B39: SHORT_TERM_DEBT_DETAILED | C39: 0 | D39: 0 | E39: 0 | F39: 0 | G39: 0
