Workbook
Name cash: DCF!$C$21
Name debt: DCF!$C$22
Name ebi: CCA!$L$25:$L$29,CCA!$L$31:$L$37,CCA!$L$30
Name fcff: DCF!$L$16
Name reve: CCA!$J$25:$J$37
Name tgr: DCF!$I$20
Name wacc: DCF!$I$23

Sheet DCF
B2: Discounted Cash Flow Analysis | F2: CSX Corp. (CSX)
H4: 0.5 | I4: =H4+1 -> 1.5 | J4: =I4+1 -> 2.5 | K4: =J4+1 -> 3.5 | L4: =K4+1 -> 4.5
B5: $M | C5: 2018 | D5: 2019 | E5: 2020 | F5: 2021 | G5: 2022 | H5: 2023 | I5: 2024 | J5: 2025 | K5: 2026 | L5: 2027
B6: Revenue, Adj | C6: 22832 | D6: 21708 | E6: 19533 | F6: 21804 | G6: 24875 | H6: 23991.76 | I6: 25025.16
B7: Growth %, YoY | C7: 7.4953 | D7: -4.9229 | E7: -10.0193 | F7: 11.6265 | G7: 14.0846 | H7: -3.5507136 | I7: 4.3073122
B8: Gross Profit, Adj | C8: — | D8: — | E8: — | F8: — | G8: — | H8: 8975.7973 | I8: 9995.7997
B9: Margin % | C9: — | D9: — | E9: — | F9: — | G9: — | H9: 37.412 | I9: 39.943
B10: EBITDA, Adj | C10: 10708 | D10: 11136 | E10: 10570 | F10: 11849 | G10: 12593 | H10: 11291.6 | I10: 12238.917
B11: Margin % | C11: 46.899089 | D11: 51.29906 | E11: 54.113551 | F11: 54.34324 | G11: 50.625126 | H11: 47.064492 | I11: 48.906449
B12: Net Income, Adj | C12: 6027.62 | D12: 5903.2 | E12: 5510.463 | F12: 6417.14 | G12: 7067 | H12: 6251.192 | I12: 6836.885
B13: Margin % | C13: 26.399877 | D13: 27.193661 | E13: 28.211043 | F13: 29.431022 | G13: 28.41005 | H13: 26.055579 | I13: 27.320045
B14: EPS, Adj | C14: 7.9917 | D14: 8.3576 | E14: 8.1178 | F14: 9.7885 | G14: 11.3206 | H14: 10.253 | I14: 11.322
B15: Growth %, YoY | C15: -39.580615 | D15: 4.5789052 | E15: -2.8700023 | F15: 20.581047 | G15: 15.652042 | H15: -9.4304115 | I15: 10.426217
B16: FCFF | C16: 5249 | D16: 5156 | E16: 5613 | F16: 6096 | G16: 5742 | H16: 4846.03 | I16: 6040.806 | J16: 6100 | K16: 6300 | L16: 7000
B17: Discounted CF | H17: =H16/(1+wacc)^H4 -> 4744.0553 | I17: {=I16/(1+wacc)^I4} -> 5667.4256 | J17: {=J16/(1+wacc)^J4} -> 5484.6393 | K17: =K16/(1+wacc)^K4 -> 5428.5779 | L17: =L16/(1+wacc)^L4 -> 5780.5726
B19: Terminal Value | C19: =fcff*(1+tgr)/(wacc-tgr) -> 304444.46 | E19: % Debt | F19: =C22/F28 -> 0.73466857 | H19: WACC (% Equity x Cost of Equity) + (% Debt x Cost of Debt x (1 -Tax rate)) | I19: 0.09 | J19: ← from Bloomberg | N19: Share Price on | O19: 45251 | P19: 224.28
B20: Enterprise Value | C20: =SUM(H17:K17,C19) -> 325769.15 | E20: Cost of Debt | F20: =Summary!$AZ$9/100 -> 0.041244 | H20: TGR | I20: 0.02 | O20: Upside in 2026 | P20: =AVERAGE(C25)/P19-1 -> 1.13345
B21: + Cash | C21: =Summary!G6 -> 1019 | E21: Tax Rate | F21: 0.231 | O21: " a year | P21: =((1+P20)^(1/3.5))-1 -> 0.24171968
B22: - Debt | C22: =Summary!G8 -> 34957 | E22: Equity Value | F22: =BS!G72 -> 12625 | I22: Calculated WACC
B23: Equity Value | C23: =C20+C21-C22 -> 291831.15 | E23: % Equity | F23: =F22/F28 -> 0.26533143 | I23: =F23*G24+(F19*F20*(1-F21)) -> 0.043452554 | P23: Terminal Growth Rate
B24: Shares | C24: 609.9 | E24: Cost of Equity Risk Free Rate + (Beta x (Expected Market Return - Risk Free Rate)) | F24: =Summary!$AZ$6/100 -> 0.0823 | G24: =F25+F27*F26 -> 0.0759478 | P24: =Q24-0.005 -> 0.01 | Q24: =R24-0.005 -> 0.015 | R24: =tgr -> 0.02 | S24: =R24+0.005 -> 0.025 | T24: =S24+0.005 -> 0.03
B25: Share Price | C25: =C23/C24 -> 478.49017 | E25: Risk Free Rate | F25: 0.0441 | G25: from US10Y | N25: WACC | O25: =O26+0.005 -> 0.053452554 | P25: =TEXT((((((fcff*(1+P$24))/ABS($O25-P$24))+SUM($H$17:$K$17)-$C$22+$C$21)/$C$24/$P$19)-1),"0.0%") &" / "& TEXT((((fcff*(1+P$24))/ABS($O25-P$24))+SUM($H$17:$K$17)-$C$22+$C$21)/$C$24,"$0.00") -> 9.7% / $246.09 | Q25: =TEXT((((((fcff*(1+Q$24))/ABS($O25-Q$24))+SUM($H$17:$K$17)-$C$22+$C$21)/$C$24/$P$19)-1),"0.0%") &" / "& TEXT((((fcff*(1+Q$24))/ABS($O25-Q$24))+SUM($H$17:$K$17)-$C$22+$C$21)/$C$24,"$0.00") -> 25.9% / $282.28 | R25: =TEXT((((((fcff*(1+R$24))/ABS($O25-R$24))+SUM($H$17:$K$17)-$C$22+$C$21)/$C$24/$P$19)-1),"0.0%") &" / "& TEXT((((fcff*(1+R$24))/ABS($O25-R$24))+SUM($H$17:$K$17)-$C$22+$C$21)/$C$24,"$0.00") -> 46.8% / $329.27 | S25: =TEXT((((((fcff*(1+S$24))/ABS($O25-S$24))+SUM($H$17:$K$17)-$C$22+$C$21)/$C$24/$P$19)-1),"0.0%") &" / "& TEXT((((fcff*(1+S$24))/ABS($O25-S$24))+SUM($H$17:$K$17)-$C$22+$C$21)/$C$24,"$0.00") -> 75.1% / $392.79 | T25: =TEXT((((((fcff*(1+T$24))/ABS($O25-T$24))+SUM($H$17:$K$17)-$C$22+$C$21)/$C$24/$P$19)-1),"0.0%") &" / "& TEXT((((fcff*(1+T$24))/ABS($O25-T$24))+SUM($H$17:$K$17)-$C$22+$C$21)/$C$24,"$0.00") -> 115.5% / $483.38
C26: =AVERAGE(CCA!M43,CCA!M46) -> 164.82844 | E26: Beta | F26: 0.986 | O26: =O27+0.005 -> 0.048452554 | P26: =TEXT((((((fcff*(1+P$24))/ABS($O26-P$24))+SUM($H$17:$K$17)-$C$22+$C$21)/$C$24/$P$19)-1),"0.0%") &" / "& TEXT((((fcff*(1+P$24))/ABS($O26-P$24))+SUM($H$17:$K$17)-$C$22+$C$21)/$C$24,"$0.00") -> 25.2% / $280.78 | Q26: =TEXT((((((fcff*(1+Q$24))/ABS($O26-Q$24))+SUM($H$17:$K$17)-$C$22+$C$21)/$C$24/$P$19)-1),"0.0%") &" / "& TEXT((((fcff*(1+Q$24))/ABS($O26-Q$24))+SUM($H$17:$K$17)-$C$22+$C$21)/$C$24,"$0.00") -> 46.0% / $327.56 | R26: =TEXT((((((fcff*(1+R$24))/ABS($O26-R$24))+SUM($H$17:$K$17)-$C$22+$C$21)/$C$24/$P$19)-1),"0.0%") &" / "& TEXT((((fcff*(1+R$24))/ABS($O26-R$24))+SUM($H$17:$K$17)-$C$22+$C$21)/$C$24,"$0.00") -> 74.2% / $390.77 | S26: =TEXT((((((fcff*(1+S$24))/ABS($O26-S$24))+SUM($H$17:$K$17)-$C$22+$C$21)/$C$24/$P$19)-1),"0.0%") &" / "& TEXT((((fcff*(1+S$24))/ABS($O26-S$24))+SUM($H$17:$K$17)-$C$22+$C$21)/$C$24,"$0.00") -> 114.4% / $480.94 | T26: =TEXT((((((fcff*(1+T$24))/ABS($O26-T$24))+SUM($H$17:$K$17)-$C$22+$C$21)/$C$24/$P$19)-1),"0.0%") &" / "& TEXT((((fcff*(1+T$24))/ABS($O26-T$24))+SUM($H$17:$K$17)-$C$22+$C$21)/$C$24,"$0.00") -> 176.4% / $619.97
E27: Market Risk Premium = Market return - Risk free return | F27: =G27-F25 -> 0.0323 | G27: 0.0764 | O27: =wacc -> 0.043452554 | P27: =TEXT((((((fcff*(1+P$24))/ABS($O27-P$24))+SUM($H$17:$K$17)-$C$22+$C$21)/$C$24/$P$19)-1),"0.0%") &" / "& TEXT((((fcff*(1+P$24))/ABS($O27-P$24))+SUM($H$17:$K$17)-$C$22+$C$21)/$C$24,"$0.00") -> 45.3% / $325.84 | Q27: =TEXT((((((fcff*(1+Q$24))/ABS($O27-Q$24))+SUM($H$17:$K$17)-$C$22+$C$21)/$C$24/$P$19)-1),"0.0%") &" / "& TEXT((((fcff*(1+Q$24))/ABS($O27-Q$24))+SUM($H$17:$K$17)-$C$22+$C$21)/$C$24,"$0.00") -> 73.3% / $388.75 | R27: =TEXT(((((fcff*(1+R$24)/($O27-R$24))+SUM($H$17:$K$17)-$C$22+$C$21)/$C$24/$P$19)-1),"0.0%") &" / "& TEXT((((fcff*(1+R$24))/ABS($O27-R$24))+SUM($H$17:$K$17)-$C$22+$C$21)/$C$24,"$0.00") -> 113.3% / $478.49 | S27: =TEXT((((((fcff*(1+S$24))/ABS($O27-S$24))+SUM($H$17:$K$17)-$C$22+$C$21)/$C$24/$P$19)-1),"0.0%") &" / "& TEXT((((fcff*(1+S$24))/ABS($O27-S$24))+SUM($H$17:$K$17)-$C$22+$C$21)/$C$24,"$0.00") -> 175.0% / $616.86 | T27: =TEXT((((((fcff*(1+T$24))/ABS($O27-T$24))+SUM($H$17:$K$17)-$C$22+$C$21)/$C$24/$P$19)-1),"0.0%") &" / "& TEXT((((fcff*(1+T$24))/ABS($O27-T$24))+SUM($H$17:$K$17)-$C$22+$C$21)/$C$24,"$0.00") -> 282.6% / $858.08
C28: 40 | E28: Debt + Equity | F28: =C22+F22 -> 47582 | O28: =O27-0.005 -> 0.038452554 | P28: =TEXT((((((fcff*(1+P$24))/ABS($O28-P$24))+SUM($H$17:$K$17)-$C$22+$C$21)/$C$24/$P$19)-1),"0.0%") &" / "& TEXT((((fcff*(1+P$24))/ABS($O28-P$24))+SUM($H$17:$K$17)-$C$22+$C$21)/$C$24,"$0.00") -> 72.4% / $386.74 | Q28: =TEXT((((((fcff*(1+Q$24))/ABS($O28-Q$24))+SUM($H$17:$K$17)-$C$22+$C$21)/$C$24/$P$19)-1),"0.0%") &" / "& TEXT((((fcff*(1+Q$24))/ABS($O28-Q$24))+SUM($H$17:$K$17)-$C$22+$C$21)/$C$24,"$0.00") -> 112.3% / $476.04 | R28: =TEXT((((((fcff*(1+R$24))/ABS($O28-R$24))+SUM($H$17:$K$17)-$C$22+$C$21)/$C$24/$P$19)-1),"0.0%") &" / "& TEXT((((fcff*(1+R$24))/ABS($O28-R$24))+SUM($H$17:$K$17)-$C$22+$C$21)/$C$24,"$0.00") -> 173.7% / $613.75 | S28: =TEXT((((((fcff*(1+S$24))/ABS($O28-S$24))+SUM($H$17:$K$17)-$C$22+$C$21)/$C$24/$P$19)-1),"0.0%") &" / "& TEXT((((fcff*(1+S$24))/ABS($O28-S$24))+SUM($H$17:$K$17)-$C$22+$C$21)/$C$24,"$0.00") -> 280.7% / $853.82 | T28: =TEXT((((((fcff*(1+T$24))/ABS($O28-T$24))+SUM($H$17:$K$17)-$C$22+$C$21)/$C$24/$P$19)-1),"0.0%") &" / "& TEXT((((fcff*(1+T$24))/ABS($O28-T$24))+SUM($H$17:$K$17)-$C$22+$C$21)/$C$24,"$0.00") -> 514.4% / $1377.90
O29: =O28-0.005 -> 0.033452554 | P29: =TEXT((((((fcff*(1+P$24))/ABS($O29-P$24))+SUM($H$17:$K$17)-$C$22+$C$21)/$C$24/$P$19)-1),"0.0%") &" / "& TEXT((((fcff*(1+P$24))/ABS($O29-P$24))+SUM($H$17:$K$17)-$C$22+$C$21)/$C$24,"$0.00") -> 111.2% / $473.60 | Q29: =TEXT((((((fcff*(1+Q$24))/ABS($O29-Q$24))+SUM($H$17:$K$17)-$C$22+$C$21)/$C$24/$P$19)-1),"0.0%") &" / "& TEXT((((fcff*(1+Q$24))/ABS($O29-Q$24))+SUM($H$17:$K$17)-$C$22+$C$21)/$C$24,"$0.00") -> 172.3% / $610.64 | R29: =TEXT((((((fcff*(1+R$24))/ABS($O29-R$24))+SUM($H$17:$K$17)-$C$22+$C$21)/$C$24/$P$19)-1),"0.0%") &" / "& TEXT((((fcff*(1+R$24))/ABS($O29-R$24))+SUM($H$17:$K$17)-$C$22+$C$21)/$C$24,"$0.00") -> 278.8% / $849.55 | S29: =TEXT((((((fcff*(1+S$24))/ABS($O29-S$24))+SUM($H$17:$K$17)-$C$22+$C$21)/$C$24/$P$19)-1),"0.0%") &" / "& TEXT((((fcff*(1+S$24))/ABS($O29-S$24))+SUM($H$17:$K$17)-$C$22+$C$21)/$C$24,"$0.00") -> 511.3% / $1371.11 | T29: =TEXT((((((fcff*(1+T$24))/ABS($O29-T$24))+SUM($H$17:$K$17)-$C$22+$C$21)/$C$24/$P$19)-1),"0.0%") &" / "& TEXT((((fcff*(1+T$24))/ABS($O29-T$24))+SUM($H$17:$K$17)-$C$22+$C$21)/$C$24,"$0.00") -> 1417.5% / $3403.34
D32: =(D16-C16)/C16 -> -0.017717661 | E32: =(E16-D16)/D16 -> 0.0886346 | F32: =(F16-E16)/E16 -> 0.086050241 | G32: =(G16-F16)/F16 -> -0.058070866 | H32: =(H16-G16)/G16 -> -0.15603797 | I32: =(I16-H16)/H16 -> 0.24654738

Sheet CCA
B2: Comparable Company Analysis | G2: Westinghouse Air Brake
G3: Technologies Corporation (WAB)
H7: Revenue (in million USDs) | K7: EBITDA (in million USDs) | M7: Net Income (in millions)
B8: Ticker | C8: Company | D8: Share Price | E8: nbr of Shares | F8: Enterprise Value | G8: Market Cap | H8: 2021 | I8: 2022 | J8: 2023 | K8: 2022 | L8: 2023 | M8: 2022 | N8: 2023
B9: WAB | C9: WAB Tech | D9: =DCF!P19 -> 224.28 | E9: =DCF!C24 -> 609.9 | F9: =Summary!G9 -> 160746.29 | G9: =Summary!G5 -> 126808.29 | H9: =DCF!F6 -> 21804 | I9: =DCF!G6 -> 24875 | J9: =DCF!H6 -> 23991.76 | K9: =Summary!G15 -> 12593 | L9: =Summary!I15 -> 11291.6 | M9: =Summary!G17 -> 7067 | N9: =Summary!I17 -> 6251.192
B10: CRRC | C10: CRRC Corp | D10: 0.73 | E10: 24327 | F10: 22821 | G10: 19479 | H10: 35000 | I10: 33152 | J10: 33384 | K10: 3008 | L10: 3119 | M10: 1411 | N10: 1688
B11: KTK | C11: KTK Group | D11: 1.31 | E11: 783 | F11: 1132 | G11: 1028 | H11: 588 | I11: 525.6 | J11: 523.7 | K11: 47.5 | L11: 52.9 | M11: 26.3 | N11: 35.2
B12: GBX | C12: Greenbrier Companies | D12: 35.81 | E12: 31.1 | F12: 2725.2 | G12: 1114 | H12: 1748 | I12: 2997 | J12: 3944 | K12: 193.5 | L12: 325.7 | M12: 17.5 | N12: 85.7
B13: SRAIL | C13: Stadler Rail | D13: 35.92 | E13: 100 | F13: 3815 | G13: 3592 | H13: 3976 | I13: 3930 | J13: 4317 | K13: 322 | L13: 367 | M13: 75 | N13: 163
B14: CAF | C14: Construcciones y Auxiliar de Ferrocarr | D14: 30.8 | E14: 34.3 | F14: 1374 | G14: 1056 | H14: 3480 | I14: 3334 | J14: 3958 | K14: 244.6 | L14: 295.6 | M14: 52.6 | N14: 79
B15: ALO | C15: Alstom | D15: 14.38 | E15: 384.3 | F15: 12050 | G15: 5514 | H15: 10252 | I15: 17983 | J15: 17189 | K15: 1162 | L15: 1203 | M15: -436.5 | N15: 135.5
B16: CSX | C16: CSX Corp | D16: 30.45 | E16: 1980 | F16: 77680 | G16: 60163 | H16: 12550 | I16: 14853 | J16: 14707 | K16: 7656 | L16: 7437 | M16: 4166 | N16: 3847
B17: NSC | C17: Norfolk Southern | D17: 199.07 | E17: 226.14 | F17: 60090 | G17: 45017 | H17: 11142 | I17: 12745 | J17: 12320 | K17: 6043 | L17: 4688 | M17: 3270 | N17: 2090
B18: CNI | C18: Canadian National | D18: 112.54 | E18: 647.7 | F18: 86100 | G18: 72908 | H18: 14477 | I18: 17107 | J18: 16899 | K18: 9040 | L18: 8978 | M18: 5118 | N18: 4915
B19: TRN | C19: Trinity Industres | D19: 23.32 | E19: 81.87 | F19: 7580 | G19: 1909 | H19: 1516 | I19: 1977 | J19: 2451 | K19: 334 | L19: 658 | M19: 86 | N19: 94
B20: UNP | C20: Union Pacific | D20: 215.33 | E20: 609.6 | F20: 161370 | G20: 127650 | H20: 21804 | I20: 24875 | J20: 24140 | K20: 12589 | L20: 11860 | M20: 6998 | N20: 6365
B21: GET | C21: Getlink | D21: 16.09 | E21: 540 | F21: 12620 | G21: 8490 | H21: 774 | I21: 1606 | J21: 1962 | K21: 460 | L21: 617 | M21: 252 | N21: 358
C23: Revenue Growth | E23: EBITDA Margin | G23: Profit Margin | I23: EV / Revenue | K23: EV / EBITDA | M23: P / E
C24: 2022 | D24: 2023 | E24: 2022 | F24: 2023 | G24: 2022 | H24: 2023 | I24: 2022 | J24: 2023 | K24: 2022 | L24: 2023 | M24: 2022 | N24: 2023
A25: 0 | B25: =B9 -> WAB | C25: =I9/H9-1 -> 0.14084572 | D25: =J9/I9-1 -> -0.035507136 | E25: =K9/I9 -> 0.50625126 | F25: =L9/J9 -> 0.47064492 | G25: =M9/I9 -> 0.2841005 | H25: =N9/J9 -> 0.26055579 | I25: =$F9/I9 -> 6.4621622 | J25: =$F9/J9 -> 6.7000622 | K25: =$F9/K9 -> 12.764733 | L25: =$F9/L9 -> 14.235917 | M25: =$G9/M9 -> 17.943722 | N25: =$G9/N9 -> 20.285457
A26: 1 | B26: =B10 -> CRRC | C26: =I10/H10-1 -> -0.0528 | D26: =J10/I10-1 -> 0.0069980695 | E26: =K10/I10 -> 0.090733591 | F26: =L10/J10 -> 0.093427989 | G26: =M10/I10 -> 0.042561535 | H26: =N10/J10 -> 0.050563144 | I26: =$F10/I10 -> 0.68837476 | J26: =$F10/J10 -> 0.68359094 | K26: =$F10/K10 -> 7.5867686 | L26: =$F10/L10 -> 7.3167682 | M26: =$G10/M10 -> 13.805103 | N26: =$G10/N10 -> 11.539692
A27: 2 | B27: =B11 -> KTK | C27: =I11/H11-1 -> -0.10612245 | D27: =J11/I11-1 -> -0.0036149163 | E27: =K11/I11 -> 0.090372907 | F27: =L11/J11 -> 0.10101203 | G27: =M11/I11 -> 0.050038052 | H27: =N11/J11 -> 0.067214054 | I27: =$F11/I11 -> 2.1537291 | J27: =$F11/J11 -> 2.1615429 | K27: =$F11/K11 -> 23.831579 | L27: =$F11/L11 -> 21.398866 | M27: =$G11/M11 -> 39.087452 | N27: =$G11/N11 -> 29.204545
A28: 3 | B28: =B12 -> GBX | C28: =I12/H12-1 -> 0.71453089 | D28: =J12/I12-1 -> 0.31598265 | E28: =K12/I12 -> 0.064564565 | F28: =L12/J12 -> 0.082581136 | G28: =M12/I12 -> 0.0058391725 | H28: =N12/J12 -> 0.021729209 | I28: =$F12/I12 -> 0.90930931 | J28: =$F12/J12 -> 0.69097363 | K28: =$F12/K12 -> 14.083721 | L28: =$F12/L12 -> 8.3672091 | M28: =$G12/M12 -> 63.657143 | N28: =$G12/N12 -> 12.998833
A29: 4 | B29: =B13 -> SRAIL | C29: =I13/H13-1 -> -0.011569416 | D29: =J13/I13-1 -> 0.098473282 | E29: =K13/I13 -> 0.081933842 | F29: =L13/J13 -> 0.08501274 | G29: =M13/I13 -> 0.019083969 | H29: =N13/J13 -> 0.037757702 | I29: =$F13/I13 -> 0.97073791 | J29: =$F13/J13 -> 0.88371554 | K29: =$F13/K13 -> 11.847826 | L29: =$F13/L13 -> 10.395095 | M29: =$G13/M13 -> 47.893333 | N29: =$G13/N13 -> 22.03681
A30: 5 | B30: =B14 -> CAF | C30: =I14/H14-1 -> -0.041954023 | D30: =J14/I14-1 -> 0.18716257 | E30: =K14/I14 -> 0.073365327 | F30: =L14/J14 -> 0.074684184 | G30: =M14/I14 -> 0.015776845 | H30: =N14/J14 -> 0.019959576 | I30: =$F14/I14 -> 0.41211758 | J30: =$F14/J14 -> 0.34714502 | K30: =$F14/K14 -> 5.6173344 | L30: =$F14/L14 -> 4.6481732 | M30: =$G14/M14 -> 20.076046 | N30: =$G14/N14 -> 13.367089
A31: 6 | B31: =B15 -> ALO | C31: =I15/H15-1 -> 0.75409676 | D31: =J15/I15-1 -> -0.044152811 | E31: =K15/I15 -> 0.064616582 | F31: =L15/J15 -> 0.069986619 | G31: =M15/I15 -> -0.024272924 | H31: =N15/J15 -> 0.0078829484 | I31: =$F15/I15 -> 0.6700773 | J31: =$F15/J15 -> 0.70102973 | K31: =$F15/K15 -> 10.370052 | L31: =$F15/L15 -> 10.016625 | M31: =$G15/M15 -> -12.632302 | N31: =$G15/N15 -> 40.693727
A32: 7 | B32: =B16 -> CSX | C32: =I16/H16-1 -> 0.18350598 | D32: =J16/I16-1 -> -0.009829664 | E32: =K16/I16 -> 0.51545142 | F32: =L16/J16 -> 0.50567757 | G32: =M16/I16 -> 0.28048206 | H32: =N16/J16 -> 0.26157612 | I32: =$F16/I16 -> 5.2299199 | J32: =$F16/J16 -> 5.2818386 | K32: =$F16/K16 -> 10.14629 | L32: =$F16/L16 -> 10.445072 | M32: =$G16/M16 -> 14.441431 | N32: =$G16/N16 -> 15.638939
A33: 8 | B33: =B17 -> NSC | C33: =I17/H17-1 -> 0.14387004 | D33: =J17/I17-1 -> -0.03334641 | E33: =K17/I17 -> 0.47414672 | F33: =L17/J17 -> 0.38051948 | G33: =M17/I17 -> 0.2565712 | H33: =N17/J17 -> 0.16964286 | I33: =$F17/I17 -> 4.7147901 | J33: =$F17/J17 -> 4.8774351 | K33: =$F17/K17 -> 9.9437366 | L33: =$F17/L17 -> 12.817833 | M33: =$G17/M17 -> 13.766667 | N33: =$G17/N17 -> 21.539234
A34: 9 | B34: =B18 -> CNI | C34: =I18/H18-1 -> 0.18166747 | D34: =J18/I18-1 -> -0.012158765 | E34: =K18/I18 -> 0.52843865 | F34: =L18/J18 -> 0.53127404 | G34: =M18/I18 -> 0.29917578 | H34: =N18/J18 -> 0.29084561 | I34: =$F18/I18 -> 5.0330274 | J34: =$F18/J18 -> 5.094976 | K34: =$F18/K18 -> 9.5243363 | L34: =$F18/L18 -> 9.5901092 | M34: =$G18/M18 -> 14.245408 | N34: =$G18/N18 -> 14.833774
A35: 10 | B35: =B19 -> TRN | C35: =I19/H19-1 -> 0.30408971 | D35: =J19/I19-1 -> 0.23975721 | E35: =K19/I19 -> 0.16894284 | F35: =L19/J19 -> 0.26846185 | G35: =M19/I19 -> 0.043500253 | H35: =N19/J19 -> 0.038351693 | I35: =$F19/I19 -> 3.8340921 | J35: =$F19/J19 -> 3.0926153 | K35: =$F19/K19 -> 22.694611 | L35: =$F19/L19 -> 11.519757 | M35: =$G19/M19 -> 22.197674 | N35: =$G19/N19 -> 20.308511
A36: 11 | B36: UNP | C36: =I20/H20-1 -> 0.14084572 | D36: =J20/I20-1 -> -0.029547739 | E36: =K20/I20 -> 0.50609045 | F36: =L20/J20 -> 0.49130075 | G36: =M20/I20 -> 0.28132663 | H36: =N20/J20 -> 0.26367026 | I36: =$F20/I20 -> 6.4872362 | J36: =$F20/J20 -> 6.6847556 | K36: =$F20/K20 -> 12.818333 | L36: =$F20/L20 -> 13.606239 | M36: =$G20/M20 -> 18.240926 | N36: =$G20/N20 -> 20.054988
A37: 12 | B37: =B21 -> GET | C37: =I21/H21-1 -> 1.0749354 | D37: =J21/I21-1 -> 0.22166874 | E37: =K21/I21 -> 0.2864259 | F37: =L21/J21 -> 0.31447503 | G37: =M21/I21 -> 0.15691158 | H37: =N21/J21 -> 0.18246687 | I37: =$F21/I21 -> 7.8580324 | J37: =$F21/J21 -> 6.432212 | K37: =$F21/K21 -> 27.434783 | L37: =$F21/L21 -> 20.453809 | M37: =$G21/M21 -> 33.690476 | N37: =$G21/N21 -> 23.715084
C39: 2023 Trading Multiple | F39: Enterprise Value | I39: Equity Value | L39: Implied Share Price
C40: Revenue | D40: EBITDA | E40: P/E | F40: Revenue | G40: EBITDA | H40: Net Income | I40: Revenue | J40: EBITDA | K40: Net Income | L40: Share Price | M40: EBITDA | N40: Net Income
B41: Minimum | C41: =MIN(reve) -> 0.34714502 | D41: =MIN(ebi) -> 4.6481732 | E41: =MIN(N25:N37) -> 11.539692 | F41: =C41*$J$9 -> 8328.6201 | G41: =D41*$L$9 -> 52485.313 | H41: =N$9*E41 -> 72136.83 | I41: =F41+cash-debt -> -25609.38 | J41: =G41+cash-debt -> 18547.313 | K41: =H41+cash-debt -> 38198.83 | L41: =I41/E$9 -> -41.989474 | M41: =J41/E$9 -> 30.410416 | N41: =K41/E$9 -> 62.6313
B42: 1st Quartile | C42: =QUARTILE(reve,1) -> 0.70102973 | D42: =QUARTILE(ebi,1) -> 9.5901092 | E42: =QUARTILE(N25:N37,1) -> 14.833774 | F42: =C42*$J$9 -> 16818.937 | G42: =D42*$L$9 -> 108287.68 | H42: =N$9*E42 -> 92728.77 | I42: =F42+cash-debt -> -17119.063 | J42: =G42+cash-debt -> 74349.677 | K42: =H42+cash-debt -> 58790.77 | L42: =I42/E$9 -> -28.068639 | M42: =J42/E$9 -> 121.9047 | N42: =K42/E$9 -> 96.394114
B43: Lower Limit 75% | C43: =C44-0.674*_xlfn.STDEV.S(reve)/SQRT(11) -> 2.8357773 | D43: =D44-0.674*_xlfn.STDEV.S(ebi)/SQRT(11) -> 10.940901 | E43: =E44-0.674*_xlfn.STDEV.S(N25:N37)/SQRT(11) -> 18.88153 | F43: =C43*$J$9 -> 68035.288 | G43: =D43*$L$9 -> 123540.28 | H43: =N$9*E43 -> 118032.07 | I43: =F43+cash-debt -> 34097.288 | J43: =G43+cash-debt -> 89602.277 | K43: =H43+cash-debt -> 84094.069 | L43: =I43/E$9 -> 55.906359 | M43: =J43/E$9 -> 146.91306 | N43: =K43/E$9 -> 137.88173
B44: Mean | C44: =AVERAGE(reve) -> 3.3562994 | D44: =AVERAGE(ebi) -> 11.908575 | E44: =AVERAGE(N25:N37) -> 20.478206 | F44: =C44*$J$9 -> 80523.53 | G44: =D44*$L$9 -> 134466.86 | H44: =N$9*E44 -> 128013.2 | I44: =F44+cash-debt -> 46585.53 | J44: =G44+cash-debt -> 100528.86 | K44: =H44+cash-debt -> 94075.2 | L44: =I44/E$9 -> 76.382243 | M44: =J44/E$9 -> 164.82844 | N44: =K44/E$9 -> 154.24693
B45: Median | C45: =MEDIAN(reve) -> 3.0926153 | D45: =MEDIAN(ebi) -> 10.445072 | E45: =MEDIAN(N25:N37) -> 20.285457 | F45: =C45*$J$9 -> 74197.283 | G45: =D45*$L$9 -> 117941.57 | H45: =N$9*E45 -> 126808.29 | I45: =F45+cash-debt -> 40259.283 | J45: =G45+cash-debt -> 84003.574 | K45: =H45+cash-debt -> 92870.285 | L45: =I45/E$9 -> 66.009646 | M45: =J45/E$9 -> 137.73336 | N45: =K45/E$9 -> 152.27133
B46: Upper Limit 75% | C46: =C44+0.674*_xlfn.STDEV.S(reve)/SQRT(11) -> 3.8768216 | D46: =D44+0.674*_xlfn.STDEV.S(ebi)/SQRT(11) -> 12.876249 | E46: =E44+0.674*_xlfn.STDEV.S(N25:N37)/SQRT(11) -> 22.074883 | F46: =C46*$J$9 -> 93011.772 | G46: =D46*$L$9 -> 145393.45 | H46: =N$9*E46 -> 137994.33 | I46: =F46+cash-debt -> 59073.772 | J46: =G46+cash-debt -> 111455.45 | K46: =H46+cash-debt -> 104056.33 | L46: =I46/E$9 -> 96.858128 | M46: =J46/E$9 -> 182.74381 | N46: =K46/E$9 -> 170.61212
...

Sheet Summary
A1: CSX Corp (CSX US) - BBG Adj Highlights | L1: CSX Corp (CSX US) - Growth | AX1: CSX Corp (CSX US) - L#1518025
A3: In Millions of USD | C3: FY 2018 | D3: FY 2019 | E3: FY 2020 | F3: FY 2021 | G3: FY 2022 | H3: Current/LTM | I3: FY 2023 Est | J3: FY 2024 Est | L3: In Millions of USD except Per Share | N3: FY 1988 | O3: FY 1989 | P3: FY 1990 | Q3: FY 1991 | R3: FY 1992 | S3: FY 1993 | T3: FY 1994 | U3: FY 1995 | V3: FY 1996 | W3: FY 1997 | X3: FY 1998 | Y3: FY 1999 | Z3: FY 2000 | AA3: FY 2001 | AB3: FY 2002 | AC3: FY 2003 | AD3: FY 2004 | AE3: FY 2005 | AF3: FY 2006 | AG3: FY 2007 | AH3: FY 2008 | AI3: FY 2009 | AJ3: FY 2010 | AK3: FY 2011 | AL3: FY 2012 | AM3: FY 2013 | AN3: FY 2014 | AO3: FY 2015 | AP3: FY 2016 | AQ3: FY 2017 | AR3: FY 2018 | AS3: FY 2019 | AT3: FY 2020 | AU3: FY 2021 | AV3: FY 2022 | AX3: WACC History | AZ3: FY 2022 | BA3: FY 2021 | BB3: FY 2020 | BC3: FY 2019 | BD3: FY 2018 | BE3: FY 2017 | BF3: FY 2016 | BG3: FY 2015 | BH3: FY 2014 | BI3: FY 2013 | BJ3: FY 2012 | BK3: FY 2011 | BL3: FY 2010 | BM3: FY 2009 | BN3: FY 2008 | BO3: FY 2007 | BP3: FY 2006 | BQ3: FY 2005 | BR3: FY 2004 | BS3: FY 2003
A4: 12 Months Ending | C4: 12/31/2018 | D4: 12/31/2019 | E4: 12/31/2020 | F4: 12/31/2021 | G4: 12/31/2022 | H4: 09/30/2023 | I4: 12/31/2023 | J4: 12/31/2024 | L4: 12 Months Ending | N4: 12/31/1988 | O4: 12/31/1989 | P4: 12/31/1990 | Q4: 12/31/1991 | R4: 12/31/1992 | S4: 12/31/1993 | T4: 12/30/1994 | U4: 12/30/1995 | V4: 12/31/1996 | W4: 12/26/1997 | X4: 12/31/1998 | Y4: 12/31/1999 | Z4: 12/29/2000 | AA4: 12/28/2001 | AB4: 12/27/2002 | AC4: 12/26/2003 | AD4: 12/31/2004 | AE4: 12/30/2005 | AF4: 12/29/2006 | AG4: 12/28/2007 | AH4: 12/26/2008 | AI4: 12/25/2009 | AJ4: 12/31/2010 | AK4: 12/30/2011 | AL4: 12/28/2012 | AM4: 12/27/2013 | AN4: 12/26/2014 | AO4: 12/25/2015 | AP4: 12/30/2016 | AQ4: 12/31/2017 | AR4: 12/31/2018 | AS4: 12/31/2019 | AT4: 12/31/2020 | AU4: 12/31/2021 | AV4: 12/31/2022 | AX4: 12 Months Ending | AZ4: 12/31/2022 | BA4: 12/31/2021 | BB4: 12/31/2020 | BC4: 12/31/2019 | BD4: 12/31/2018 | BE4: 12/31/2017 | BF4: 12/30/2016 | BG4: 12/25/2015 | BH4: 12/26/2014 | BI4: 12/27/2013 | BJ4: 12/28/2012 | BK4: 12/30/2011 | BL4: 12/31/2010 | BM4: 12/25/2009 | BN4: 12/26/2008 | BO4: 12/28/2007 | BP4: 12/29/2006 | BQ4: 12/30/2005 | BR4: 12/31/2004 | BS4: 12/26/2003
A5: Market Capitalization | B5: HISTORICAL_MARKET_CAP | C5: 100224.59 | D5: 125124.88 | E5: 139788.78 | F5: 160943.38 | G5: 126808.29 | H5: 136720.53 | L5: 1 Year Growth | N5: {=GEOMEAN(AR6:AV6/100+1)-1} -> 0.032100101 | AX5: Equity
A6: - Cash & Equivalents | B6: CASH_AND_MARKETABLE_SECURITIES | C6: 1333 | D6: 891 | E6: 1859 | F6: 1006 | G6: 1019 | H6: 766 | L6: Revenue | M6: SALES_GROWTH | AC6: =_xll.BDH("UNP US Equity","SALES_GROWTH","FY 2003","FY 2003","Currency=USD","Period=FY","BEST_FPERIOD_OVERRIDE=FY","FILING_STATUS=MR","FA_ADJUSTED=GAAP","Sort=A","Dates=H","DateFormat=P","Fill=—","Direction=H","UseDPDF=Y") -> 3.5129 | AD6: =_xll.BDH("UNP US Equity","SALES_GROWTH","FY 2004","FY 2004","Currency=USD","Period=FY","BEST_FPERIOD_OVERRIDE=FY","FILING_STATUS=MR","FA_ADJUSTED=GAAP","Sort=A","Dates=H","DateFormat=P","Fill=—","Direction=H","UseDPDF=Y") -> 5.7484 | AE6: =_xll.BDH("UNP US Equity","SALES_GROWTH","FY 2005","FY 2005","Currency=USD","Period=FY","BEST_FPERIOD_OVERRIDE=FY","FILING_STATUS=MR","FA_ADJUSTED=GAAP","Sort=A","Dates=H","DateFormat=P","Fill=—","Direction=H","UseDPDF=Y") -> 11.1584 | AF6: =_xll.BDH("UNP US Equity","SALES_GROWTH","FY 2006","FY 2006","Currency=USD","Period=FY","BEST_FPERIOD_OVERRIDE=FY","FILING_STATUS=MR","FA_ADJUSTED=GAAP","Sort=A","Dates=H","DateFormat=P","Fill=—","Direction=H","UseDPDF=Y") -> 14.7297 | AG6: =_xll.BDH("UNP US Equity","SALES_GROWTH","FY 2007","FY 2007","Currency=USD","Period=FY","BEST_FPERIOD_OVERRIDE=FY","FILING_STATUS=MR","FA_ADJUSTED=GAAP","Sort=A","Dates=H","DateFormat=P","Fill=—","Direction=H","UseDPDF=Y") -> 4.5256 | AH6: =_xll.BDH("UNP US Equity","SALES_GROWTH","FY 2008","FY 2008","Currency=USD","Period=FY","BEST_FPERIOD_OVERRIDE=FY","FILING_STATUS=MR","FA_ADJUSTED=GAAP","Sort=A","Dates=H","DateFormat=P","Fill=—","Direction=H","UseDPDF=Y") -> 10.3605 | AI6: =_xll.BDH("UNP US Equity","SALES_GROWTH","FY 2009","FY 2009","Currency=USD","Period=FY","BEST_FPERIOD_OVERRIDE=FY","FILING_STATUS=MR","FA_ADJUSTED=GAAP","Sort=A","Dates=H","DateFormat=P","Fill=—","Direction=H","UseDPDF=Y") -> -21.2966 | AJ6: =_xll.BDH("UNP US Equity","SALES_GROWTH","FY 2010","FY 2010","Currency=USD","Period=FY","BEST_FPERIOD_OVERRIDE=FY","FILING_STATUS=MR","FA_ADJUSTED=GAAP","Sort=A","Dates=H","DateFormat=P","Fill=—","Direction=H","UseDPDF=Y") -> 19.9533 | AK6: =_xll.BDH("UNP US Equity","SALES_GROWTH","FY 2011","FY 2011","Currency=USD","Period=FY","BEST_FPERIOD_OVERRIDE=FY","FILING_STATUS=MR","FA_ADJUSTED=GAAP","Sort=A","Dates=H","DateFormat=P","Fill=—","Direction=H","UseDPDF=Y") -> 15.2785 | AL6: =_xll.BDH("UNP US Equity","SALES_GROWTH","FY 2012","FY 2012","Currency=USD","Period=FY","BEST_FPERIOD_OVERRIDE=FY","FILING_STATUS=MR","FA_ADJUSTED=GAAP","Sort=A","Dates=H","DateFormat=P","Fill=—","Direction=H","UseDPDF=Y") -> 7.0001 | AM6: =_xll.BDH("UNP US Equity","SALES_GROWTH","FY 2013","FY 2013","Currency=USD","Period=FY","BEST_FPERIOD_OVERRIDE=FY","FILING_STATUS=MR","FA_ADJUSTED=GAAP","Sort=A","Dates=H","DateFormat=P","Fill=—","Direction=H","UseDPDF=Y") -> 4.9556 | AN6: =_xll.BDH("UNP US Equity","SALES_GROWTH","FY 2014","FY 2014","Currency=USD","Period=FY","BEST_FPERIOD_OVERRIDE=FY","FILING_STATUS=MR","FA_ADJUSTED=GAAP","Sort=A","Dates=H","DateFormat=P","Fill=—","Direction=H","UseDPDF=Y") -> 9.2201 | AO6: =_xll.BDH("UNP US Equity","SALES_GROWTH","FY 2015","FY 2015","Currency=USD","Period=FY","BEST_FPERIOD_OVERRIDE=FY","FILING_STATUS=MR","FA_ADJUSTED=GAAP","Sort=A","Dates=H","DateFormat=P","Fill=—","Direction=H","UseDPDF=Y") -> -9.067 | AP6: =_xll.BDH("UNP US Equity","SALES_GROWTH","FY 2016","FY 2016","Currency=USD","Period=FY","BEST_FPERIOD_OVERRIDE=FY","FILING_STATUS=MR","FA_ADJUSTED=GAAP","Sort=A","Dates=H","DateFormat=P","Fill=—","Direction=H","UseDPDF=Y") -> -8.582 | AQ6: =_xll.BDH("UNP US Equity","SALES_GROWTH","FY 2017","FY 2017","Currency=USD","Period=FY","BEST_FPERIOD_OVERRIDE=FY","FILING_STATUS=MR","FA_ADJUSTED=GAAP","Sort=A","Dates=H","DateFormat=P","Fill=—","Direction=H","UseDPDF=Y") -> 6.5142 | AR6: =_xll.BDH("UNP US Equity","SALES_GROWTH","FY 2018","FY 2018","Currency=USD","Period=FY","BEST_FPERIOD_OVERRIDE=FY","FILING_STATUS=MR","FA_ADJUSTED=GAAP","Sort=A","Dates=H","DateFormat=P","Fill=—","Direction=H","UseDPDF=Y") -> 7.4953 | AS6: =_xll.BDH("UNP US Equity","SALES_GROWTH","FY 2019","FY 2019","Currency=USD","Period=FY","BEST_FPERIOD_OVERRIDE=FY","FILING_STATUS=MR","FA_ADJUSTED=GAAP","Sort=A","Dates=H","DateFormat=P","Fill=—","Direction=H","UseDPDF=Y") -> -4.9229 | AT6: =_xll.BDH("UNP US Equity","SALES_GROWTH","FY 2020","FY 2020","Currency=USD","Period=FY","BEST_FPERIOD_OVERRIDE=FY","FILING_STATUS=MR","FA_ADJUSTED=GAAP","Sort=A","Dates=H","DateFormat=P","Fill=—","Direction=H","UseDPDF=Y") -> -10.0193 | AU6: =_xll.BDH("UNP US Equity","SALES_GROWTH","FY 2021","FY 2021","Currency=USD","Period=FY","BEST_FPERIOD_OVERRIDE=FY","FILING_STATUS=MR","FA_ADJUSTED=GAAP","Sort=A","Dates=H","DateFormat=P","Fill=—","Direction=H","UseDPDF=Y") -> 11.6265 | AV6: =_xll.BDH("UNP US Equity","SALES_GROWTH","FY 2022","FY 2022","Currency=USD","Period=FY","BEST_FPERIOD_OVERRIDE=FY","FILING_STATUS=MR","FA_ADJUSTED=GAAP","Sort=A","Dates=H","DateFormat=P","Fill=—","Direction=H","UseDPDF=Y") -> 14.0846 | AX6: Cost of Equity | AY6: WACC_COST_EQUITY | AZ6: 8.23 | BA6: 9.9753 | BB6: 8.8113 | BC6: 9.0663 | BD6: 11.8505 | BE6: 10.1221 | BF6: 10.5031 | BG6: 10.7549 | BH6: 9.9474 | BI6: 11.2585 | BJ6: 12.3654 | BK6: 13.0941 | BL6: 15.0257 | BM6: 11.5097 | BN6: 11.7515 | BO6: 11.9134 | BP6: 11.6332 | BQ6: 10.9957 | BR6: 9.3144 | BS6: 9.0797
A7: + Preferred & Other | B7: PFD_EQTY_MINORTY_INTEREST | C7: 0 | D7: 0 | E7: 0 | F7: 0 | G7: 0 | H7: 0 | L7: EBITDA | M7: EBITDA_GROWTH | N7: -4.378 | O7: -4.3605 | P7: -2.1277 | Q7: 5.2019 | R7: 10.1107 | S7: -0.4692 | T7: 21.8182 | U7: 12.1614 | V7: 5.5692 | W7: 6.0224 | X7: -22.5011 | Y7: -32.1591 | Z7: 17.6717 | AA7: 12.3843 | AB7: 12.4763 | AC7: -34.5158 | AD7: 48.7532 | AE7: 37.7457 | AF7: 26.1016 | AG7: 4.6922 | AH7: 17.1647 | AI7: -13.9175 | AJ7: 26.6309 | AK7: 10.6521 | AL7: 1.5744 | AM7: 1.3508 | AN7: 4.0856 | AO7: 0.5877 | AP7: -2.1285 | AQ7: 7.3561 | AR7: 23.138 | AS7: 3.1935 | AT7: -8.9247 | AU7: 21.8981 | AV7: 7.4476 | AX7: Weight of Equity | AY7: WACC_WEIGHT_OF_EQUITY | AZ7: 77.4825 | BA7: 83.0403 | BB7: 92.3467 | BC7: 76.9257 | BD7: 77.5013 | BE7: 80.5644 | BF7: 74.7035 | BG7: 70.5429 | BH7: 78.8739 | BI7: 74.9184 | BJ7: 66.851 | BK7: 70.5102 | BL7: 73.3986 | BM7: 71.21 | BN7: 61.0998 | BO7: 71.3311 | BP7: 71.6557 | BQ7: 64.7537 | BR7: 54.0901 | BS7: 51.1861
A8: + Total Debt | B8: SHORT_AND_LONG_TERM_DEBT | C8: 22391 | D8: 27033 | E8: 28333 | F8: 31488 | G8: 34957 | H8: 34483 | L8: Operating Income | M8: OPER_INC_GROWTH | N8: 1.5642 | O8: -4.4004 | P8: -6.214 | Q8: 4.7853 | R8: 12.9977 | S8: -5.3886 | T8: 34.9398 | U8: 15.9903 | V8: 6.508 | W8: 4.0079 | X8: -28.6166 | Y8: -49.292 | Z8: 40.4887 | AA8: 18.882 | AB8: 17.7638 | AC8: -53.8598 | AD8: 92.3077 | AE8: 55 | AF8: 37.9355 | AG8: 5.5192 | AH8: 22.695 | AI8: -17.9913 | AJ8: 35.2863 | AK8: 12.9925 | AL8: -0.3746 | AM8: 0.4628 | AN8: 4.0311 | AO8: -0.8027 | AP8: -5.4408 | AQ8: 9.7669 | AR8: 30.8871 | AS8: 1.9717 | AT8: -12.145 | AU8: 28.2439 | AV8: 7.6689 | AX8: + Debt
A9: Enterprise Value | B9: ENTERPRISE_VALUE | C9: 121282.59 | D9: 151266.88 | E9: 166262.78 | F9: 191425.38 | G9: 160746.29 | H9: 170437.53 | L9: Net Income to Common | M9: EARN_FOR_COM_GROWTH | N9: 0.7353 | O9: 220.438 | P9: -7.2893 | Q9: — | R9: — | S9: 1695 | T9: 81.6156 | U9: -5.2147 | V9: 38.3495 | W9: -6.5497 | X9: -32.791 | Y9: -99.6276 | Z9: 28150 | AA9: -48.1416 | AB9: 44.7099 | AC9: -41.9811 | AD9: 37.8049 | AE9: 237.7581 | AF9: 14.4105 | AG9: 1.9847 | AH9: 2.1707 | AI9: -16.2637 | AJ9: 36.7454 | AK9: 18.682 | AL9: 0.2156 | AM9: 0.2152 | AN9: 3.3816 | AO9: 2.1288 | AP9: -12.9131 | AQ9: 219.3228 | AR9: -39.5247 | AS9: 0.6953 | AT9: -16.9919 | AU9: 36.745 | AV9: 10.1825 | AX9: Cost of Debt | AY9: WACC_COST_DEBT | AZ9: 4.1244 | BA9: 1.5807 | BB9: 0.9397 | BC9: 2.0369 | BD9: 2.8496 | BE9: 3.3206 | BF9: 2.079 | BG9: 1.9388 | BH9: 1.936 | BI9: 2.5144 | BJ9: 1.4206 | BK9: 1.6093 | BL9: 2.8116 | BM9: 3.5887 | BN9: 1.9549 | BO9: 3.7171 | BP9: 4.7908 | BQ9: 4.3609 | BR9: 3.7945 | BS9: 4.0281
L10: EPS Diluted | M10: DILUTED_EPS_AFT_XO_ITEMS_GROWTH | N10: 5.6818 | O10: 366.6667 | P10: -4.3779 | Q10: — | R10: — | S10: 1721.0526 | T10: 80.0578 | U10: -5.618 | V10: 34.6939 | W10: -6.0606 | X10: -32.5269 | Y10: -99.6016 | Z10: 26600 | AA10: -48.3146 | AB10: 44.2029 | AC10: -44.2211 | AD10: 36.9369 | AE10: 231.5789 | AF10: 11.9048 | AG10: 6.0284 | AH10: 11.7057 | AI10: -13.4731 | AJ10: 40.1384 | AK10: 25.9259 | AL10: 5.2941 | AM10: 2.2346 | AN10: 4.918 | AO10: 4.1667 | AP10: -9.5 | AQ10: 230.9392 | AR10: -35.8932 | AS10: 8.5938 | AT10: -71.223 | AU10: 320 | AV10: 16.0714 | AX10: Weight of Debt | AY10: WACC_WEIGHT_OF_DEBT | AZ10: 22.5175 | BA10: 16.9597 | BB10: 7.6533 | BC10: 23.0743 | BD10: 22.4987 | BE10: 19.4356 | BF10: 25.2965 | BG10: 29.4571 | BH10: 21.1261 | BI10: 25.0816 | BJ10: 33.149 | BK10: 29.4898 | BL10: 26.6014 | BM10: 28.79 | BN10: 38.9002 | BO10: 28.6689 | BP10: 28.3443 | BQ10: 35.2463 | BR10: 45.9099 | BS10: 48.8139
A11: Revenue, Adj | B11: SALES_REV_TURN | C11: 22832 | D11: 21708 | E11: 19533 | F11: 21804 | G11: 24875 | H11: 24140 | I11: 23991.76 | J11: 25025.16 | L11: EPS Diluted before XO | M11: DILUTED_EPS_BEF_XO_ITEMS_GROWTH | N11: — | O11: — | P11: -11.2469 | Q11: — | R11: — | S11: 1721.0526 | T11: 80.0578 | U11: -5.618 | V11: 34.6939 | W11: -6.0606 | X11: -32.5269 | Y11: -90.4382 | Z11: 265.1921 | AA11: 57.4514 | AB11: 58.6957 | AC11: -71.2329 | AD11: 196.8254 | AE11: 69.5187 | AF11: 77.918 | AG11: -2.8369 | AH11: 33.5766 | AI11: -22.1311 | AJ11: 42.1053 | AK11: 25.9259 | AL11: 5.2941 | AM11: 2.2346 | AN11: 4.918 | AO11: 4.1667 | AP11: -9.5 | AQ11: 230.9392 | AR11: -35.8932 | AS11: 8.5938 | AT11: -71.223 | AU11: 320 | AV11: 16.0714 | AX11: + Preferred Equity
A12: Growth %, YoY | B12: SALES_GROWTH | C12: 7.4953 | D12: -4.9229 | E12: -10.0193 | F12: 11.6265 | G12: 14.0846 | H12: -1.1789749 | I12: -3.5507136 | J12: 4.3073122 | L12: EPS Diluted before Abnormal | M12: RR_DIL_EPS_CONT_OPS_GROWTH | N12: — | O12: — | P12: -11.2469 | Q12: — | R12: — | S12: 1721.0526 | T12: 80.0578 | U12: -5.618 | V12: 34.6939 | W12: 5.303 | X12: -52.0384 | Y12: -92.5 | Z12: 486.6667 | AA12: 56.8182 | AB12: 44.2029 | AC12: -42.7136 | AD12: 64.0351 | AE12: 69.5187 | AF12: 77.918 | AG12: -4.2553 | AH12: 35.5556 | AI12: -22.1311 | AJ12: 45.3434 | AK12: 23.1204 | AL12: -0.625 | AM12: 5.0118 | AN12: 10.2385 | AO12: -0.7736 | AP12: -7.2455 | AQ12: 24.7399 | AR12: 65.4584 | AS12: 7.7674 | AT12: -70.326 | AU12: 279.1495 | AV12: 21.849 | AX12: Cost of Pref. Equity | AY12: WACC_COST_PFD | AZ12: 0 | BA12: 0 | BB12: 0 | BC12: 0 | BD12: 0 | BE12: 0 | BF12: 0 | BG12: 0 | BH12: 0 | BI12: 0 | BJ12: 0 | BK12: 0 | BL12: 0 | BM12: 0 | BN12: 0 | BO12: 0 | BP12: 0 | BQ12: 0 | BR12: 0 | BS12: 0
A13: Gross Profit, Adj | B13: GROSS_PROFIT | C13: — | D13: — | E13: — | F13: — | G13: — | I13: 8975.7973 | J13: 9995.7997 | L13: Dividend per Share | M13: DIVIDEND_PER_SHARE_1_YEAR_GROWTH | N13: 11.2069 | O13: -0.7752 | P13: 9.375 | Q13: 2.1429 | R13: 6.2937 | S13: 3.9474 | T13: 11.3924 | U13: 4.5455 | V13: 13.0435 | W13: 3.8462 | X13: 11.1111 | Y13: 0 | Z13: 0 | AA13: -33.3333 | AB13: -50 | AC13: 0 | AD13: 0 | AE13: 7.5 | AF13: 53.4884 | AG13: 63.6364 | AH13: 42.5926 | AI13: 14.2857 | AJ13: 12.5 | AK13: 36.3636 | AL13: 20 | AM13: 9.2593 | AN13: 6.7797 | AO13: 11.1111 | AP13: 2.8571 | AQ13: 8.3333 | AR13: 12.8205 | AS13: 227.2727 | AT13: -87.9167 | AU13: 220.6896 | AV13: 7.5269 | AX13: Weight of Pref. Equity | AY13: WACC_WEIGHT_OF_PREFERRED_EQUITY | AZ13: 0 | BA13: 0 | BB13: 0 | BC13: 0 | BD13: 0 | BE13: 0 | BF13: 0 | BG13: 0 | BH13: 0 | BI13: 0 | BJ13: 0 | BK13: 0 | BL13: 0 | BM13: 0 | BN13: 0 | BO13: 0 | BP13: 0 | BQ13: 0 | BR13: 0 | BS13: 0
A14: Margin % | B14: GROSS_PROFIT | C14: — | D14: — | E14: — | F14: — | G14: — | I14: 37.412 | J14: 39.943 | AX14: WACC | AY14: WACC | AZ14: =_xll.BDH("UNP US Equity","WACC","FY 2022","FY 2022","Currency=USD","Period=FY","BEST_FPERIOD_OVERRIDE=FY","FILING_STATUS=MR","Sort=D","Dates=H","DateFormat=P","Fill=—","Direction=H","UseDPDF=Y") -> 7.0156 | BA14: =_xll.BDH("UNP US Equity","WACC","FY 2021","FY 2021","Currency=USD","Period=FY","BEST_FPERIOD_OVERRIDE=FY","FILING_STATUS=MR","Sort=D","Dates=H","DateFormat=P","Fill=—","Direction=H","UseDPDF=Y") -> 8.9158 | BB14: =_xll.BDH("UNP US Equity","WACC","FY 2020","FY 2020","Currency=USD","Period=FY","BEST_FPERIOD_OVERRIDE=FY","FILING_STATUS=MR","Sort=D","Dates=H","DateFormat=P","Fill=—","Direction=H","UseDPDF=Y") -> 7.6743 | BC14: =_xll.BDH("UNP US Equity","WACC","FY 2019","FY 2019","Currency=USD","Period=FY","BEST_FPERIOD_OVERRIDE=FY","FILING_STATUS=MR","Sort=D","Dates=H","DateFormat=P","Fill=—","Direction=H","UseDPDF=Y") -> 7.3163 | BD14: =_xll.BDH("UNP US Equity","WACC","FY 2018","FY 2018","Currency=USD","Period=FY","BEST_FPERIOD_OVERRIDE=FY","FILING_STATUS=MR","Sort=D","Dates=H","DateFormat=P","Fill=—","Direction=H","UseDPDF=Y") -> 9.3826 | BE14: =_xll.BDH("UNP US Equity","WACC","FY 2017","FY 2017","Currency=USD","Period=FY","BEST_FPERIOD_OVERRIDE=FY","FILING_STATUS=MR","Sort=D","Dates=H","DateFormat=P","Fill=—","Direction=H","UseDPDF=Y") -> 7.7235 | BF14: =_xll.BDH("UNP US Equity","WACC","FY 2016","FY 2016","Currency=USD","Period=FY","BEST_FPERIOD_OVERRIDE=FY","FILING_STATUS=MR","Sort=D","Dates=H","DateFormat=P","Fill=—","Direction=H","UseDPDF=Y") -> 8.0489 | BG14: =_xll.BDH("UNP US Equity","WACC","FY 2015","FY 2015","Currency=USD","Period=FY","BEST_FPERIOD_OVERRIDE=FY","FILING_STATUS=MR","Sort=D","Dates=H","DateFormat=P","Fill=—","Direction=H","UseDPDF=Y") -> 8.9576 | BH14: =_xll.BDH("UNP US Equity","WACC","FY 2014","FY 2014","Currency=USD","Period=FY","BEST_FPERIOD_OVERRIDE=FY","FILING_STATUS=MR","Sort=D","Dates=H","DateFormat=P","Fill=—","Direction=H","UseDPDF=Y") -> 8.6918 | BI14: =_xll.BDH("UNP US Equity","WACC","FY 2013","FY 2013","Currency=USD","Period=FY","BEST_FPERIOD_OVERRIDE=FY","FILING_STATUS=MR","Sort=D","Dates=H","DateFormat=P","Fill=—","Direction=H","UseDPDF=Y") -> 8.9777 | BJ14: =_xll.BDH("UNP US Equity","WACC","FY 2012","FY 2012","Currency=USD","Period=FY","BEST_FPERIOD_OVERRIDE=FY","FILING_STATUS=MR","Sort=D","Dates=H","DateFormat=P","Fill=—","Direction=H","UseDPDF=Y") -> 10.0191 | BK14: =_xll.BDH("UNP US Equity","WACC","FY 2011","FY 2011","Currency=USD","Period=FY","BEST_FPERIOD_OVERRIDE=FY","FILING_STATUS=MR","Sort=D","Dates=H","DateFormat=P","Fill=—","Direction=H","UseDPDF=Y") -> 10.3805 | BL14: =_xll.BDH("UNP US Equity","WACC","FY 2010","FY 2010","Currency=USD","Period=FY","BEST_FPERIOD_OVERRIDE=FY","FILING_STATUS=MR","Sort=D","Dates=H","DateFormat=P","Fill=—","Direction=H","UseDPDF=Y") -> 11.7584 | BM14: =_xll.BDH("UNP US Equity","WACC","FY 2009","FY 2009","Currency=USD","Period=FY","BEST_FPERIOD_OVERRIDE=FY","FILING_STATUS=MR","Sort=D","Dates=H","DateFormat=P","Fill=—","Direction=H","UseDPDF=Y") -> 9.0324 | BN14: =_xll.BDH("UNP US Equity","WACC","FY 2008","FY 2008","Currency=USD","Period=FY","BEST_FPERIOD_OVERRIDE=FY","FILING_STATUS=MR","Sort=D","Dates=H","DateFormat=P","Fill=—","Direction=H","UseDPDF=Y") -> 8.5613 | BO14: =_xll.BDH("UNP US Equity","WACC","FY 2007","FY 2007","Currency=USD","Period=FY","BEST_FPERIOD_OVERRIDE=FY","FILING_STATUS=MR","Sort=D","Dates=H","DateFormat=P","Fill=—","Direction=H","UseDPDF=Y") -> 10.3763 | BP14: =_xll.BDH("UNP US Equity","WACC","FY 2006","FY 2006","Currency=USD","Period=FY","BEST_FPERIOD_OVERRIDE=FY","FILING_STATUS=MR","Sort=D","Dates=H","DateFormat=P","Fill=—","Direction=H","UseDPDF=Y") -> 8.9917 | BQ14: =_xll.BDH("UNP US Equity","WACC","FY 2005","FY 2005","Currency=USD","Period=FY","BEST_FPERIOD_OVERRIDE=FY","FILING_STATUS=MR","Sort=D","Dates=H","DateFormat=P","Fill=—","Direction=H","UseDPDF=Y") -> 8.1771 | BR14: =_xll.BDH("UNP US Equity","WACC","FY 2004","FY 2004","Currency=USD","Period=FY","BEST_FPERIOD_OVERRIDE=FY","FILING_STATUS=MR","Sort=D","Dates=H","DateFormat=P","Fill=—","Direction=H","UseDPDF=Y") -> 6.88 | BS14: =_xll.BDH("UNP US Equity","WACC","FY 2003","FY 2003","Currency=USD","Period=FY","BEST_FPERIOD_OVERRIDE=FY","FILING_STATUS=MR","Sort=D","Dates=H","DateFormat=P","Fill=—","Direction=H","UseDPDF=Y") -> 6.7372
A15: EBITDA, Adj | B15: EBITDA | C15: 10708 | D15: 11136 | E15: 10570 | F15: 11849 | G15: 12593 | H15: 11363 | I15: 11291.6 | J15: 12238.917 | L15: Accounts Receivable | M15: ACCOUNTS_RECEIVABLE_GROWTH | N15: 2.2831 | O15: -28.0134 | P15: 12.8682 | Q15: 0 | R15: -16.8956 | S15: 10.4132 | T15: 5.6886 | U15: 17.847 | V15: 7.4519 | W15: 10.4027 | X15: -9.0172 | Y15: 26.392 | Z15: -25.1101 | AA15: 3.2941 | AB15: -8.9977 | AC15: 45.5569 | AD15: -0.3439 | AE15: 3.7101 | AF15: -2.3295 | AG15: 0 | AH15: -5.707 | AI15: -10.1174 | AJ15: -0.201 | AK15: 0.7049 | AL15: -3.8 | AM15: 9.3555 | AN15: 7.3194 | AO15: -13.0204 | AP15: -4.4807 | AQ15: 3.4115 | AR15: 4.1237 | AS15: -2.3762 | AT15: -7.5051 | AU15: 25.8772 | AV15: 14.3728 | AY15: =AVERAGE(AZ14:BS14) -> 8.680905 | AZ15: =(AZ14-BA14)/BA14 -> -0.21312726 | BA15: =(BA14-BB14)/BB14 -> 0.16177371 | BB15: =(BB14-BC14)/BC14 -> 0.048931837 | BC15: =(BC14-BD14)/BD14 -> -0.2202268 | BD15: =(BD14-BE14)/BE14 -> 0.21481194 | BE15: =(BE14-BF14)/BF14 -> -0.040427885 | BF15: =(BF14-BG14)/BG14 -> -0.10144458 | BG15: =(BG14-BH14)/BH14 -> 0.030580547 | ... BO15: =(BO14-BP14)/BP14 -> 0.15398645
A16: Margin % | B16: EBITDA | C16: 46.899089 | D16: 51.29906 | E16: 54.113551 | F16: 54.34324 | G16: 50.625126 | H16: 47.071251 | I16: 47.064492 | J16: 48.906449 | L16: Inventory | M16: INVENTORY_GROWTH | N16: -33.6088 | O16: -1.6598 | P16: 8.4388 | Q16: -19.8444 | R16: -8.2524 | S16: 5.291 | T16: 6.0302 | U16: 4.2654 | V16: 4.0909 | W16: -0.8734 | X16: -0.8811 | Y16: -2.2222 | Z16: 11.3636 | AA16: -15.9184 | AB16: -12.6214 | AC16: -5.5556 | AD16: -2.9412 | AE16: 20.6061 | AF16: 2.5126 | AG16: 17.6471 | AH16: -9.5833 | AI16: -6.4516 | AJ16: 7.3892 | AK16: 10.0917 | AL16: 14.1667 | AM16: -8.0292 | AN16: 8.3333 | AO16: 28.2051 | AP16: 16.2857 | AQ16: -8.5995 | AR16: -29.3011 | AS16: -0.7605 | AT16: 15.7088 | AU16: 12.2517 | AV16: 0.59 | AX16: Capital Structure | BS16: {=GEOMEAN(AZ15:BO15/100+1)-1} -> -4.5499138e-05
A17: Net Income, Adj | B17: EARN_FOR_COMMON | C17: 6027.62 | D17: 5903.2 | E17: 5510.463 | F17: 6417.14 | G17: 7067 | H17: 6348 | I17: 6251.192 | J17: 6836.885 | L17: Fixed Assets | M17: NET_FIXED_ASSETS_1_YEAR_GROWTH | N17: -5.2253 | O17: 0.218 | P17: 3.5122 | Q17: 1.8617 | R17: 4.5102 | S17: 1.4291 | T17: 2.373 | U17: 2.2908 | V17: 5.3908 | W17: 4.1996 | X17: 1.9265 | Y17: -3.0684 | Z17: 3.1411 | AA17: 2.6103 | AB17: 2.4206 | AC17: 3.3419 | AD17: 45.2658 | AE17: 1.093 | AF17: 3.7693 | AG17: 4.096 | AH17: 4.169 | AI17: 1.6573 | AJ17: 3.1868 | AK17: 4.9372 | AL17: 4.3085 | AM17: 4.7639 | AN17: 4.7378 | AO17: 5.5626 | AP17: 3.2346 | AQ17: 1.9711 | AR17: 0.7367 | AS17: 2.1939 | AT17: 0.6606 | AU17: 1.8228 | AV17: 3.6729 | AX17: + Historical Market Cap | AY17: HISTORICAL_MARKET_CAP | AZ17: 64016.05 | BA17: 82787.191 | BB17: 207598.52 | BC17: 55968.362 | BD17: 50833.523 | BE17: 48950.704 | BF17: 33349.507 | BG17: 25228.881 | BH17: 36371.558 | BI17: 28540.649 | BJ17: 19828.024 | BK17: 22095.246 | BL17: 23905.7 | BM17: 19807.2 | BN17: 12301.569 | BO17: 18056.139 | BP17: 15072.215 | BQ17: 11078.166 | BR17: 8638.4023 | BS17: 7669.4319
A18: Margin % | B18: EARN_FOR_COMMON | C18: 26.399877 | D18: 27.193661 | E18: 28.211043 | F18: 29.431022 | G18: 28.41005 | H18: 26.296603 | I18: 26.055579 | J18: 27.320045 | L18: Total Assets | M18: ASSET_GROWTH | N18: -1.5494 | O18: -5.5888 | P18: 4.1145 | Q18: -0.0469 | R18: 1.9612 | S18: 2.8431 | T18: 2.2653 | U18: 4.0659 | V18: 18.7859 | W18: 17.6363 | X18: 2.3551 | Y18: 1.4344 | Z18: -1.1052 | AA18: 1.5129 | AB18: 0.7211 | AC18: 3.8614 | AD18: 13.0744 | AE18: -1.516 | AF18: 3.7017 | AG18: 1.6117 | AH18: 2.9529 | AI18: 2.2786 | AJ18: 4.664 | AK18: 4.2749 | AL18: 4.1814 | AM18: 3.9613 | AN18: 3.9991 | AO18: 5.1191 | AP18: 1.9255 | AQ18: 0.9177 | AR18: 2.7701 | AS18: 4.1602 | AT18: 4.015 | AU18: 1.8546 | AV18: 3.4073 | AX18: + Short Term Debt | AY18: BS_ST_BORROW | AZ18: 220 | BA18: 245 | BB18: 446 | BC18: 302 | BD18: 18 | BE18: 19 | BF18: 331 | BG18: 20 | BH18: 228 | BI18: 533 | BJ18: 780 | BK18: 507 | BL18: 613 | BM18: 113 | BN18: 320 | BO18: 787 | BP18: 600 | BQ18: 937 | BR18: 1084 | BS18: 428
A19: EPS, Adj | B19: IS_DIL_EPS_CONT_OPS | C19: 7.9917 | D19: 8.3576 | E19: 8.1178 | F19: 9.7885 | G19: 11.3206 | H19: 10.392299 | I19: 10.253 | J19: 11.322 | L19: Modified Working Capital | M19: MODIFIED_WORK_CAP_GROWTH | N19: -30.4167 | O19: -92.8144 | P19: — | Q19: — | R19: — | S19: 53.271 | T19: 82 | U19: -666.6667 | V19: 4.3478 | W19: — | X19: — | Y19: — | Z19: -89.8734 | AA19: 637.5 | AB19: 50 | AC19: 185.8757 | AD19: -10.2767 | AE19: -1.5419 | AF19: -9.6197 | AG19: 8.4158 | AH19: -19.863 | AI19: -34.188 | AJ19: -28.5714 | AK19: 34.5455 | AL19: 0 | AM19: 56.3063 | AN19: 60.5187 | AO19: 1.9749 | AP19: -5.1056 | AQ19: -8.1633 | AR19: -34.5455 | AS19: -37.037 | AT19: 98.5294 | AU19: 29.3827 | AV19: 0 | AX19: + Long Term Debt | AY19: BS_LT_BORROW | AZ19: 18384 | BA19: 16663 | BB19: 16759 | BC19: 16486 | BD19: 14739 | BE19: 11790 | BF19: 10962 | BG19: 10515 | BH19: 9514 | BI19: 9022 | BJ19: 9052 | BK19: 8734 | BL19: 8051 | BM19: 7895 | BN19: 7512 | BO19: 6470 | BP19: 5362 | BQ19: 5093 | BR19: 6248 | BS19: 6886
A20: Growth %, YoY | B20: IS_DIL_EPS_CONT_OPS | C20: -39.580615 | D20: 4.5789052 | E20: -2.8700023 | F20: 20.581047 | G20: 15.652042 | H20: -6.9889293 | I20: -9.4304115 | J20: 10.426217 | L20: Working Capital | M20: WORK_CAP_GROWTH | N20: — | O20: 0.9585 | P20: 6.7742 | Q20: -62.9758 | R20: 8.811 | S20: 18.0442 | T20: -19.3182 | U20: -25.7143 | V20: 35.1326 | W20: 22.3358 | X20: -15.7895 | Y20: -47.7273 | Z20: -35.6044 | AA20: 0.4052 | AB20: 45.891 | AC20: 53.8346 | AD20: -2.2801 | AE20: -93.3121 | AF20: — | AG20: — | AH20: 92.7778 | AI20: — | AJ20: -54.8936 | AK20: -22.0126 | AL20: -29.8387 | AM20: 2.2989 | AN20: 161.236 | AO20: 90.9677 | AP20: -49.6622 | AQ20: -95.302 | AR20: 2995.2381 | AS20: 73.3846 | AT20: 114.9068 | AU20: -32.2874 | AV20: -15.9756 | AX20: + Preferred Equity and Hybrid Capital | AY20: PFD_EQTY_HYBRID_CAPITAL | AZ20: 0 | BA20: 0 | BB20: 0 | BC20: 0 | BD20: 0 | BE20: 0 | BF20: 0 | BG20: 0 | BH20: 0 | BI20: 0 | BJ20: 0 | BK20: 0 | BL20: 0 | BM20: 0 | BN20: 0 | BO20: — | BP20: 0 | BQ20: 0 | BR20: 0 | BS20: 0
L21: Employees | M21: EMPL_GROWTH | N21: -3.3611 | O21: -1.6139 | P21: -3.1264 | Q21: -2.9162 | R21: -4.6839 | S21: -1.124 | T21: -9.738 | U21: 10.6403 | V21: 0.6681 | W21: -0.8518 | X21: -1.6286 | Y21: — | Z21: — | AA21: -3.8717 | AB21: — | AC21: — | AD21: -4.4488 | AE21: -2.3628 | AF21: 2.8571 | AG21: -2.7778 | AH21: -2.8571 | AI21: -11.5059 | AJ21: -0.2925 | AK21: 3.3333 | AL21: 3.2258 | AM21: -3.125 | AN21: 3.2258 | AO21: -9.375 | AP21: -6.8966 | AQ21: -11.1111 | AR21: -6.25 | AS21: -6.6667 | AT21: -8.181 | AU21: 8.4898 | AV21: 7.7585 | AX21: Total Capital | AY21: WACC_TOTAL_CAPITAL | AZ21: 82620.05 | BA21: 99695.191 | BB21: 224803.52 | BC21: 72756.362 | BD21: 65590.523 | BE21: 60759.704 | BF21: 44642.507 | BG21: 35763.881 | BH21: 46113.558 | BI21: 38095.649 | BJ21: 29660.024 | BK21: 31336.246 | BL21: 32569.7 | BM21: 27815.2 | BN21: 20133.569 | BO21: 25313.139 | BP21: 21034.214 | BQ21: 17108.166 | BR21: 15970.402 | BS21: 14983.432
A22: Cash from Operations | B22: CF_CASH_FROM_OPER | C22: 8686 | D22: 8609 | E22: 8540 | F22: 9032 | G22: 9362 | H22: 8276 | L22: Accounts Payable | M22: ACCOUNTS_PAYABLE_GROWTH_1YR | N22: 5.7971 | O22: 6.8493 | P22: 20.2797 | Q22: -10.2713 | R22: -2.6998 | S22: 1.7758 | T22: 0.9815 | U22: 21.0583 | V22: 6.066 | W22: -0.841 | X22: 3.1383 | Y22: -1.5625 | Z22: -9.858 | AA22: -10.4727 | AB22: -16.9772 | AC22: 3.1172 | AD22: 5.1995 | AE22: 9.6552 | AF22: 2.0964 | AG22: 0.2053 | AH22: -0.3074 | AI22: -0.6166 | AJ22: 8.1696 | AK22: -2.6769 | AL22: -0.3929 | AM22: -5.6213 | AN22: -11.7032 | AO22: -9.5858 | AP22: 5.4974 | AQ22: 5.0868 | AR22: 12.0425 | AS22: 9.9052 | AT22: -22.4353 | AU22: 19.0358 | AV22: 17.3416
A23: Capital Expenditures | B23: CAPITAL_EXPEND | C23: -3437 | D23: -3453 | E23: -2927 | F23: -2936 | G23: -3620 | H23: -3557 | I23: -3695.062 | J23: -3590.944 | L23: Short-Term Debt | M23: SHORT_TERM_DEBT_1_YEAR_GROWTH | N23: 270.2786 | O23: -61.204 | P23: -23.0603 | Q23: 11.4846 | R23: -46.2312 | S23: 44.8598 | T23: 65.4839 | U23: 23.5867 | V23: -31.2303 | W23: -18.578 | X23: -19.1549 | Y23: 221.6028 | Z23: -0.2167 | AA23: 37.785 | AB23: -57.9196 | AC23: -19.8502 | AD23: 153.271 | AE23: -13.5609 | AF23: -35.9658 | AG23: 31.1667 | AH23: -59.3393 | AI23: -64.6875 | AJ23: 442.4779 | AK23: -17.292 | AL23: 53.8462 | AM23: -31.6667 | AN23: -57.2233 | AO23: -91.2281 | AP23: 1555 | AQ23: -94.2598 | AR23: -5.2632 | AS23: 1577.7778 | AT23: 47.6821 | AU23: -45.0673 | AV23: -10.2041 | AX23: EVA
A24: Free Cash Flow | B24: CF_FREE_CASH_FLOW | C24: 5249 | D24: 5156 | E24: 5613 | F24: 6096 | G24: 5742 | H24: 4719 | I24: 4846.03 | J24: 6040.806 | L24: Total Debt | M24: TOTAL_DEBT_1_YEAR_GROWTH | N24: 21.3199 | O24: -24.527 | P24: 5.9856 | Q24: -5.3223 | R24: 8.0262 | S24: -0.4626 | T24: -9.0619 | U24: -8.7831 | V24: 66.9118 | W24: 42.039 | X24: -0.768 | Y24: 5.9533 | Z24: -5.4502 | AA24: 5.601 | AB24: -0.7738 | AC24: 3.7006 | AD24: 0.2461 | AE24: -17.7578 | AF24: -1.1277 | AG24: 21.7209 | AH24: 7.9234 | AI24: 2.2472 | AJ24: 8.1918 | AK24: 6.6597 | AL24: 6.3954 | AM24: -2.8173 | AN24: 1.9571 | AO24: 8.14 | AP24: 7.1951 | AQ24: 4.5692 | AR24: 24.964 | AS24: 13.763 | AT24: 2.4839 | AU24: -1.7262 | AV24: 10.0308 | AX24: + Net Op. Profit | AY24: WACC_NET_OPER_PROFIT | AZ24: 5949 | BA24: 5536 | BB24: 4322 | BC24: 4927 | BD24: 4825 | BE24: 3753 | BF24: 3398 | BG24: 3613 | BH24: 3693 | BI24: 3517 | BJ24: 3496 | BK24: 3503 | BL24: 3086 | BM24: 2273 | BN24: 2767 | BO24: 2287 | BP24: 2164 | BQ24: 1562 | BR24: 1005 | BS24: 513
A25: Source: Bloomberg | L25: Total Equity | M25: TOTAL_EQUITY_1_YEAR_GROWTH | N25: -32.3563 | O25: 0.3706 | P25: 0.568 | Q25: -10.1384 | R25: -6.5053 | S25: 6.8908 | T25: 17.327 | U25: 13.6961 | V25: 17.7511 | W25: 15.4354 | X25: 1.9771 | Y25: -2.1088 | Z25: 4.5344 | AA25: 1.7118 | AB25: 1.9771 | AC25: 3.3969 | AD25: 5.5478 | AE25: 16.7817 | AF25: 12.4214 | AG25: -2.8741 | AH25: -7.3345 | AI25: 8.9463 | AJ25: -0.7755 | AK25: -2.6667 | AL25: 6.3061 | AM25: 16.6852 | AN25: 6.3976 | AO25: 4.4023 | AP25: 0.2228 | AQ25: 25.8851 | AR25: -14.5438 | AS25: -5.6995 | AT25: 10.5117 | AU25: 2.9748 | AV25: -6.4815 | AX25: - Cash Op. Taxes | AY25: WACC_CASH_OPER_TAXES | AZ25: 1202.3827 | BA25: 1106.9511 | BB25: 829.6816 | BC25: 862.1152 | BD25: 853.6169 | BE25: 849 | BF25: 852.7931 | BG25: 874.2906 | BH25: 1115.7953 | BI25: 727.5065 | BJ25: 730.7939 | BK25: 723.7755 | BL25: 694.7003 | BM25: 465.4708 | BN25: 816.3312 | BO25: 841.3975 | BP25: 615.6638 | BQ25: 625.7799 | BR25: -2051.2009 | BS25: -22.3333
L26: Capital | M26: GROWTH_IN_CAP | N26: -10.7831 | O26: -13.2368 | P26: 3.1436 | Q26: -7.7856 | R26: 0.7832 | S26: 2.9375 | T26: 3.6086 | U26: 3.4392 | V26: 37.5317 | W26: 28.4266 | X26: 0.4945 | Y26: 2.1907 | Z26: -0.9864 | AA26: 3.7653 | AB26: 0.4989 | AC26: 3.558 | AD26: 2.7312 | AE26: -1.1242 | AF26: 6.5789 | AG26: 6.9646 | AH26: -0.3889 | AI26: 5.6423 | AJ26: 3.505 | AK26: 1.9869 | AL26: 6.3527 | AM26: 6.5042 | AN26: 4.2824 | AO26: 6.143 | AP26: 3.5311 | AQ26: 15.4131 | AR26: 3.0418 | AS26: 4.8067 | AT26: 5.8078 | AU26: 0.3068 | AV26: 2.6999 | AX26: + NOPAT | AY26: WACC_NOPAT | AZ26: 4746.6173 | BA26: 4429.0489 | BB26: 3492.3184 | BC26: 4064.8848 | BD26: 3971.3831 | BE26: 2904 | BF26: 2545.2069 | BG26: 2738.7094 | BH26: 2577.2047 | BI26: 2789.4935 | BJ26: 2765.2061 | BK26: 2779.2245 | BL26: 2391.2997 | BM26: 1807.5292 | BN26: 1950.6688 | BO26: 1445.6025 | BP26: 1548.3362 | BQ26: 936.2201 | BR26: 3056.2009 | BS26: 535.3333
L27: Book Value per Share | M27: BVPS_GROWTH | N27: -2.7611 | O27: 9.3674 | P27: 8.1205 | Q27: -13.5072 | R27: -7.4974 | S27: 6.1532 | T27: 16.7366 | U27: 13.1284 | V27: 14.2818 | W27: 14.6819 | X27: 2.5365 | Y27: -2.7026 | Z27: 7.3382 | AA27: 1.2596 | AB27: 1.5026 | AC27: 3.2123 | AD27: 5.3235 | AE27: 15.3506 | AF27: 12.0727 | AG27: 4.2461 | AH27: -3.2205 | AI27: 8.0876 | AJ27: 5.3911 | AK27: 2.9855 | AL27: 9.2907 | AM27: 17.9772 | AN27: 8.2344 | AO27: 7.3054 | AP27: 4.2633 | AQ27: 31.3331 | AR27: -7.0827 | AS27: -0.24 | AT27: -62.6126 | AU27: 220.9453 | AV27: -0.3578 | AX27: Total Invested Capital | AY27: WACC_TOTAL_INV_CAPITAL | AZ27: 38983 | BA27: 37959 | BB27: 37841 | BC27: 36008 | BD27: 34486 | BE27: 33300 | BF27: 33077 | BG27: 32078 | BH27: 30337 | BI27: 28869 | BJ27: 27592 | BK27: 26118 | BL27: 24984 | BM27: 23919 | BN27: 22849 | BO27: 22431 | BP27: 21523 | BQ27: 20594 | BR27: 20902 | BS27: 18042
AX28: WACC | AY28: WACC | AZ28: 7.3055 | BA28: 8.5516 | BB28: 8.2089 | BC28: 7.4443 | BD28: 9.8254 | BE28: 8.8002 | BF28: 8.3721 | BG28: 8.158 | BH28: 8.2549 | BI28: 9.0653 | BJ28: 8.7373 | BK28: 9.7072 | BL28: 11.7766 | BM28: 9.2292 | BN28: 7.9406 | BO28: 9.5636 | BP28: 9.6938 | BQ28: 8.6572 | BR28: 6.7802 | BS28: 6.6139
L29: Cash From Operations | M29: CASH_FLOW_GROWTH | N29: -32.9198 | O29: 24.1677 | P29: -11.718 | Q29: -2.5872 | R29: 8.4296 | S29: 2.4494 | T29: 37.8378 | U29: 18.175 | V29: -8.1047 | W29: 8.1944 | X29: -35.8151 | Y29: 7.1 | Z29: -33.7068 | AA29: 16.4789 | AB29: 36.2757 | AC29: -28.6602 | AD29: 79.8507 | AE29: -23.2365 | AF29: 85.4054 | AG29: 6.1224 | AH29: 33.4249 | AI29: -30.0275 | AJ29: 59.9313 | AK29: 7.0531 | AL29: -15.6116 | AM29: 10.8961 | AN29: 2.3263 | AO29: 0.8077 | AP29: -9.7626 | AQ29: 14.173 | AR29: 33.6694 | AS29: 4.5033 | AT29: -12.1031 | AU29: 19.6106 | AV29: 10.1981 | AX29: - Capital Charge | AY29: WACC_CAPITAL_CHARGE | AZ29: 2847.8995 | BA29: 3246.1049 | BB29: 3106.3292 | BC29: 2680.559 | BD29: 3388.3884 | BE29: 2930.4646 | BF29: 2769.2336 | BG29: 2616.9094 | BH29: 2504.2848 | BI29: 2617.0651 | BJ29: 2410.7886 | BK29: 2535.3354 | BL29: 2942.2646 | BM29: 2207.5388 | BN29: 1814.3501 | BO29: 2145.2112 | BP29: 2086.3874 | BQ29: 1782.8579 | BR29: 1417.1948 | BS29: 1193.2711
L30: Capital Expenditures | M30: TOT_CAP_EXPEND_GROWTH | N30: 49.5695 | O30: 7.2368 | P30: -9.0491 | Q30: -27.1501 | R30: 20.4861 | S30: -26.2248 | T30: 13.9323 | U30: 32.1143 | V30: 5.7958 | W30: -8.0131 | X30: 31.4667 | Y30: 2.5693 | Z30: -39.8154 | AA30: 1.862 | AB30: 16.129 | AC30: -1.9444 | AD30: -2.7384 | AE30: 10.2913 | AF30: 44.2782 | AG30: 8.1757 | AH30: -1.8613 | AI30: -18.046 | AJ30: 29.0323 | AK30: 24.837 | AL30: 1.9155 | AM30: -1.1961 | AN30: 5.8798 | AO30: 4.6141 | AP30: -6.4012 | AQ30: -14.9291 | AR30: -14.4608 | AS30: -5.043 | AT30: -1.8709 | AU30: 10.1476 | AV30: 19.0955 | AX30: Economic Value Added | AY30: WACC_ECON_VALUE_ADDED | AZ30: 1898.7178 | BA30: 1182.944 | BB30: 385.9893 | BC30: 1384.3258 | BD30: 582.9947 | BE30: -26.4646 | BF30: -224.0267 | BG30: 121.7999 | BH30: 72.9199 | BI30: 172.4284 | BJ30: 354.4175 | BK30: 243.8891 | BL30: -550.965 | BM30: -400.0096 | BN30: 136.3186 | BO30: -699.6087 | BP30: -538.0512 | BQ30: -846.6378 | BR30: 1639.0061 | BS30: -657.9377
L31: Net Change In Cash | M31: NET_CHANGE_IN_CASH_1_YEAR_GROWTH | N31: — | O31: — | P31: — | Q31: 88.8889 | R31: — | S31: — | T31: 56.5789 | U31: — | V31: -12.7273 | W31: — | X31: -24.7863 | Y31: — | Z31: — | AA31: 66.3934 | AB31: 91.8699 | AC31: — | AD31: 33.7278 | AE31: — | AF31: — | AG31: — | AH31: — | AI31: 19.6013 | AJ31: -26.9444 | AK31: — | AL31: — | AM31: — | AN31: — | AO31: — | AP31: 39.0244 | AQ31: -708 | AR31: — | AS31: -78.1182 | AT31: 2071 | AU31: — | AV31: 68.427 | AX31: ROIC | AY31: WACC_RETURN_ON_INV_CAPITAL | AZ31: 12.1761 | BA31: 11.668 | BB31: 9.2289 | BC31: 11.2888 | BD31: 11.5159 | BE31: 8.7207 | BF31: 7.6948 | BG31: 8.5377 | BH31: 8.4953 | BI31: 9.6626 | BJ31: 10.0218 | BK31: 10.641 | BL31: 9.5713 | BM31: 7.5569 | BN31: 8.5372 | BO31: 6.4447 | BP31: 7.1939 | BQ31: 4.5461 | BR31: 14.6216 | BS31: 2.9672
L32: Free Cash Flow | M32: FREE_CASH_FLOW_1_YEAR_GROWTH | N32: — | O32: 26.6667 | P32: 0 | Q32: — | R32: — | S32: — | T32: 132.4742 | U32: -8.8692 | V32: -47.2019 | W32: 99.5392 | X32: — | Y32: 6.8894 | Z32: 54.4843 | AA32: 49.2611 | AB32: — | AC32: — | AD32: — | AE32: — | AF32: — | AG32: -1.9093 | AH32: 185.6448 | AI32: -47.7853 | AJ32: 131.8108 | AK32: -15.9747 | AL32: -49.33 | AM32: 57.686 | AN32: -6.2893 | AO32: -9.6197 | AP32: -20.4208 | AQ32: 122.7061 | AR32: 102.2346 | AS32: 10.2555 | AT32: -17.4131 | AU32: 25.4456 | AV32: 5.3809 | AX32: EVA Spread | AY32: WACC_EVA_SPREAD | AZ32: 4.8706 | BA32: 3.1164 | BB32: 1.02 | BC32: 3.8445 | BD32: 1.6905 | BE32: -0.0795 | BF32: -0.6773 | BG32: 0.3797 | BH32: 0.2404 | BI32: 0.5973 | BJ32: 1.2845 | BK32: 0.9338 | BL32: -2.2053 | BM32: -1.6724 | BN32: 0.5966 | BO32: -3.1189 | BP32: -2.4999 | BQ32: -4.1111 | BR32: 7.8414 | BS32: -3.6467
L33: Cash Flow to Firm | M33: CASH_FLOW_TO_FIRM_1_YEAR_GROWTH | N33: — | O33: — | P33: -9.3578 | Q33: — | R33: — | S33: — | T33: 33.0147 | U33: 15.2637 | V33: -7.6995 | W33: 16.394 | X33: -27.2717 | Y33: -9.3432 | Z33: -12.7258 | AA33: 8.4837 | AB33: 21.3293 | AC33: -22.395 | AD33: 57.7382 | AE33: -18.9131 | AF33: 66.4511 | AG33: 4.779 | AH33: 32.4957 | AI33: -26.04 | AJ33: 50.1543 | AK33: 6.5545 | AL33: -14.0165 | AM33: 9.831 | AN33: 1.7239 | AO33: 0.6279 | AP33: -8.3022 | AQ33: — | AR33: — | AS33: 5.5828 | AT33: -10.7219 | AU33: 16.7964 | AV33: 9.5494 | AX33: Source: Bloomberg | AZ33: Right click to show data transparency (not supported for all values)
L34: Free Cash Flow to Firm | M34: FCF_TO_FIRM_1_YEAR_GROWTH | N34: — | O34: — | P34: 4.3852 | Q34: — | R34: — | S34: — | T34: 73.0784 | U34: -8.0246 | V34: -34.4903 | W34: 94.6433 | X34: — | Y34: -136.5158 | Z34: — | AA34: 45.8919 | AB34: 41.8409 | AC34: -88.4367 | AD34: 1713.8476 | AE34: -61.7966 | AF34: 160.4462 | AG34: -3.1976 | AH34: 122.6573 | AI34: -35.2864 | AJ34: 81.0944 | AK34: -12.5271 | AL34: -37.7477 | AM34: 36.7211 | AN34: -5.5999 | AO34: -7.251 | AP34: -12.5404 | AQ34: — | AR34: — | AS34: 11.0568 | AT34: -14.6206 | AU34: 20.1624 | AV34: 5.1195
L36: 5 Year Growth
L37: Revenue | M37: GEO_GROW_NET_SALES | N37: — | O37: — | P37: — | Q37: — | R37: 1.6621 | S37: 3.3228 | T37: 4.4052 | U37: 5.0643 | V37: 4.0573 | W37: 3.9897 | X37: 1.9949 | Y37: 1.5479 | Z37: -4.8527 | AA37: -5.0994 | AB37: -5.1538 | AC37: -5.174 | AD37: -4.9716 | AE37: 1.0215 | AF37: 3.3575 | AG37: 4.2335 | AH37: 8.2669 | AI37: 2.3746 | AJ37: 4.2976 | AK37: 4.2782 | AL37: 3.2266 | AM37: 1.334 | AN37: 6.9806 | AO37: 2.1179 | AP37: -1.2625 | AQ37: -0.5992 | AR37: 0.3698 | AS37: -1.1832 | AT37: -2.1717 | AU37: 2.4975 | AV37: 5.4195
L38: EBITDA | M38: GEO_GROW_EBITDA | N38: — | O38: — | P38: — | Q38: — | R38: 0.726 | S38: 1.5364 | T38: 6.5704 | U38: 9.5149 | V38: 9.5913 | W38: 8.7651 | X38: 3.4564 | Y38: -7.9734 | Z38: -7.0865 | AA38: -5.9167 | AB38: -4.7982 | AC38: -7.9522 | AD38: 7.6982 | AE38: 11.1449 | AF38: 13.7346 | AG38: 12.1149 | AH38: 25.9491 | AI38: 12.8976 | AJ38: 11.0139 | AK38: 8.1496 | AL38: 7.4977 | AM38: 4.4252 | AN38: 8.4677 | AO38: 3.5861 | AP38: 1.0743 | AQ38: 2.1996 | AR38: 6.2581 | AS38: 6.0754 | AT38: 3.9886 | AU38: 8.656 | AV38: 8.6745
L39: Operating Income | M39: GEO_GROW_OPER_INC | N39: — | O39: — | P39: — | Q39: — | R39: 1.5175 | S39: 0.0879 | T39: 7.2305 | U39: 11.8858 | V39: 12.2513 | W39: 10.4055 | X39: 4.357 | Y39: -14.1958 | Z39: -10.8436 | AA39: -8.862 | AB39: -6.5695 | AC39: -14.3781 | AD39: 11.7813 | AE39: 14.0006 | AF39: 17.4408 | AG39: 14.8902 | AH39: 39.7116 | AI39: 17.8162 | AJ39: 14.6541 | AK39: 10.1703 | AL39: 8.9111 | AM39: 4.6424 | AN39: 9.7409 | AO39: 3.1377 | AP39: -0.4713 | AQ39: 1.4773 | AR39: 6.9909 | AS39: 6.5639 | AT39: 4.0072 | AU39: 10.5427 | AV39: 10.1169
L40: Net Income to Common | M40: NET_INCOME_TO_COMMON_5_YR_GROWTH | N40: — | O40: — | P40: — | Q40: — | R40: -31.8449 | S40: 21.2481 | T40: 8.2322 | U40: 8.7123 | V40: — | W40: 109.0756 | X40: 8.3867 | Y40: -68.5691 | Z40: -1.7773 | AA40: -19.2802 | AB40: -11.9025 | AC40: -14.4555 | AD40: 179.1476 | AE40: 15.1732 | AF40: 34.9214 | AG40: 25.8022 | AH40: 40.8768 | AI40: 27.5174 | AJ40: 6.4218 | AK40: 7.2049 | AL40: 6.8303 | AM40: 6.4182 | AN40: 10.9998 | AO40: 4.7054 | AP40: -1.5802 | AQ40: 24.0914 | AR40: 12.1684 | AS40: 11.5793 | AT40: 7.0479 | AU40: 17.1574 | AV40: -5.3008
L41: EPS Diluted | M41: 5Y_GEO_GROWTH_DILUTED_EPS | N41: — | O41: — | P41: — | Q41: — | R41: -26.404 | S41: 30.0525 | T41: 7.4978 | U41: 7.2175 | V41: — | W41: 108.2399 | X41: 7.7272 | Y41: -68.2818 | Z41: -1.9082 | AA41: -19.009 | AB41: -11.7607 | AC41: -15.0566 | AD41: 173.1296 | AE41: 13.5491 | AF41: 32.5196 | AG41: 24.6148 | AH41: 43.1827 | AI41: 30.6222 | AJ41: 9.954 | AK41: 12.5808 | AL41: 12.4244 | AM41: 10.4499 | AN41: 14.7902 | AO41: 8.1781 | AP41: 1.2619 | AQ41: 27.3253 | AR41: 15.9781 | AS41: 16.7796 | AT41: -9.712 | AU41: 22.7299 | AV41: -0.4719
L42: EPS Diluted before XO | M42: 5Y_GEO_GROWTH_DILUTED_EPS_BEF_XO | N42: — | O42: — | P42: — | Q42: — | R42: — | S42: — | T42: 8.781 | U42: 10.1271 | V42: — | W42: 108.2399 | X42: 7.7272 | Y42: -40.1105 | Z42: -21.4987 | AA42: -19.009 | AB42: -10.0543 | AC42: -24.1539 | AD42: 50.7739 | AE42: 29.3199 | AF42: 32.5196 | AG42: 20.1344 | AH42: 63.318 | AI42: 24.9703 | AJ42: 20.6383 | AK42: 12.5808 | AL42: 14.4049 | AM42: 8.4472 | AN42: 15.1107 | AO42: 8.1781 | AP42: 1.2619 | AQ42: 27.3253 | AR42: 15.9781 | AS42: 16.7796 | AT42: -9.712 | AU42: 22.7299 | AV42: -0.4719
...

Sheet IS
