Workbook
Name BS: DCF!$AD$3:$AI$104
Name CF: DCF!$W$3:$AB$99
Name CF_1: DCF!#REF!
Name IS: DCF!#REF!
Name IS_1: DCF!#REF!
Name IS_2: DCF!$N$3:$U$74

Sheet DCF
B2: Discounted Cash Flow Analysis | F2: Westinghouse Air Brake | N2: Income Statement | W2: Cash Flow | AD2: Balance sheet
F3: Technologies Corporation (WAB) | Q3: 2022 | R3: 2021 | S3: 2020 | T3: 2019 | U3: 2018 | X3: 2022 | Y3: 2021 | Z3: 2020 | AA3: 2019 | AB3: 2018 | AE3: 2022 | AF3: 2021 | AG3: 2020 | AH3: 2019 | AI3: 2018
N4: Sales/Revenue | Q4: 8362 | R4: 7822 | S4: 7556 | T4: 8200 | U4: 4364 | W4: Net Income before Extraordinaries | X4: 641 | Y4: 565 | Z4: 412 | AA4: 327 | AB4: 292 | AD4: Net Income before Extraordinaries | AE4: - | AF4: - | AG4: - | AH4: - | AI4: -
H5: 1 | I5: =H5+1 -> 2 | J5: =I5+1 -> 3 | K5: =J5+1 -> 4 | N5: Sales Growth | Q5: 0.069 | R5: 0.0352 | S5: -0.0785 | T5: 0.8792 | U5: - | W5: Net Income Growth | X5: 0.1345 | Y5: 0.3704 | Z5: 0.2628 | AA5: 0.1193 | AB5: - | AD5: Cash & Short Term Investments | AE5: 541 | AF5: 473 | AG5: 599 | AH5: 604 | AI5: 2342
B6: Income Statement ($M) | C6: 2020 | D6: 2021 | E6: 2022 | F6: 2023 | G6: 2024 | H6: 2025 | I6: 2026 | J6: 2027 | K6: 2028 | W6: Depreciation, Depletion & Amortization | X6: 479 | Y6: 491 | Z6: 473 | AA6: 401 | AB6: 109 | AD6: Cash Only | AE6: 541 | AF6: 473 | AG6: 599 | AH6: 604 | AI6: 2342
B7: Revenue | C7: 7556 | D7: 7822 | E7: 8362 | F7: 9677 | G7: 10330 | H7: =G7*(1+H8) -> 11341.564 | I7: =H7*(1+I8) -> 12561.4 | J7: =I7*(1+J8) -> 13704.316 | K7: =J7*(1+K8) -> 15058.603 | N7: Cost of Goods Sold (COGS) incl. D&A | Q7: 6070 | R7: 5687 | S7: 5657 | T7: 6122 | U7: 3152 | W7: Depreciation and Depletion | X7: 188 | Y7: 204 | Z7: 191 | AA7: 163 | AB7: 70 | AD7: Short-Term Investments | AE7: - | AF7: - | AG7: - | AH7: - | AI7: -
B8: % growth | D8: =(D7-C7)/C7 -> 0.035203812 | E8: =(E7-D7)/D7 -> 0.069036052 | F8: =(F7-E7)/E7 -> 0.15725903 | G8: =(G7-F7)/F7 -> 0.067479591 | H8: =AVERAGE(E8:G8) -> 0.097924891 | I8: =AVERAGE(F8:H8) -> 0.1075545 | J8: =AVERAGE(G8:I8) -> 0.090986328 | K8: =AVERAGE(H8:J8) -> 0.098821907 | N8: COGS excluding D&A | Q8: 5591 | R8: 5196 | S8: 5184 | T8: 5721 | U8: 3043 | W8: Amortization of Intangible Assets | X8: 291 | Y8: 287 | Z8: 282 | AA8: 238 | AB8: 40 | AD8: Cash & Short Term Investments Growth | AE8: 0.1438 | AF8: -0.21 | AG8: -0.0091 | AH8: -0.7421 | AI8: -
B9: EBIT | C9: 860 | D9: 954 | E9: 1063 | F9: 1310 | G9: 1609 | H9: =H10*H7 -> 1581.2225 | I9: =I10*I7 -> 1802.7738 | J9: =J10*J7 -> 2004.0061 | K9: =K10*K7 -> 2154.2189 | N9: Depreciation & Amortization Expense | Q9: 479 | R9: 491 | S9: 473 | T9: 401 | U9: 109 | W9: Deferred Taxes & Investment Tax Credit | X9: 36 | Y9: 88 | Z9: 29 | AA9: -27 | AB9: -5
B10: % of sales | C10: =C9/C7 -> 0.11381683 | D10: =D9/D7 -> 0.12196369 | E10: =E9/E7 -> 0.1271227 | F10: =F9/F7 -> 0.13537253 | G10: =G9/G7 -> 0.15575992 | H10: =AVERAGE(E10:G10) -> 0.13941838 | I10: =AVERAGE(F10:H10) -> 0.14351695 | J10: =AVERAGE(G10:I10) -> 0.14623175 | K10: =AVERAGE(H10:J10) -> 0.14305569 | N10: Depreciation | Q10: 188 | R10: 204 | S10: 191 | T10: 163 | U10: 70 | AD10: Cash & ST Investments / Total Assets | AE10: 0.0292 | AF10: 0.0256 | AG10: 0.0324 | AH10: 0.0319 | AI10: 0.2708
B11: Taxes | C11: 145 | D11: 172 | E11: 213 | F11: 233 | G11: 263.85134 | H11: =H9*H12 -> 285.79204 | I11: =I9*I12 -> 314.03627 | J11: =J9*J12 -> 346.64097 | K11: =K9*K12 -> 379.07886 | N11: Amortization of Intangibles | Q11: 291 | R11: 287 | S11: 282 | T11: 238 | U11: 40 | W11: Deferred Taxes | X11: 36 | Y11: 88 | Z11: 29 | AA11: -27 | AB11: -5 | AD11: Total Accounts Receivable | AE11: 1519 | AF11: 1477 | AG11: 1413 | AH11: 1664 | AI11: 1147
B12: % of EBIT | C12: =C11/C9 -> 0.16860465 | D12: =D11/D9 -> 0.1802935 | E12: =E11/E9 -> 0.20037629 | F12: =F11/F9 -> 0.1778626 | G12: =G11/G9 -> 0.16398468 | H12: =AVERAGE(E12:G12) -> 0.18074119 | I12: =AVERAGE(F12:H12) -> 0.17419615 | J12: =AVERAGE(G12:I12) -> 0.17297401 | K12: =AVERAGE(H12:J12) -> 0.17597045 | N12: Amortization of Deferred Charges | Q12: - | R12: - | S12: - | T12: - | U12: - | AD12: Accounts Receivables, Net | AE12: 1519 | AF12: 1477 | AG12: 1413 | AH12: 1664 | AI12: 1147
B13: EBIAT = EBIT - Taxes | C13: =C9-C11 -> 715 | D13: =D9-D11 -> 782 | E13: =E9-E11 -> 850 | F13: =F9-F11 -> 1077 | G13: =G9-G11 -> 1345.1487 | H13: =H9-H11 -> 1295.4305 | I13: =I9-I11 -> 1488.7376 | J13: =J9-J11 -> 1657.3652 | K13: =K9-K11 -> 1775.14 | N13: COGS Growth | Q13: 0.0673 | R13: 0.0052 | S13: -0.076 | T13: 0.9425 | U13: - | W13: Investment Tax Credit | X13: - | Y13: - | Z13: - | AA13: - | AB13: - | AD13: Accounts Receivables, Gross | AE13: 1547 | AF13: 1509 | AG13: 1449 | AH13: 1684 | AI13: 1164
B14: D&A | C14: 473 | D14: 441 | E14: 426 | F14: 477 | G14: 486 | H14: =SLOPE(C14:G14,C$6:G$6)*H$6+INTERCEPT(C14:G14,C$6:G$6) -> 479.2 | I14: =(SLOPE(D14:H14,D6:H6)*I6 +INTERCEPT(D14:H14,D6:H6)) -> 502.76 | J14: =(SLOPE(E14:I14,E6:I6)*J6+INTERCEPT(E14:I14,E6:I6)) -> 520.908 | K14: =(SLOPE(F14:J14,F6:J6)*K6+INTERCEPT(F14:J14,F6:J6)) -> 524.5464 | W14: Other Funds | X14: -9 | Y14: -8 | Z14: -59 | AA14: -16 | AB14: 26 | AD14: Bad Debt/Doubtful Accounts | AE14: -28 | AF14: -32 | AG14: -37 | AH14: -20 | AI14: -17
B15: % of sales | C15: =C14/C7 -> 0.062599259 | D15: =D14/D7 -> 0.056379443 | E15: =E14/E7 -> 0.05094475 | F15: =F14/F7 -> 0.049292136 | G15: =G14/G7 -> 0.047047435 | H15: =AVERAGE(E15:G15) -> 0.049094774 | I15: =AVERAGE(F15:H15) -> 0.048478115 | J15: =AVERAGE(G15:I15) -> 0.048206774 | K15: =AVERAGE(H15:J15) -> 0.048593221 | N15: Gross Income | Q15: 2292 | R15: 2135 | S15: 1899 | T15: 2078 | U15: 1212
B16: CapEx | C16: -136 | D16: -130 | E16: -149 | F16: -186 | G16: -200 | H16: =SLOPE(E16:G16,E$6:G$6)*H$6+INTERCEPT(E16:G16,E$6:G$6) -> -229.33333 | I16: =SLOPE(E16:H16,E$6:H$6)*I$6+INTERCEPT(E16:H16,E$6:H$6) -> -254.83333 | J16: =SLOPE(F16:I16,F$6:I$6)*J$6+INTERCEPT(F16:I16,F$6:I$6) -> -276.5 | K16: =SLOPE(F16:J16,F$6:J$6)*K$6+INTERCEPT(F16:J16,F$6:J$6) -> -300.08333 | N16: Gross Income Growth | Q16: 0.0735 | R16: 0.1245 | S16: -0.0861 | T16: 0.7146 | U16: - | W16: Funds from Operations | X16: 1147 | Y16: 1136 | Z16: 856 | AA16: 684 | AB16: 422 | AD16: Other Receivables | AE16: - | AF16: - | AG16: - | AH16: - | AI16: -
B17: % of sales | C17: =C16/C7 -> -0.017998941 | D17: =D16/D7 -> -0.01661979 | E17: =E16/E7 -> -0.017818704 | F17: =F16/F7 -> -0.019220833 | G17: =G16/G7 -> -0.019361084 | H17: =H16/H7 -> -0.020220609 | I17: =I16/I7 -> -0.020287016 | J17: =J16/J7 -> -0.020176125 | K17: =K16/K7 -> -0.019927701 | W17: Extraordinaries | X17: - | Y17: - | Z17: - | AA17: - | AB17: - | AD17: Accounts Receivable Growth | AE17: 0.0284 | AF17: 0.0457 | AG17: -0.1511 | AH17: 0.4509 | AI17: -
B18: Change in NWC | C18: -72 | D18: -63 | E18: -109 | F18: -97 | G18: 238 | H18: =H19*H7 -> -0.072724101 | I18: =I19*I7 -> -36.865001 | J18: =J19*J7 -> -25.158016 | K18: =K19*K7 -> -12.037361 | N18: Gross Profit Margin | Q18: 0.2741 | R18: - | S18: - | T18: - | U18: - | W18: Changes in Working Capital | X18: -109 | Y18: -63 | Z18: -72 | AA18: 331 | AB18: -107
B19: % of sales | C19: =C18/C7 -> -0.0095288512 | D19: =D18/D7 -> -0.0080542061 | E19: =E18/E7 -> -0.013035159 | F19: =F18/F7 -> -0.010023768 | G19: =G18/G7 -> 0.02303969 | H19: =AVERAGE(E19:G19) -> -6.4121756e-06 | I19: =AVERAGE(C19:H19) -> -0.0029347843 | J19: =AVERAGE(D19:I19) -> -0.0018357732 | K19: =AVERAGE(E19:J19) -> -0.0007993677 | N19: SG&A Expense | Q19: 1229 | R19: 1181 | S19: 1039 | T19: 1147 | U19: 661 | AD19: Accounts Receivable Turnover | AE19: 5.5 | AF19: 5.3 | AG19: 5.35 | AH19: 4.93 | AI19: 3.81
B20: Unlevered FCF | C20: =C13+C14-C16-C18 -> 1396 | D20: =D13+D14-D16-D18 -> 1416 | E20: =E13+E14-E16-E18 -> 1534 | F20: =F13+F14-F16-F18 -> 1837 | G20: =G13+G14-G16-G18 -> 1793.1487 | H20: =H13+H14-H16-H18 -> 2004.0366 | I20: =I13+I14-I16-I18 -> 2283.1959 | J20: =J13+J14-J16-J18 -> 2479.9312 | K20: =K13+K14-K16-K18 -> 2611.8071 | N20: Research & Development | Q20: 209 | R20: 176 | S20: 162 | T20: 210 | U20: 87 | W20: Receivables | X20: -52 | Y20: -76 | Z20: 315 | AA20: -6 | AB20: -55 | AD20: Inventories | AE20: 2034 | AF20: 1689 | AG20: 1642 | AH20: 1773 | AI20: 845
B21: Discounted Cash Flow | H21: =H20/(1+C38)^H5 -> 1908.6062 | I21: =I20/(1+C38)^I5 -> 2070.926 | J21: =J20/(1+C38)^J5 -> 2142.2578 | K21: =K20/(1+C38)^K5 -> 2148.7402 | N21: Other SG&A | Q21: 1020 | R21: 1005 | S21: 877 | T21: 937 | U21: 574 | AD21: Finished Goods | AE21: 641 | AF21: 616 | AG21: 633 | AH21: 613 | AI21: 225
B22: % growth | D22: pre-COVID data not relevant | E22: =E20/C20-1 -> 0.098853868 | F22: =F20/E20-1 -> 0.19752282 | G22: =G20/F20-1 -> -0.023871172 | H22: =H20/G20-1 -> 0.1176076 | I22: =I20/H20-1 -> 0.13929853 | J22: =J20/I20-1 -> 0.086166627 | K22: =K20/J20-1 -> 0.053177247 | N22: SGA Growth | Q22: 0.0406 | R22: 0.1365 | S22: -0.0936 | T22: 0.7342 | U22: - | W22: Inventories | X22: -368 | Y22: -41 | Z22: 181 | AA22: 256 | AB22: -109 | AD22: Work in Progress | AE22: 515 | AF22: 316 | AG22: 339 | AH22: 374 | AI22: 154
E23: %change compared with 2019 ↑ | AD23: Raw Materials | AE23: 878 | AF23: 757 | AG23: 669 | AH23: 786 | AI23: 466
B24: Terminal Value | C24: =(K21*(1+C43))/ABS(C42-C43) -> 37922.823 | N24: Other Operating Expense | Q24: - | R24: - | S24: - | T24: - | U24: - | W24: Accounts Payable | X24: 306 | Y24: 109 | Z24: -269 | AA24: -144 | AB24: 49 | AD24: Progress Payments & Other | AE24: - | AF24: - | AG24: - | AH24: - | AI24: -
B25: Present Value of Terminal Value | C25: =C24/(1+C38)^K5 -> 31199.201 | N25: EBIT | Q25: 1063 | R25: 954 | S25: 860 | T25: 931 | U25: 551 | AD25: Other Current Assets | AE25: 233 | AF25: 193 | AG25: 227 | AH25: 151 | AI25: 116
B26: Enterprise Value | C26: =SUM(H21:K21,C25) -> 39469.731 | E26: Share Price on | F26: 45236 | G26: 200.4 | N26: Unusual Expense | Q26: 51 | R26: 83 | S26: 114 | T26: 268 | U26: 74 | W26: Income Taxes Payable | X26: 7 | Y26: -4 | Z26: 57 | AA26: 11 | AB26: 8 | AD26: Prepaid Expenses | AE26: - | AF26: - | AG26: - | AH26: - | AI26: -
B27: + Cash | C27: 620 | N27: Non Operating Income/Expense | Q27: 11 | R27: 23 | S27: 1 | T27: -5 | U27: -3 | AD27: Miscellaneous Current Assets | AE27: 233 | AF27: 193 | AG27: 227 | AH27: 151 | AI27: 116
B28: - Debt | C28: 3449 | W28: Other Accruals | X28: 108 | Y28: 84 | Z28: -91 | AA28: -12 | AB28: 32 | AD28: Total Current Assets | AE28: 4327 | AF28: 3832 | AG28: 3880 | AH28: 4192 | AI28: 4450
B29: Equity Value | C29: =C26+C27-C28 -> 36640.731 | N29: Non-Operating Interest Income | Q29: - | R29: - | S29: - | T29: - | U29: - | AD29: Net Property, Plant & Equipment | AE29: 1429 | AF29: 1497 | AG29: 1602 | AH29: 1656 | AI29: 564
B30: Shares | C30: 171.89 | N30: Equity in Affiliates (Pretax) | Q30: 17 | R30: 20 | S30: 10 | T30: 8 | U30: 2 | W30: Other Assets/Liabilities | X30: -110 | Y30: -135 | Z30: -265 | AA30: 227 | AB30: -32 | AD30: Property, Plant & Equipment - Gross | AE30: 2479 | AF30: 2403 | AG30: 2373 | AH30: 2216 | AI30: 1037
B31: Share Price | C31: =C29/C30 -> 213.16383 | N31: Interest Expense | Q31: 186 | R31: 177 | S31: 199 | T31: 219 | U31: 107 | AD31: Buildings | AE31: 783 | AF31: 785 | AG31: 801 | AH31: 774 | AI31: 248
B32: % Debt | C32: =C28/AE103 -> 0.33990342 | N32: Interest Expense Growth | Q32: 0.0508 | R32: -0.1101 | S32: -0.0922 | T32: 1.0416 | U32: - | W32: Net Operating Cash Flow | X32: 1038 | Y32: 1073 | Z32: 784 | AA32: 1016 | AB32: 315 | AD32: Land & Improvements | AE32: 100 | AF32: 96 | AG32: 98 | AH32: 78 | AI32: 39
B33: Cost of Debt | C33: =(1-C34)*Q34/C28 -> 0.042603653 | G33: Terminal Growth Rate | W33: Net Operating Cash Flow Growth | X33: -0.0326 | Y33: 0.3691 | Z33: -0.2283 | AA33: 2.2272 | AB33: - | AD33: Machinery & Equipment | AE33: 1474 | AF33: 1433 | AG33: 1475 | AH33: 1364 | AI33: 750
B34: Tax Rate | C34: 0.21 | G34: =H34-0.005 -> 0.01 | H34: =I34-0.005 -> 0.015 | I34: =C43 -> 0.02 | J34: =I34+0.005 -> 0.025 | K34: =J34+0.005 -> 0.03 | N34: Gross Interest Expense | Q34: 186 | R34: 177 | S34: 199 | T34: 219 | U34: 107 | AD34: Construction in Progress | AE34: 122 | AF34: 89 | AG34: - | AH34: - | AI34: -
B35: Equity Value | C35: 10524 | E35: WACC | F35: =F36+0.005 -> 0.087794088 | G35: =TEXT((((((($K$21*(1+G$34))/ABS($F35-G$34))/(1+$C$38)^$K$5)+SUM($H$21:$K$21)-$C$28+$C$27)/$C$30/$G$26)-1),"0.0%") &" / "& TEXT((1+(((((($K$21*(1+G$34))/ABS($F35-G$34))/(1+$C$38)^$K$5)+SUM($H$21:$K$21)-$C$28+$C$27)/$C$30/$G$26)-1))*$G$26,"$0.00") -> -17.6% / $165.18 | H35: =TEXT((((((($K$21*(1+H$34))/ABS($F35-H$34))/(1+$C$38)^$K$5)+SUM($H$21:$K$21)-$C$28+$C$27)/$C$30/$G$26)-1),"0.0%") &" / "& TEXT((1+(((((($K$21*(1+H$34))/ABS($F35-H$34))/(1+$C$38)^$K$5)+SUM($H$21:$K$21)-$C$28+$C$27)/$C$30/$G$26)-1))*$G$26,"$0.00") -> -12.6% / $175.06 | I35: =TEXT((((((($K$21*(1+I$34))/ABS($F35-I$34))/(1+$C$38)^$K$5)+SUM($H$21:$K$21)-$C$28+$C$27)/$C$30/$G$26)-1),"0.0%") &" / "& TEXT((1+(((((($K$21*(1+I$34))/ABS($F35-I$34))/(1+$C$38)^$K$5)+SUM($H$21:$K$21)-$C$28+$C$27)/$C$30/$G$26)-1))*$G$26,"$0.00") -> -7.0% / $186.39 | J35: =TEXT((((((($K$21*(1+J$34))/ABS($F35-J$34))/(1+$C$38)^$K$5)+SUM($H$21:$K$21)-$C$28+$C$27)/$C$30/$G$26)-1),"0.0%") &" / "& TEXT((1+(((((($K$21*(1+J$34))/ABS($F35-J$34))/(1+$C$38)^$K$5)+SUM($H$21:$K$21)-$C$28+$C$27)/$C$30/$G$26)-1))*$G$26,"$0.00") -> -0.4% / $199.53 | K35: =TEXT((((((($K$21*(1+K$34))/ABS($F35-K$34))/(1+$C$38)^$K$5)+SUM($H$21:$K$21)-$C$28+$C$27)/$C$30/$G$26)-1),"0.0%") &" / "& TEXT((1+(((((($K$21*(1+K$34))/ABS($F35-K$34))/(1+$C$38)^$K$5)+SUM($H$21:$K$21)-$C$28+$C$27)/$C$30/$G$26)-1))*$G$26,"$0.00") -> 7.3% / $214.94 | N35: Interest Capitalized | Q35: - | R35: - | S35: - | T35: - | U35: - | W35: Net Operating Cash Flow / Sales | X35: 0.1241 | Y35: 0.1372 | Z35: 0.1037 | AA35: 0.1238 | AB35: 0.0721 | AD35: Accumulated Depreciation | AE35: 1050 | AF35: 906 | AG35: 772 | AH35: 560 | AI35: 473
B36: % Equity | C36: =C35/C41 -> 0.75316682 | F36: =F37+0.005 -> 0.082794088 | G36: =TEXT((((((($K$21*(1+G$34))/ABS($F36-G$34))/(1+$C$38)^$K$5)+SUM($H$21:$K$21)-$C$28+$C$27)/$C$30/$G$26)-1),"0.0%") &" / "& TEXT((1+(((((($K$21*(1+G$34))/ABS($F36-G$34))/(1+$C$38)^$K$5)+SUM($H$21:$K$21)-$C$28+$C$27)/$C$30/$G$26)-1))*$G$26,"$0.00") -> -13.0% / $174.35 | H36: =TEXT((((((($K$21*(1+H$34))/ABS($F36-H$34))/(1+$C$38)^$K$5)+SUM($H$21:$K$21)-$C$28+$C$27)/$C$30/$G$26)-1),"0.0%") &" / "& TEXT((1+(((((($K$21*(1+H$34))/ABS($F36-H$34))/(1+$C$38)^$K$5)+SUM($H$21:$K$21)-$C$28+$C$27)/$C$30/$G$26)-1))*$G$26,"$0.00") -> -7.4% / $185.63 | I36: =TEXT((((((($K$21*(1+I$34))/ABS($F36-I$34))/(1+$C$38)^$K$5)+SUM($H$21:$K$21)-$C$28+$C$27)/$C$30/$G$26)-1),"0.0%") &" / "& TEXT((1+(((((($K$21*(1+I$34))/ABS($F36-I$34))/(1+$C$38)^$K$5)+SUM($H$21:$K$21)-$C$28+$C$27)/$C$30/$G$26)-1))*$G$26,"$0.00") -> -0.8% / $198.71 | J36: =TEXT((((((($K$21*(1+J$34))/ABS($F36-J$34))/(1+$C$38)^$K$5)+SUM($H$21:$K$21)-$C$28+$C$27)/$C$30/$G$26)-1),"0.0%") &" / "& TEXT((1+(((((($K$21*(1+J$34))/ABS($F36-J$34))/(1+$C$38)^$K$5)+SUM($H$21:$K$21)-$C$28+$C$27)/$C$30/$G$26)-1))*$G$26,"$0.00") -> 6.8% / $214.05 | K36: =TEXT((((((($K$21*(1+K$34))/ABS($F36-K$34))/(1+$C$38)^$K$5)+SUM($H$21:$K$21)-$C$28+$C$27)/$C$30/$G$26)-1),"0.0%") &" / "& TEXT((1+(((((($K$21*(1+K$34))/ABS($F36-K$34))/(1+$C$38)^$K$5)+SUM($H$21:$K$21)-$C$28+$C$27)/$C$30/$G$26)-1))*$G$26,"$0.00") -> 15.9% / $232.30 | N36: Pretax Income | Q36: 854 | R36: 737 | S36: 557 | T36: 447 | U36: 368 | W36: Capital Expenditures | X36: -149 | Y36: -130 | Z36: -136 | AA36: -185 | AB36: -93 | AD36: Total Investments and Advances | AE36: 105 | AF36: 96 | AG36: 200 | AH36: - | AI36: -
B37: Cost of Equity Risk Free Rate + (Beta x (Expected Market Return - Risk Free Rate)) | C37: =C38+C39*C40 -> 0.0881 | F37: =C42 -> 0.077794088 | G37: =TEXT((((((($K$21*(1+G$34))/ABS($F37-G$34))/(1+$C$38)^$K$5)+SUM($H$21:$K$21)-$C$28+$C$27)/$C$30/$G$26)-1),"0.0%") &" / "& TEXT((1+(((((($K$21*(1+G$34))/ABS($F37-G$34))/(1+$C$38)^$K$5)+SUM($H$21:$K$21)-$C$28+$C$27)/$C$30/$G$26)-1))*$G$26,"$0.00") -> -7.7% / $184.87 | H37: =TEXT((((((($K$21*(1+H$34))/ABS($F37-H$34))/(1+$C$38)^$K$5)+SUM($H$21:$K$21)-$C$28+$C$27)/$C$30/$G$26)-1),"0.0%") &" / "& TEXT((1+(((((($K$21*(1+H$34))/ABS($F37-H$34))/(1+$C$38)^$K$5)+SUM($H$21:$K$21)-$C$28+$C$27)/$C$30/$G$26)-1))*$G$26,"$0.00") -> -1.3% / $197.89 | I37: =TEXT((((((($K$21*(1+I$34))/ABS($F37-I$34))/(1+$C$38)^$K$5)+SUM($H$21:$K$21)-$C$28+$C$27)/$C$30/$G$26)-1),"0.0%") &" / "& TEXT((1+(((((($K$21*(1+I$34))/ABS($F37-I$34))/(1+$C$38)^$K$5)+SUM($H$21:$K$21)-$C$28+$C$27)/$C$30/$G$26)-1))*$G$26,"$0.00") -> 6.4% / $213.16 | J37: =TEXT((((((($K$21*(1+J$34))/ABS($F37-J$34))/(1+$C$38)^$K$5)+SUM($H$21:$K$21)-$C$28+$C$27)/$C$30/$G$26)-1),"0.0%") &" / "& TEXT((1+(((((($K$21*(1+J$34))/ABS($F37-J$34))/(1+$C$38)^$K$5)+SUM($H$21:$K$21)-$C$28+$C$27)/$C$30/$G$26)-1))*$G$26,"$0.00") -> 15.4% / $231.33 | K37: =TEXT((((((($K$21*(1+K$34))/ABS($F37-K$34))/(1+$C$38)^$K$5)+SUM($H$21:$K$21)-$C$28+$C$27)/$C$30/$G$26)-1),"0.0%") &" / "& TEXT((1+(((((($K$21*(1+K$34))/ABS($F37-K$34))/(1+$C$38)^$K$5)+SUM($H$21:$K$21)-$C$28+$C$27)/$C$30/$G$26)-1))*$G$26,"$0.00") -> 26.4% / $253.29 | N37: Pretax Income Growth | Q37: 0.1588 | R37: 0.3227 | S37: 0.2471 | T37: 0.2155 | U37: - | AD37: LT Investment - Affiliate Companies | AE37: 105 | AF37: 96 | AG37: 100 | AH37: - | AI37: -
B38: Risk Free Rate | C38: 0.05 | D38: from US10Y | F38: =F37-0.005 -> 0.072794088 | G38: =TEXT((((((($K$21*(1+G$34))/ABS($F38-G$34))/(1+$C$38)^$K$5)+SUM($H$21:$K$21)-$C$28+$C$27)/$C$30/$G$26)-1),"0.0%") &" / "& TEXT((1+(((((($K$21*(1+G$34))/ABS($F38-G$34))/(1+$C$38)^$K$5)+SUM($H$21:$K$21)-$C$28+$C$27)/$C$30/$G$26)-1))*$G$26,"$0.00") -> -1.7% / $197.07 | H38: =TEXT((((((($K$21*(1+H$34))/ABS($F38-H$34))/(1+$C$38)^$K$5)+SUM($H$21:$K$21)-$C$28+$C$27)/$C$30/$G$26)-1),"0.0%") &" / "& TEXT((1+(((((($K$21*(1+H$34))/ABS($F38-H$34))/(1+$C$38)^$K$5)+SUM($H$21:$K$21)-$C$28+$C$27)/$C$30/$G$26)-1))*$G$26,"$0.00") -> 5.9% / $212.27 | I38: =TEXT((((((($K$21*(1+I$34))/ABS($F38-I$34))/(1+$C$38)^$K$5)+SUM($H$21:$K$21)-$C$28+$C$27)/$C$30/$G$26)-1),"0.0%") &" / "& TEXT((1+(((((($K$21*(1+I$34))/ABS($F38-I$34))/(1+$C$38)^$K$5)+SUM($H$21:$K$21)-$C$28+$C$27)/$C$30/$G$26)-1))*$G$26,"$0.00") -> 14.9% / $230.35 | J38: =TEXT((((((($K$21*(1+J$34))/ABS($F38-J$34))/(1+$C$38)^$K$5)+SUM($H$21:$K$21)-$C$28+$C$27)/$C$30/$G$26)-1),"0.0%") &" / "& TEXT((1+(((((($K$21*(1+J$34))/ABS($F38-J$34))/(1+$C$38)^$K$5)+SUM($H$21:$K$21)-$C$28+$C$27)/$C$30/$G$26)-1))*$G$26,"$0.00") -> 25.9% / $252.22 | K38: =TEXT((((((($K$21*(1+K$34))/ABS($F38-K$34))/(1+$C$38)^$K$5)+SUM($H$21:$K$21)-$C$28+$C$27)/$C$30/$G$26)-1),"0.0%") &" / "& TEXT((1+(((((($K$21*(1+K$34))/ABS($F38-K$34))/(1+$C$38)^$K$5)+SUM($H$21:$K$21)-$C$28+$C$27)/$C$30/$G$26)-1))*$G$26,"$0.00") -> 39.3% / $279.19 | N38: Pretax Margin | Q38: 0.1021 | R38: - | S38: - | T38: - | U38: - | W38: Capital Expenditures (Fixed Assets) | X38: -149 | Y38: -130 | Z38: -136 | AA38: -185 | AB38: -93 | AD38: Other Long-Term Investments | AE38: - | AF38: - | AG38: 100 | AH38: - | AI38: -
B39: Beta | C39: 1.27 | F39: =F38-0.005 -> 0.067794088 | G39: =TEXT((((((($K$21*(1+G$34))/ABS($F39-G$34))/(1+$C$38)^$K$5)+SUM($H$21:$K$21)-$C$28+$C$27)/$C$30/$G$26)-1),"0.0%") &" / "& TEXT((1+(((((($K$21*(1+G$34))/ABS($F39-G$34))/(1+$C$38)^$K$5)+SUM($H$21:$K$21)-$C$28+$C$27)/$C$30/$G$26)-1))*$G$26,"$0.00") -> 5.5% / $211.38 | H39: =TEXT((((((($K$21*(1+H$34))/ABS($F39-H$34))/(1+$C$38)^$K$5)+SUM($H$21:$K$21)-$C$28+$C$27)/$C$30/$G$26)-1),"0.0%") &" / "& TEXT((1+(((((($K$21*(1+H$34))/ABS($F39-H$34))/(1+$C$38)^$K$5)+SUM($H$21:$K$21)-$C$28+$C$27)/$C$30/$G$26)-1))*$G$26,"$0.00") -> 14.5% / $229.38 | I39: =TEXT((((((($K$21*(1+I$34))/ABS($F39-I$34))/(1+$C$38)^$K$5)+SUM($H$21:$K$21)-$C$28+$C$27)/$C$30/$G$26)-1),"0.0%") &" / "& TEXT((1+(((((($K$21*(1+I$34))/ABS($F39-I$34))/(1+$C$38)^$K$5)+SUM($H$21:$K$21)-$C$28+$C$27)/$C$30/$G$26)-1))*$G$26,"$0.00") -> 25.3% / $251.14 | J39: =TEXT((((((($K$21*(1+J$34))/ABS($F39-J$34))/(1+$C$38)^$K$5)+SUM($H$21:$K$21)-$C$28+$C$27)/$C$30/$G$26)-1),"0.0%") &" / "& TEXT((1+(((((($K$21*(1+J$34))/ABS($F39-J$34))/(1+$C$38)^$K$5)+SUM($H$21:$K$21)-$C$28+$C$27)/$C$30/$G$26)-1))*$G$26,"$0.00") -> 38.7% / $277.99 | K39: =TEXT((((((($K$21*(1+K$34))/ABS($F39-K$34))/(1+$C$38)^$K$5)+SUM($H$21:$K$21)-$C$28+$C$27)/$C$30/$G$26)-1),"0.0%") &" / "& TEXT((1+(((((($K$21*(1+K$34))/ABS($F39-K$34))/(1+$C$38)^$K$5)+SUM($H$21:$K$21)-$C$28+$C$27)/$C$30/$G$26)-1))*$G$26,"$0.00") -> 55.7% / $311.94 | N39: Income Tax | Q39: 213 | R39: 172 | S39: 145 | T39: 120 | U39: 76 | AD39: Long-Term Note Receivable | AE39: 162 | AF39: 153 | AG39: 101 | AH39: 109 | AI39: -
B40: Market Risk Premium = Market return - Risk free return | C40: =D40-C38 -> 0.03 | D40: 0.08 | N40: Income Tax - Current Domestic | Q40: 40 | R40: -54 | S40: 23 | T40: 6 | U40: 13 | W40: Capital Expenditures (Other Assets) | X40: - | Y40: - | Z40: - | AA40: - | AB40: - | AD40: Intangible Assets | AE40: 11910 | AF40: 12292 | AG40: 12354 | AH40: 12465 | AI40: 3526
B41: Debt + Equity | C41: =C28+C35 -> 13973 | W41: Capital Expenditures Growth | X41: -0.1462 | Y41: 0.0469 | Z41: 0.2639 | AA41: -0.986 | AB41: - | AD41: Net Goodwill | AE41: 8508 | AF41: 8587 | AG41: 8485 | AH41: 8361 | AI41: 2397
...

Sheet CCA
B2: Comparable Company Analysis | G2: Westinghouse Air Brake
G3: Technologies Corporation (WAB)
E5: EPS | F5: Cash | G5: Debt
B6: 45236 | C6: Share Price: | D6: =DCF!G26 -> 200.4 | E6: 5.99 | F6: =DCF!C27 -> 620 | G6: =DCF!C28 -> 3449
H7: Revenue (in million USDs) | K7: EBITDA (in million USDs) | M7: Net Income (in millions)
B8: Ticker | C8: Company | D8: Share Price | E8: nbr of Shares (M) | F8: Enterprise Value | G8: Market Cap | H8: 2022 | I8: 2023 | J8: 2024 | K8: 2023 | L8: 2024 | M8: 2023 | N8: 2024
B9: WAB | C9: WAB Tech | D9: =DCF!G26 -> 200.4 | E9: =DCF!C30 -> 171.89 | F9: =DCF!C26 -> 39469.731 | G9: =E9*D9 -> 34446.756 | H9: =DCF!E7 -> 8362 | I9: =DCF!F7 -> 9677 | J9: =DCF!G7 -> 10330 | K9: =DCF!F9+DCF!F14 -> 1787 | L9: =DCF!G9+DCF!G14 -> 2095 | M9: =DCF!Q53 -> 633 | N9: 815
B10: GBX | C10: The Greenbrier | D10: 65.21 | E10: 31.34 | F10: 2570 | G10: 2044 | H10: 2977 | I10: 3944 | J10: 3544 | K10: 276 | L10: 433 | M10: 62 | N10: 160
B11: CSX | C11: CSX Corp | D11: 36.88 | E11: 1950 | F11: 3420 | G11: 71120 | H11: 14853 | I11: 14657 | J11: 14681 | K11: 7656 | L11: 7311 | M11: 4166 | N11: 3715
B12: TRN | C12: Trinity Industries | D12: 37 | E12: 82.16 | F12: 8340 | G12: 2870 | H12: 1977 | I12: 2983 | J12: 3247 | K12: 707 | L12: 822 | M12: 106 | N12: 172
B13: CNI | C13: Canadian National | D13: 112.32 | E13: 628 | F13: 88800 | G13: 73710 | H13: 17107 | I13: 16828 | J13: 17159 | K13: 9027 | L13: 8941 | M13: 5625 | N13: 5432
B14: FDX | C14: FedEx | D14: 280.06 | E14: 244 | F14: 104410 | G14: 73190 | H14: 93512 | I14: 90155 | J14: 87693 | K14: 10233 | L14: 10868 | M14: 3972 | N14: 4331
B15: NSC | C15: Norfolk Southern | D15: 277 | E15: 226 | F15: 73120 | G15: 56180 | H15: 12745 | I15: 12156 | J15: 12172 | K15: 4340 | L15: 5196 | M15: 1827 | N15: 2416
C17: Revenue Growth | E17: EBITDA Margin | G17: Profit Margin | I17: EV / Revenue | K17: EV / EBITDA | M17: P / E
C18: 2022 | D18: 2023 | E18: 2022 | F18: 2023 | G18: 2022 | H18: 2023 | I18: 2022 | J18: 2023 | K18: 2022 | L18: 2023 | M18: 2022 | N18: 2023
B19: =B9 -> WAB | C19: =I9/H9-1 -> 0.15725903 | D19: =J9/I9-1 -> 0.067479591 | E19: =K9/I9 -> 0.18466467 | F19: =L9/J9 -> 0.20280736 | G19: =M9/I9 -> 0.065412835 | H19: =N9/J9 -> 0.078896418 | I19: =$F9/I9 -> 4.0787156 | J19: =$F9/J9 -> 3.8208839 | K19: =$F9/K9 -> 22.087146 | L19: =$F9/L9 -> 18.839967 | M19: =$G9/M9 -> 54.418256 | N19: =$G9/N9 -> 42.265958
B20: =B10 -> GBX | C20: =I10/H10-1 -> 0.32482365 | D20: =J10/I10-1 -> -0.10141988 | E20: =K10/I10 -> 0.069979716 | F20: =L10/J10 -> 0.12217833 | G20: =M10/I10 -> 0.015720081 | H20: =N10/J10 -> 0.045146727 | I20: =$F10/I10 -> 0.65162272 | J20: =$F10/J10 -> 0.7251693 | K20: =$F10/K10 -> 9.3115942 | L20: =$F10/L10 -> 5.9353349 | M20: =$G10/M10 -> 32.967742 | N20: =$G10/N10 -> 12.775
B21: =B11 -> CSX | C21: =I11/H11-1 -> -0.013195987 | D21: =J11/I11-1 -> 0.0016374429 | E21: =K11/I11 -> 0.52234427 | F21: =L11/J11 -> 0.4979906 | G21: =M11/I11 -> 0.28423279 | H21: =N11/J11 -> 0.25304816 | I21: =$F11/I11 -> 0.23333561 | J21: =$F11/J11 -> 0.23295416 | K21: =$F11/K11 -> 0.44670846 | L21: =$F11/L11 -> 0.46778826 | M21: =$G11/M11 -> 17.071531 | N21: =$G11/N11 -> 19.144011
B22: =B12 -> TRN | C22: =I12/H12-1 -> 0.5088518 | D22: =J12/I12-1 -> 0.088501509 | E22: =K12/I12 -> 0.23700972 | F22: =L12/J12 -> 0.25315676 | G22: =M12/I12 -> 0.035534697 | H22: =N12/J12 -> 0.052971974 | I22: =$F12/I12 -> 2.7958431 | J22: =$F12/J12 -> 2.5685248 | K22: =$F12/K12 -> 11.796322 | L22: =$F12/L12 -> 10.145985 | M22: =$G12/M12 -> 27.075472 | N22: =$G12/N12 -> 16.686047
B23: =B13 -> CNI | C23: =I13/H13-1 -> -0.016309113 | D23: =J13/I13-1 -> 0.019669598 | E23: =K13/I13 -> 0.53642738 | F23: =L13/J13 -> 0.52106766 | G23: =M13/I13 -> 0.33426432 | H23: =N13/J13 -> 0.31656856 | I23: =$F13/I13 -> 5.2769194 | J23: =$F13/J13 -> 5.1751268 | K23: =$F13/K13 -> 9.8371552 | L23: =$F13/L13 -> 9.931775 | M23: =$G13/M13 -> 13.104 | N23: =$G13/N13 -> 13.569588
B24: =B14 -> FDX | C24: =I14/H14-1 -> -0.035899136 | D24: =J14/I14-1 -> -0.027308524 | E24: =K14/I14 -> 0.11350452 | F24: =L14/J14 -> 0.12393235 | G24: =M14/I14 -> 0.044057457 | H24: =N14/J14 -> 0.049388207 | I24: =$F14/I14 -> 1.1581166 | J24: =$F14/J14 -> 1.190631 | K24: =$F14/K14 -> 10.203264 | L24: =$F14/L14 -> 9.6071034 | M24: =$G14/M14 -> 18.426485 | N24: =$G14/N14 -> 16.8991
B25: =B15 -> NSC | C25: =I15/H15-1 -> -0.046214202 | D25: =J15/I15-1 -> 0.0013162224 | E25: =K15/I15 -> 0.35702534 | F25: =L15/J15 -> 0.42688137 | G25: =M15/I15 -> 0.15029615 | H25: =N15/J15 -> 0.19848833 | I25: =$F15/I15 -> 6.0151366 | J25: =$F15/J15 -> 6.0072297 | K25: =$F15/K15 -> 16.847926 | L25: =$F15/L15 -> 14.072363 | M25: =$G15/M15 -> 30.749863 | N25: =$G15/N15 -> 23.253311
C27: 2023 Trading Multiple | F27: Enterprise Value | I27: Equity Value | L27: Implied Share Price
C28: Revenue | D28: EBITDA | E28: P/E | F28: Revenue | G28: EBITDA | H28: Net Income | I28: Revenue | J28: EBITDA | K28: Net Income | L28: Revenue | M28: EBITDA | N28: Net Income
B29: Minimum | C29: =MIN(J19:J25) -> 0.23295416 | D29: =MIN(L19:L25) -> 0.46778826 | E29: =MIN(N19:N25) -> 12.775 | F29: =C29*$J$9 -> 2406.4165 | G29: =D29*$L$9 -> 980.01641 | H29: =N$9*E29 -> 10411.625 | I29: =F29+F$6-G$6 -> -422.58354 | J29: =G29+G$6-F$6 -> 3809.0164 | K29: =H29+G$6-F$6 -> 13240.625 | L29: =I29/E$9 -> -2.4584533 | M29: =J29/E$9 -> 22.159616 | N29: =K29/E$9 -> 77.029641
B30: 1st Quartile | C30: =QUARTILE(J19:J25,1) -> 0.95790013 | D30: =QUARTILE(L19:L25,1) -> 7.7712191 | E30: =QUARTILE(N19:N25,1) -> 15.127817 | F30: =C30*$J$9 -> 9895.1083 | G30: =D30*$L$9 -> 16280.704 | H30: =N$9*E30 -> 12329.171 | I30: =F30+F$6-G$6 -> 7066.1083 | J30: =G30+G$6-F$6 -> 19109.704 | K30: =H30+G$6-F$6 -> 15158.171 | L30: =I30/E$9 -> 41.108315 | M30: =J30/E$9 -> 111.17403 | N30: =K30/E$9 -> 88.185298
B31: Mean | C31: =AVERAGE(J19:J25) -> 2.8172171 | D31: =AVERAGE(L19:L25) -> 9.8571882 | E31: =AVERAGE(N19:N25) -> 20.656145 | F31: =C31*$J$9 -> 29101.852 | G31: =D31*$L$9 -> 20650.809 | H31: =N$9*E31 -> 16834.758 | I31: =F31+F$6-G$6 -> 26272.852 | J31: =G31+G$6-F$6 -> 23479.809 | K31: =H31+G$6-F$6 -> 19663.758 | L31: =I31/E$9 -> 152.84689 | M31: =J31/E$9 -> 136.59788 | N31: =K31/E$9 -> 114.39734
B32: Median | C32: =MEDIAN(J19:J25) -> 2.5685248 | D32: =MEDIAN(L19:L25) -> 9.931775 | E32: =MEDIAN(N19:N25) -> 16.8991 | F32: =C32*$J$9 -> 26532.861 | G32: =D32*$L$9 -> 20807.069 | H32: =N$9*E32 -> 13772.766 | I32: =F32+F$6-G$6 -> 23703.861 | J32: =G32+G$6-F$6 -> 23636.069 | K32: =H32+G$6-F$6 -> 16601.766 | L32: =I32/E$9 -> 137.90134 | M32: =J32/E$9 -> 137.50694 | N32: =K32/E$9 -> 96.583665
B33: 3rd Quartile | C33: =QUARTILE(J19:J25,3) -> 4.4980053 | D33: =QUARTILE(L19:L25,3) -> 12.109174 | E33: =QUARTILE(N19:N25,3) -> 21.198661 | F33: =C33*$J$9 -> 46464.395 | G33: =D33*$L$9 -> 25368.72 | H33: =N$9*E33 -> 17276.909 | I33: =F33+F$6-G$6 -> 43635.395 | J33: =G33+G$6-F$6 -> 28197.72 | K33: =H33+G$6-F$6 -> 20105.909 | L33: =I33/E$9 -> 253.85651 | M33: =J33/E$9 -> 164.04515 | N33: =K33/E$9 -> 116.96962
B34: Maximum | C34: =MAX(J19:J25) -> 6.0072297 | D34: =MAX(L19:L25) -> 18.839967 | E34: =MAX(N19:N25) -> 42.265958 | F34: =C34*$J$9 -> 62054.683 | G34: =D34*$L$9 -> 39469.731 | H34: =N$9*E34 -> 34446.756 | I34: =F34+F$6-G$6 -> 59225.683 | J34: =G34+G$6-F$6 -> 42298.731 | K34: =H34+G$6-F$6 -> 37275.756 | L34: =I34/E$9 -> 344.55572 | M34: =J34/E$9 -> 246.08023 | N34: =K34/E$9 -> 216.8582

Sheet Sheet1
D3: Terminal Growth Rate
D4: 0.1901 | E4: 0.1951 | F4: 0.2001 | G4: 0.2051 | H4: 0.2101
B5: WACC | C5: 0.114 | D5: {=TEXT(DCF!G35:K39,"0.0%")&" / "&TEXT((1+(((((($K$20*(1+G$36))/ABS($F37-G$36))/(1+$F37)^$K$5)+SUM($H$21:$K$21)-$C$28+$C$27)/$C$30/$G$31)-1))*DCF!G26,"$0.00")} -> #DIV/0! | E5: #DIV/0! | F5: #DIV/0! | G5: #DIV/0! | H5: #DIV/0!
C6: 0.104 | D6: #DIV/0! | E6: #DIV/0! | F6: #DIV/0! | G6: #DIV/0! | H6: #DIV/0!
C7: 0.094 | D7: #DIV/0! | E7: #DIV/0! | F7: #DIV/0! | G7: #DIV/0! | H7: #DIV/0!
C8: 0.084 | D8: #DIV/0! | E8: #DIV/0! | F8: #DIV/0! | G8: #DIV/0! | H8: #DIV/0!
C9: 0.074 | D9: #DIV/0! | E9: #DIV/0! | F9: #DIV/0! | G9: #DIV/0! | H9: #DIV/0!
H13: beta | I13: return
E14: {=I14:I22/100} -> -0.000781 | G14: CRRC Corp | H14: 1.027 | I14: -0.0781
E15: -0.000711 | G15: KTK Group | H15: 0.891 | I15: -0.0711
E16: 0.000461 | G16: Greenbrier Companies | H16: 1.195 | I16: 0.0461
E17: -0.000994 | G17: Stadler Rail | H17: 1.142 | I17: -0.0994
E18: -0.0012 | G18: Construcciones y Auxiliar de Ferrocarriles | H18: 1.019 | I18: -0.12
E19: -0.001598 | G19: Alstom | H19: 1.308 | I19: -0.1598
E20: 0.000935 | G20: WABtec | H20: 0.972 | I20: 0.0935 | J20: 3Y
E21: 0.000764 | G21: S&P | H21: 1 | I21: 0.0764
E22: 0.0001932 | G22: US 10Y | H22: 0 | I22: 0.01932

Sheet BBG Adj Highlights
A2: Westinghouse Air Brake Technologies Corp (WAB US) - BBG Adj Highlights
A4: In Millions of USD | C4: FY 2011 | D4: FY 2012 | E4: FY 2013 | F4: FY 2014 | G4: FY 2015 | H4: FY 2016 | I4: FY 2017 | J4: FY 2018 | K4: FY 2019 | L4: FY 2020 | M4: FY 2021 | N4: FY 2022 | O4: Current/LTM | P4: FY 2023 Est | Q4: FY 2024 Est
A5: 12 Months Ending | C5: 12/31/2011 | D5: 12/31/2012 | E5: 12/31/2013 | F5: 12/31/2014 | G5: 12/31/2015 | H5: 12/31/2016 | I5: 12/31/2017 | J5: 12/31/2018 | K5: 12/31/2019 | L5: 12/31/2020 | M5: 12/31/2021 | N5: 12/31/2022 | O5: 09/30/2023 | P5: 12/31/2023 | Q5: 12/31/2024
A6: Market Capitalization | B6: HISTORICAL_MARKET_CAP | C6: =_xll.BDH("WAB US Equity","HISTORICAL_MARKET_CAP","FY 2011","FY 2011","Currency=USD","Period=FY","BEST_FPERIOD_OVERRIDE=FY","FILING_STATUS=MR","SCALING_FORMAT=MLN","Sort=A","Dates=H","DateFormat=P","Fill=—","Direction=H","UseDPDF=Y") -> #NAME? | D6: =_xll.BDH("WAB US Equity","HISTORICAL_MARKET_CAP","FY 2012","FY 2012","Currency=USD","Period=FY","BEST_FPERIOD_OVERRIDE=FY","FILING_STATUS=MR","SCALING_FORMAT=MLN","Sort=A","Dates=H","DateFormat=P","Fill=—","Direction=H","UseDPDF=Y") -> #NAME? | E6: =_xll.BDH("WAB US Equity","HISTORICAL_MARKET_CAP","FY 2013","FY 2013","Currency=USD","Period=FY","BEST_FPERIOD_OVERRIDE=FY","FILING_STATUS=MR","SCALING_FORMAT=MLN","Sort=A","Dates=H","DateFormat=P","Fill=—","Direction=H","UseDPDF=Y") -> #NAME? | F6: =_xll.BDH("WAB US Equity","HISTORICAL_MARKET_CAP","FY 2014","FY 2014","Currency=USD","Period=FY","BEST_FPERIOD_OVERRIDE=FY","FILING_STATUS=MR","SCALING_FORMAT=MLN","Sort=A","Dates=H","DateFormat=P","Fill=—","Direction=H","UseDPDF=Y") -> #NAME? | G6: =_xll.BDH("WAB US Equity","HISTORICAL_MARKET_CAP","FY 2015","FY 2015","Currency=USD","Period=FY","BEST_FPERIOD_OVERRIDE=FY","FILING_STATUS=MR","SCALING_FORMAT=MLN","Sort=A","Dates=H","DateFormat=P","Fill=—","Direction=H","UseDPDF=Y") -> #NAME? | H6: =_xll.BDH("WAB US Equity","HISTORICAL_MARKET_CAP","FY 2016","FY 2016","Currency=USD","Period=FY","BEST_FPERIOD_OVERRIDE=FY","FILING_STATUS=MR","SCALING_FORMAT=MLN","Sort=A","Dates=H","DateFormat=P","Fill=—","Direction=H","UseDPDF=Y") -> #NAME? | I6: =_xll.BDH("WAB US Equity","HISTORICAL_MARKET_CAP","FY 2017","FY 2017","Currency=USD","Period=FY","BEST_FPERIOD_OVERRIDE=FY","FILING_STATUS=MR","SCALING_FORMAT=MLN","Sort=A","Dates=H","DateFormat=P","Fill=—","Direction=H","UseDPDF=Y") -> #NAME? | J6: =_xll.BDH("WAB US Equity","HISTORICAL_MARKET_CAP","FY 2018","FY 2018","Currency=USD","Period=FY","BEST_FPERIOD_OVERRIDE=FY","FILING_STATUS=MR","SCALING_FORMAT=MLN","Sort=A","Dates=H","DateFormat=P","Fill=—","Direction=H","UseDPDF=Y") -> #NAME? | K6: =_xll.BDH("WAB US Equity","HISTORICAL_MARKET_CAP","FY 2019","FY 2019","Currency=USD","Period=FY","BEST_FPERIOD_OVERRIDE=FY","FILING_STATUS=MR","SCALING_FORMAT=MLN","Sort=A","Dates=H","DateFormat=P","Fill=—","Direction=H","UseDPDF=Y") -> #NAME? | L6: =_xll.BDH("WAB US Equity","HISTORICAL_MARKET_CAP","FY 2020","FY 2020","Currency=USD","Period=FY","BEST_FPERIOD_OVERRIDE=FY","FILING_STATUS=MR","SCALING_FORMAT=MLN","Sort=A","Dates=H","DateFormat=P","Fill=—","Direction=H","UseDPDF=Y") -> #NAME? | M6: =_xll.BDH("WAB US Equity","HISTORICAL_MARKET_CAP","FY 2021","FY 2021","Currency=USD","Period=FY","BEST_FPERIOD_OVERRIDE=FY","FILING_STATUS=MR","SCALING_FORMAT=MLN","Sort=A","Dates=H","DateFormat=P","Fill=—","Direction=H","UseDPDF=Y") -> #NAME? | N6: =_xll.BDH("WAB US Equity","HISTORICAL_MARKET_CAP","FY 2022","FY 2022","Currency=USD","Period=FY","BEST_FPERIOD_OVERRIDE=FY","FILING_STATUS=MR","SCALING_FORMAT=MLN","Sort=A","Dates=H","DateFormat=P","Fill=—","Direction=H","UseDPDF=Y") -> #NAME? | O6: 20160.78
A7: - Cash & Equivalents | B7: CASH_AND_MARKETABLE_SECURITIES | C7: =_xll.BDH("WAB US Equity","CASH_AND_MARKETABLE_SECURITIES","FY 2011","FY 2011","Currency=USD","Period=FY","BEST_FPERIOD_OVERRIDE=FY","FILING_STATUS=MR","SCALING_FORMAT=MLN","Sort=A","Dates=H","DateFormat=P","Fill=—","Direction=H","UseDPDF=Y") -> #NAME? | D7: =_xll.BDH("WAB US Equity","CASH_AND_MARKETABLE_SECURITIES","FY 2012","FY 2012","Currency=USD","Period=FY","BEST_FPERIOD_OVERRIDE=FY","FILING_STATUS=MR","SCALING_FORMAT=MLN","Sort=A","Dates=H","DateFormat=P","Fill=—","Direction=H","UseDPDF=Y") -> #NAME? | E7: =_xll.BDH("WAB US Equity","CASH_AND_MARKETABLE_SECURITIES","FY 2013","FY 2013","Currency=USD","Period=FY","BEST_FPERIOD_OVERRIDE=FY","FILING_STATUS=MR","SCALING_FORMAT=MLN","Sort=A","Dates=H","DateFormat=P","Fill=—","Direction=H","UseDPDF=Y") -> #NAME? | F7: =_xll.BDH("WAB US Equity","CASH_AND_MARKETABLE_SECURITIES","FY 2014","FY 2014","Currency=USD","Period=FY","BEST_FPERIOD_OVERRIDE=FY","FILING_STATUS=MR","SCALING_FORMAT=MLN","Sort=A","Dates=H","DateFormat=P","Fill=—","Direction=H","UseDPDF=Y") -> #NAME? | G7: =_xll.BDH("WAB US Equity","CASH_AND_MARKETABLE_SECURITIES","FY 2015","FY 2015","Currency=USD","Period=FY","BEST_FPERIOD_OVERRIDE=FY","FILING_STATUS=MR","SCALING_FORMAT=MLN","Sort=A","Dates=H","DateFormat=P","Fill=—","Direction=H","UseDPDF=Y") -> #NAME? | H7: =_xll.BDH("WAB US Equity","CASH_AND_MARKETABLE_SECURITIES","FY 2016","FY 2016","Currency=USD","Period=FY","BEST_FPERIOD_OVERRIDE=FY","FILING_STATUS=MR","SCALING_FORMAT=MLN","Sort=A","Dates=H","DateFormat=P","Fill=—","Direction=H","UseDPDF=Y") -> #NAME? | I7: =_xll.BDH("WAB US Equity","CASH_AND_MARKETABLE_SECURITIES","FY 2017","FY 2017","Currency=USD","Period=FY","BEST_FPERIOD_OVERRIDE=FY","FILING_STATUS=MR","SCALING_FORMAT=MLN","Sort=A","Dates=H","DateFormat=P","Fill=—","Direction=H","UseDPDF=Y") -> #NAME? | J7: =_xll.BDH("WAB US Equity","CASH_AND_MARKETABLE_SECURITIES","FY 2018","FY 2018","Currency=USD","Period=FY","BEST_FPERIOD_OVERRIDE=FY","FILING_STATUS=MR","SCALING_FORMAT=MLN","Sort=A","Dates=H","DateFormat=P","Fill=—","Direction=H","UseDPDF=Y") -> #NAME? | K7: =_xll.BDH("WAB US Equity","CASH_AND_MARKETABLE_SECURITIES","FY 2019","FY 2019","Currency=USD","Period=FY","BEST_FPERIOD_OVERRIDE=FY","FILING_STATUS=MR","SCALING_FORMAT=MLN","Sort=A","Dates=H","DateFormat=P","Fill=—","Direction=H","UseDPDF=Y") -> #NAME? | L7: =_xll.BDH("WAB US Equity","CASH_AND_MARKETABLE_SECURITIES","FY 2020","FY 2020","Currency=USD","Period=FY","BEST_FPERIOD_OVERRIDE=FY","FILING_STATUS=MR","SCALING_FORMAT=MLN","Sort=A","Dates=H","DateFormat=P","Fill=—","Direction=H","UseDPDF=Y") -> #NAME? | M7: =_xll.BDH("WAB US Equity","CASH_AND_MARKETABLE_SECURITIES","FY 2021","FY 2021","Currency=USD","Period=FY","BEST_FPERIOD_OVERRIDE=FY","FILING_STATUS=MR","SCALING_FORMAT=MLN","Sort=A","Dates=H","DateFormat=P","Fill=—","Direction=H","UseDPDF=Y") -> #NAME? | N7: =_xll.BDH("WAB US Equity","CASH_AND_MARKETABLE_SECURITIES","FY 2022","FY 2022","Currency=USD","Period=FY","BEST_FPERIOD_OVERRIDE=FY","FILING_STATUS=MR","SCALING_FORMAT=MLN","Sort=A","Dates=H","DateFormat=P","Fill=—","Direction=H","UseDPDF=Y") -> #NAME? | O7: 392
A8: + Preferred & Other | B8: PFD_EQTY_MINORTY_INTEREST | C8: =_xll.BDH("WAB US Equity","PFD_EQTY_MINORTY_INTEREST","FY 2011","FY 2011","Currency=USD","Period=FY","BEST_FPERIOD_OVERRIDE=FY","FILING_STATUS=MR","SCALING_FORMAT=MLN","Sort=A","Dates=H","DateFormat=P","Fill=—","Direction=H","UseDPDF=Y") -> #NAME? | D8: =_xll.BDH("WAB US Equity","PFD_EQTY_MINORTY_INTEREST","FY 2012","FY 2012","Currency=USD","Period=FY","BEST_FPERIOD_OVERRIDE=FY","FILING_STATUS=MR","SCALING_FORMAT=MLN","Sort=A","Dates=H","DateFormat=P","Fill=—","Direction=H","UseDPDF=Y") -> #NAME? | E8: =_xll.BDH("WAB US Equity","PFD_EQTY_MINORTY_INTEREST","FY 2013","FY 2013","Currency=USD","Period=FY","BEST_FPERIOD_OVERRIDE=FY","FILING_STATUS=MR","SCALING_FORMAT=MLN","Sort=A","Dates=H","DateFormat=P","Fill=—","Direction=H","UseDPDF=Y") -> #NAME? | F8: =_xll.BDH("WAB US Equity","PFD_EQTY_MINORTY_INTEREST","FY 2014","FY 2014","Currency=USD","Period=FY","BEST_FPERIOD_OVERRIDE=FY","FILING_STATUS=MR","SCALING_FORMAT=MLN","Sort=A","Dates=H","DateFormat=P","Fill=—","Direction=H","UseDPDF=Y") -> #NAME? | G8: =_xll.BDH("WAB US Equity","PFD_EQTY_MINORTY_INTEREST","FY 2015","FY 2015","Currency=USD","Period=FY","BEST_FPERIOD_OVERRIDE=FY","FILING_STATUS=MR","SCALING_FORMAT=MLN","Sort=A","Dates=H","DateFormat=P","Fill=—","Direction=H","UseDPDF=Y") -> #NAME? | H8: =_xll.BDH("WAB US Equity","PFD_EQTY_MINORTY_INTEREST","FY 2016","FY 2016","Currency=USD","Period=FY","BEST_FPERIOD_OVERRIDE=FY","FILING_STATUS=MR","SCALING_FORMAT=MLN","Sort=A","Dates=H","DateFormat=P","Fill=—","Direction=H","UseDPDF=Y") -> #NAME? | I8: =_xll.BDH("WAB US Equity","PFD_EQTY_MINORTY_INTEREST","FY 2017","FY 2017","Currency=USD","Period=FY","BEST_FPERIOD_OVERRIDE=FY","FILING_STATUS=MR","SCALING_FORMAT=MLN","Sort=A","Dates=H","DateFormat=P","Fill=—","Direction=H","UseDPDF=Y") -> #NAME? | J8: =_xll.BDH("WAB US Equity","PFD_EQTY_MINORTY_INTEREST","FY 2018","FY 2018","Currency=USD","Period=FY","BEST_FPERIOD_OVERRIDE=FY","FILING_STATUS=MR","SCALING_FORMAT=MLN","Sort=A","Dates=H","DateFormat=P","Fill=—","Direction=H","UseDPDF=Y") -> #NAME? | K8: =_xll.BDH("WAB US Equity","PFD_EQTY_MINORTY_INTEREST","FY 2019","FY 2019","Currency=USD","Period=FY","BEST_FPERIOD_OVERRIDE=FY","FILING_STATUS=MR","SCALING_FORMAT=MLN","Sort=A","Dates=H","DateFormat=P","Fill=—","Direction=H","UseDPDF=Y") -> #NAME? | L8: =_xll.BDH("WAB US Equity","PFD_EQTY_MINORTY_INTEREST","FY 2020","FY 2020","Currency=USD","Period=FY","BEST_FPERIOD_OVERRIDE=FY","FILING_STATUS=MR","SCALING_FORMAT=MLN","Sort=A","Dates=H","DateFormat=P","Fill=—","Direction=H","UseDPDF=Y") -> #NAME? | M8: =_xll.BDH("WAB US Equity","PFD_EQTY_MINORTY_INTEREST","FY 2021","FY 2021","Currency=USD","Period=FY","BEST_FPERIOD_OVERRIDE=FY","FILING_STATUS=MR","SCALING_FORMAT=MLN","Sort=A","Dates=H","DateFormat=P","Fill=—","Direction=H","UseDPDF=Y") -> #NAME? | N8: =_xll.BDH("WAB US Equity","PFD_EQTY_MINORTY_INTEREST","FY 2022","FY 2022","Currency=USD","Period=FY","BEST_FPERIOD_OVERRIDE=FY","FILING_STATUS=MR","SCALING_FORMAT=MLN","Sort=A","Dates=H","DateFormat=P","Fill=—","Direction=H","UseDPDF=Y") -> #NAME? | O8: 41
A9: + Total Debt | B9: SHORT_AND_LONG_TERM_DEBT | C9: =_xll.BDH("WAB US Equity","SHORT_AND_LONG_TERM_DEBT","FY 2011","FY 2011","Currency=USD","Period=FY","BEST_FPERIOD_OVERRIDE=FY","FILING_STATUS=MR","SCALING_FORMAT=MLN","Sort=A","Dates=H","DateFormat=P","Fill=—","Direction=H","UseDPDF=Y") -> #NAME? | D9: =_xll.BDH("WAB US Equity","SHORT_AND_LONG_TERM_DEBT","FY 2012","FY 2012","Currency=USD","Period=FY","BEST_FPERIOD_OVERRIDE=FY","FILING_STATUS=MR","SCALING_FORMAT=MLN","Sort=A","Dates=H","DateFormat=P","Fill=—","Direction=H","UseDPDF=Y") -> #NAME? | E9: =_xll.BDH("WAB US Equity","SHORT_AND_LONG_TERM_DEBT","FY 2013","FY 2013","Currency=USD","Period=FY","BEST_FPERIOD_OVERRIDE=FY","FILING_STATUS=MR","SCALING_FORMAT=MLN","Sort=A","Dates=H","DateFormat=P","Fill=—","Direction=H","UseDPDF=Y") -> #NAME? | F9: =_xll.BDH("WAB US Equity","SHORT_AND_LONG_TERM_DEBT","FY 2014","FY 2014","Currency=USD","Period=FY","BEST_FPERIOD_OVERRIDE=FY","FILING_STATUS=MR","SCALING_FORMAT=MLN","Sort=A","Dates=H","DateFormat=P","Fill=—","Direction=H","UseDPDF=Y") -> #NAME? | G9: =_xll.BDH("WAB US Equity","SHORT_AND_LONG_TERM_DEBT","FY 2015","FY 2015","Currency=USD","Period=FY","BEST_FPERIOD_OVERRIDE=FY","FILING_STATUS=MR","SCALING_FORMAT=MLN","Sort=A","Dates=H","DateFormat=P","Fill=—","Direction=H","UseDPDF=Y") -> #NAME? | H9: =_xll.BDH("WAB US Equity","SHORT_AND_LONG_TERM_DEBT","FY 2016","FY 2016","Currency=USD","Period=FY","BEST_FPERIOD_OVERRIDE=FY","FILING_STATUS=MR","SCALING_FORMAT=MLN","Sort=A","Dates=H","DateFormat=P","Fill=—","Direction=H","UseDPDF=Y") -> #NAME? | I9: =_xll.BDH("WAB US Equity","SHORT_AND_LONG_TERM_DEBT","FY 2017","FY 2017","Currency=USD","Period=FY","BEST_FPERIOD_OVERRIDE=FY","FILING_STATUS=MR","SCALING_FORMAT=MLN","Sort=A","Dates=H","DateFormat=P","Fill=—","Direction=H","UseDPDF=Y") -> #NAME? | J9: =_xll.BDH("WAB US Equity","SHORT_AND_LONG_TERM_DEBT","FY 2018","FY 2018","Currency=USD","Period=FY","BEST_FPERIOD_OVERRIDE=FY","FILING_STATUS=MR","SCALING_FORMAT=MLN","Sort=A","Dates=H","DateFormat=P","Fill=—","Direction=H","UseDPDF=Y") -> #NAME? | K9: =_xll.BDH("WAB US Equity","SHORT_AND_LONG_TERM_DEBT","FY 2019","FY 2019","Currency=USD","Period=FY","BEST_FPERIOD_OVERRIDE=FY","FILING_STATUS=MR","SCALING_FORMAT=MLN","Sort=A","Dates=H","DateFormat=P","Fill=—","Direction=H","UseDPDF=Y") -> #NAME? | L9: =_xll.BDH("WAB US Equity","SHORT_AND_LONG_TERM_DEBT","FY 2020","FY 2020","Currency=USD","Period=FY","BEST_FPERIOD_OVERRIDE=FY","FILING_STATUS=MR","SCALING_FORMAT=MLN","Sort=A","Dates=H","DateFormat=P","Fill=—","Direction=H","UseDPDF=Y") -> #NAME? | M9: =_xll.BDH("WAB US Equity","SHORT_AND_LONG_TERM_DEBT","FY 2021","FY 2021","Currency=USD","Period=FY","BEST_FPERIOD_OVERRIDE=FY","FILING_STATUS=MR","SCALING_FORMAT=MLN","Sort=A","Dates=H","DateFormat=P","Fill=—","Direction=H","UseDPDF=Y") -> #NAME? | N9: =_xll.BDH("WAB US Equity","SHORT_AND_LONG_TERM_DEBT","FY 2022","FY 2022","Currency=USD","Period=FY","BEST_FPERIOD_OVERRIDE=FY","FILING_STATUS=MR","SCALING_FORMAT=MLN","Sort=A","Dates=H","DateFormat=P","Fill=—","Direction=H","UseDPDF=Y") -> #NAME? | O9: 4364
A10: Enterprise Value | B10: ENTERPRISE_VALUE | C10: =_xll.BDH("WAB US Equity","ENTERPRISE_VALUE","FY 2011","FY 2011","Currency=USD","Period=FY","BEST_FPERIOD_OVERRIDE=FY","FILING_STATUS=MR","SCALING_FORMAT=MLN","Sort=A","Dates=H","DateFormat=P","Fill=—","Direction=H","UseDPDF=Y") -> #NAME? | D10: =_xll.BDH("WAB US Equity","ENTERPRISE_VALUE","FY 2012","FY 2012","Currency=USD","Period=FY","BEST_FPERIOD_OVERRIDE=FY","FILING_STATUS=MR","SCALING_FORMAT=MLN","Sort=A","Dates=H","DateFormat=P","Fill=—","Direction=H","UseDPDF=Y") -> #NAME? | E10: =_xll.BDH("WAB US Equity","ENTERPRISE_VALUE","FY 2013","FY 2013","Currency=USD","Period=FY","BEST_FPERIOD_OVERRIDE=FY","FILING_STATUS=MR","SCALING_FORMAT=MLN","Sort=A","Dates=H","DateFormat=P","Fill=—","Direction=H","UseDPDF=Y") -> #NAME? | F10: =_xll.BDH("WAB US Equity","ENTERPRISE_VALUE","FY 2014","FY 2014","Currency=USD","Period=FY","BEST_FPERIOD_OVERRIDE=FY","FILING_STATUS=MR","SCALING_FORMAT=MLN","Sort=A","Dates=H","DateFormat=P","Fill=—","Direction=H","UseDPDF=Y") -> #NAME? | G10: =_xll.BDH("WAB US Equity","ENTERPRISE_VALUE","FY 2015","FY 2015","Currency=USD","Period=FY","BEST_FPERIOD_OVERRIDE=FY","FILING_STATUS=MR","SCALING_FORMAT=MLN","Sort=A","Dates=H","DateFormat=P","Fill=—","Direction=H","UseDPDF=Y") -> #NAME? | H10: =_xll.BDH("WAB US Equity","ENTERPRISE_VALUE","FY 2016","FY 2016","Currency=USD","Period=FY","BEST_FPERIOD_OVERRIDE=FY","FILING_STATUS=MR","SCALING_FORMAT=MLN","Sort=A","Dates=H","DateFormat=P","Fill=—","Direction=H","UseDPDF=Y") -> #NAME? | I10: =_xll.BDH("WAB US Equity","ENTERPRISE_VALUE","FY 2017","FY 2017","Currency=USD","Period=FY","BEST_FPERIOD_OVERRIDE=FY","FILING_STATUS=MR","SCALING_FORMAT=MLN","Sort=A","Dates=H","DateFormat=P","Fill=—","Direction=H","UseDPDF=Y") -> #NAME? | J10: =_xll.BDH("WAB US Equity","ENTERPRISE_VALUE","FY 2018","FY 2018","Currency=USD","Period=FY","BEST_FPERIOD_OVERRIDE=FY","FILING_STATUS=MR","SCALING_FORMAT=MLN","Sort=A","Dates=H","DateFormat=P","Fill=—","Direction=H","UseDPDF=Y") -> #NAME? | K10: =_xll.BDH("WAB US Equity","ENTERPRISE_VALUE","FY 2019","FY 2019","Currency=USD","Period=FY","BEST_FPERIOD_OVERRIDE=FY","FILING_STATUS=MR","SCALING_FORMAT=MLN","Sort=A","Dates=H","DateFormat=P","Fill=—","Direction=H","UseDPDF=Y") -> #NAME? | L10: =_xll.BDH("WAB US Equity","ENTERPRISE_VALUE","FY 2020","FY 2020","Currency=USD","Period=FY","BEST_FPERIOD_OVERRIDE=FY","FILING_STATUS=MR","SCALING_FORMAT=MLN","Sort=A","Dates=H","DateFormat=P","Fill=—","Direction=H","UseDPDF=Y") -> #NAME? | M10: =_xll.BDH("WAB US Equity","ENTERPRISE_VALUE","FY 2021","FY 2021","Currency=USD","Period=FY","BEST_FPERIOD_OVERRIDE=FY","FILING_STATUS=MR","SCALING_FORMAT=MLN","Sort=A","Dates=H","DateFormat=P","Fill=—","Direction=H","UseDPDF=Y") -> #NAME? | N10: =_xll.BDH("WAB US Equity","ENTERPRISE_VALUE","FY 2022","FY 2022","Currency=USD","Period=FY","BEST_FPERIOD_OVERRIDE=FY","FILING_STATUS=MR","SCALING_FORMAT=MLN","Sort=A","Dates=H","DateFormat=P","Fill=—","Direction=H","UseDPDF=Y") -> #NAME? | O10: 24173.78
A12: Revenue, Adj | B12: SALES_REV_TURN | C12: =_xll.BDH("WAB US Equity","SALES_REV_TURN","FY 2011","FY 2011","Currency=USD","Period=FY","BEST_FPERIOD_OVERRIDE=FY","FILING_STATUS=MR","SCALING_FORMAT=MLN","FA_ADJUSTED=Adjusted","Sort=A","Dates=H","DateFormat=P","Fill=—","Direction=H","UseDPDF=Y") -> #NAME? | D12: =_xll.BDH("WAB US Equity","SALES_REV_TURN","FY 2012","FY 2012","Currency=USD","Period=FY","BEST_FPERIOD_OVERRIDE=FY","FILING_STATUS=MR","SCALING_FORMAT=MLN","FA_ADJUSTED=Adjusted","Sort=A","Dates=H","DateFormat=P","Fill=—","Direction=H","UseDPDF=Y") -> #NAME? | E12: =_xll.BDH("WAB US Equity","SALES_REV_TURN","FY 2013","FY 2013","Currency=USD","Period=FY","BEST_FPERIOD_OVERRIDE=FY","FILING_STATUS=MR","SCALING_FORMAT=MLN","FA_ADJUSTED=Adjusted","Sort=A","Dates=H","DateFormat=P","Fill=—","Direction=H","UseDPDF=Y") -> #NAME? | F12: =_xll.BDH("WAB US Equity","SALES_REV_TURN","FY 2014","FY 2014","Currency=USD","Period=FY","BEST_FPERIOD_OVERRIDE=FY","FILING_STATUS=MR","SCALING_FORMAT=MLN","FA_ADJUSTED=Adjusted","Sort=A","Dates=H","DateFormat=P","Fill=—","Direction=H","UseDPDF=Y") -> #NAME? | G12: =_xll.BDH("WAB US Equity","SALES_REV_TURN","FY 2015","FY 2015","Currency=USD","Period=FY","BEST_FPERIOD_OVERRIDE=FY","FILING_STATUS=MR","SCALING_FORMAT=MLN","FA_ADJUSTED=Adjusted","Sort=A","Dates=H","DateFormat=P","Fill=—","Direction=H","UseDPDF=Y") -> #NAME? | H12: =_xll.BDH("WAB US Equity","SALES_REV_TURN","FY 2016","FY 2016","Currency=USD","Period=FY","BEST_FPERIOD_OVERRIDE=FY","FILING_STATUS=MR","SCALING_FORMAT=MLN","FA_ADJUSTED=Adjusted","Sort=A","Dates=H","DateFormat=P","Fill=—","Direction=H","UseDPDF=Y") -> #NAME? | I12: =_xll.BDH("WAB US Equity","SALES_REV_TURN","FY 2017","FY 2017","Currency=USD","Period=FY","BEST_FPERIOD_OVERRIDE=FY","FILING_STATUS=MR","SCALING_FORMAT=MLN","FA_ADJUSTED=Adjusted","Sort=A","Dates=H","DateFormat=P","Fill=—","Direction=H","UseDPDF=Y") -> #NAME? | J12: =_xll.BDH("WAB US Equity","SALES_REV_TURN","FY 2018","FY 2018","Currency=USD","Period=FY","BEST_FPERIOD_OVERRIDE=FY","FILING_STATUS=MR","SCALING_FORMAT=MLN","FA_ADJUSTED=Adjusted","Sort=A","Dates=H","DateFormat=P","Fill=—","Direction=H","UseDPDF=Y") -> #NAME? | K12: =_xll.BDH("WAB US Equity","SALES_REV_TURN","FY 2019","FY 2019","Currency=USD","Period=FY","BEST_FPERIOD_OVERRIDE=FY","FILING_STATUS=MR","SCALING_FORMAT=MLN","FA_ADJUSTED=Adjusted","Sort=A","Dates=H","DateFormat=P","Fill=—","Direction=H","UseDPDF=Y") -> #NAME? | L12: =_xll.BDH("WAB US Equity","SALES_REV_TURN","FY 2020","FY 2020","Currency=USD","Period=FY","BEST_FPERIOD_OVERRIDE=FY","FILING_STATUS=MR","SCALING_FORMAT=MLN","FA_ADJUSTED=Adjusted","Sort=A","Dates=H","DateFormat=P","Fill=—","Direction=H","UseDPDF=Y") -> #NAME? | M12: =_xll.BDH("WAB US Equity","SALES_REV_TURN","FY 2021","FY 2021","Currency=USD","Period=FY","BEST_FPERIOD_OVERRIDE=FY","FILING_STATUS=MR","SCALING_FORMAT=MLN","FA_ADJUSTED=Adjusted","Sort=A","Dates=H","DateFormat=P","Fill=—","Direction=H","UseDPDF=Y") -> #NAME? | N12: =_xll.BDH("WAB US Equity","SALES_REV_TURN","FY 2022","FY 2022","Currency=USD","Period=FY","BEST_FPERIOD_OVERRIDE=FY","FILING_STATUS=MR","SCALING_FORMAT=MLN","FA_ADJUSTED=Adjusted","Sort=A","Dates=H","DateFormat=P","Fill=—","Direction=H","UseDPDF=Y") -> #NAME? | O12: 9457 | P12: 9584.182 | Q12: 10097.636
A13: Growth %, YoY | B13: SALES_GROWTH | C13: =_xll.BDH("WAB US Equity","SALES_GROWTH","FY 2011","FY 2011","Currency=USD","Period=FY","BEST_FPERIOD_OVERRIDE=FY","FILING_STATUS=MR","FA_ADJUSTED=Adjusted","Sort=A","Dates=H","DateFormat=P","Fill=—","Direction=H","UseDPDF=Y") -> #NAME? | D13: =_xll.BDH("WAB US Equity","SALES_GROWTH","FY 2012","FY 2012","Currency=USD","Period=FY","BEST_FPERIOD_OVERRIDE=FY","FILING_STATUS=MR","FA_ADJUSTED=Adjusted","Sort=A","Dates=H","DateFormat=P","Fill=—","Direction=H","UseDPDF=Y") -> #NAME? | E13: =_xll.BDH("WAB US Equity","SALES_GROWTH","FY 2013","FY 2013","Currency=USD","Period=FY","BEST_FPERIOD_OVERRIDE=FY","FILING_STATUS=MR","FA_ADJUSTED=Adjusted","Sort=A","Dates=H","DateFormat=P","Fill=—","Direction=H","UseDPDF=Y") -> #NAME? | F13: =_xll.BDH("WAB US Equity","SALES_GROWTH","FY 2014","FY 2014","Currency=USD","Period=FY","BEST_FPERIOD_OVERRIDE=FY","FILING_STATUS=MR","FA_ADJUSTED=Adjusted","Sort=A","Dates=H","DateFormat=P","Fill=—","Direction=H","UseDPDF=Y") -> #NAME? | G13: =_xll.BDH("WAB US Equity","SALES_GROWTH","FY 2015","FY 2015","Currency=USD","Period=FY","BEST_FPERIOD_OVERRIDE=FY","FILING_STATUS=MR","FA_ADJUSTED=Adjusted","Sort=A","Dates=H","DateFormat=P","Fill=—","Direction=H","UseDPDF=Y") -> #NAME? | H13: =_xll.BDH("WAB US Equity","SALES_GROWTH","FY 2016","FY 2016","Currency=USD","Period=FY","BEST_FPERIOD_OVERRIDE=FY","FILING_STATUS=MR","FA_ADJUSTED=Adjusted","Sort=A","Dates=H","DateFormat=P","Fill=—","Direction=H","UseDPDF=Y") -> #NAME? | I13: =_xll.BDH("WAB US Equity","SALES_GROWTH","FY 2017","FY 2017","Currency=USD","Period=FY","BEST_FPERIOD_OVERRIDE=FY","FILING_STATUS=MR","FA_ADJUSTED=Adjusted","Sort=A","Dates=H","DateFormat=P","Fill=—","Direction=H","UseDPDF=Y") -> #NAME? | J13: =_xll.BDH("WAB US Equity","SALES_GROWTH","FY 2018","FY 2018","Currency=USD","Period=FY","BEST_FPERIOD_OVERRIDE=FY","FILING_STATUS=MR","FA_ADJUSTED=Adjusted","Sort=A","Dates=H","DateFormat=P","Fill=—","Direction=H","UseDPDF=Y") -> #NAME? | K13: =_xll.BDH("WAB US Equity","SALES_GROWTH","FY 2019","FY 2019","Currency=USD","Period=FY","BEST_FPERIOD_OVERRIDE=FY","FILING_STATUS=MR","FA_ADJUSTED=Adjusted","Sort=A","Dates=H","DateFormat=P","Fill=—","Direction=H","UseDPDF=Y") -> #NAME? | L13: =_xll.BDH("WAB US Equity","SALES_GROWTH","FY 2020","FY 2020","Currency=USD","Period=FY","BEST_FPERIOD_OVERRIDE=FY","FILING_STATUS=MR","FA_ADJUSTED=Adjusted","Sort=A","Dates=H","DateFormat=P","Fill=—","Direction=H","UseDPDF=Y") -> #NAME? | M13: =_xll.BDH("WAB US Equity","SALES_GROWTH","FY 2021","FY 2021","Currency=USD","Period=FY","BEST_FPERIOD_OVERRIDE=FY","FILING_STATUS=MR","FA_ADJUSTED=Adjusted","Sort=A","Dates=H","DateFormat=P","Fill=—","Direction=H","UseDPDF=Y") -> #NAME? | N13: =_xll.BDH("WAB US Equity","SALES_GROWTH","FY 2022","FY 2022","Currency=USD","Period=FY","BEST_FPERIOD_OVERRIDE=FY","FILING_STATUS=MR","FA_ADJUSTED=Adjusted","Sort=A","Dates=H","DateFormat=P","Fill=—","Direction=H","UseDPDF=Y") -> #NAME? | O13: 16.336573 | P13: 14.615905 | Q13: 5.3573064
A14: Gross Profit, Adj | B14: GROSS_PROFIT | C14: =_xll.BDH("WAB US Equity","GROSS_PROFIT","FY 2011","FY 2011","Currency=USD","Period=FY","BEST_FPERIOD_OVERRIDE=FY","FILING_STATUS=MR","SCALING_FORMAT=MLN","FA_ADJUSTED=Adjusted","Sort=A","Dates=H","DateFormat=P","Fill=—","Direction=H","UseDPDF=Y") -> #NAME? | D14: =_xll.BDH("WAB US Equity","GROSS_PROFIT","FY 2012","FY 2012","Currency=USD","Period=FY","BEST_FPERIOD_OVERRIDE=FY","FILING_STATUS=MR","SCALING_FORMAT=MLN","FA_ADJUSTED=Adjusted","Sort=A","Dates=H","DateFormat=P","Fill=—","Direction=H","UseDPDF=Y") -> #NAME? | E14: =_xll.BDH("WAB US Equity","GROSS_PROFIT","FY 2013","FY 2013","Currency=USD","Period=FY","BEST_FPERIOD_OVERRIDE=FY","FILING_STATUS=MR","SCALING_FORMAT=MLN","FA_ADJUSTED=Adjusted","Sort=A","Dates=H","DateFormat=P","Fill=—","Direction=H","UseDPDF=Y") -> #NAME? | F14: =_xll.BDH("WAB US Equity","GROSS_PROFIT","FY 2014","FY 2014","Currency=USD","Period=FY","BEST_FPERIOD_OVERRIDE=FY","FILING_STATUS=MR","SCALING_FORMAT=MLN","FA_ADJUSTED=Adjusted","Sort=A","Dates=H","DateFormat=P","Fill=—","Direction=H","UseDPDF=Y") -> #NAME? | G14: =_xll.BDH("WAB US Equity","GROSS_PROFIT","FY 2015","FY 2015","Currency=USD","Period=FY","BEST_FPERIOD_OVERRIDE=FY","FILING_STATUS=MR","SCALING_FORMAT=MLN","FA_ADJUSTED=Adjusted","Sort=A","Dates=H","DateFormat=P","Fill=—","Direction=H","UseDPDF=Y") -> #NAME? | H14: =_xll.BDH("WAB US Equity","GROSS_PROFIT","FY 2016","FY 2016","Currency=USD","Period=FY","BEST_FPERIOD_OVERRIDE=FY","FILING_STATUS=MR","SCALING_FORMAT=MLN","FA_ADJUSTED=Adjusted","Sort=A","Dates=H","DateFormat=P","Fill=—","Direction=H","UseDPDF=Y") -> #NAME? | I14: =_xll.BDH("WAB US Equity","GROSS_PROFIT","FY 2017","FY 2017","Currency=USD","Period=FY","BEST_FPERIOD_OVERRIDE=FY","FILING_STATUS=MR","SCALING_FORMAT=MLN","FA_ADJUSTED=Adjusted","Sort=A","Dates=H","DateFormat=P","Fill=—","Direction=H","UseDPDF=Y") -> #NAME? | J14: =_xll.BDH("WAB US Equity","GROSS_PROFIT","FY 2018","FY 2018","Currency=USD","Period=FY","BEST_FPERIOD_OVERRIDE=FY","FILING_STATUS=MR","SCALING_FORMAT=MLN","FA_ADJUSTED=Adjusted","Sort=A","Dates=H","DateFormat=P","Fill=—","Direction=H","UseDPDF=Y") -> #NAME? | K14: =_xll.BDH("WAB US Equity","GROSS_PROFIT","FY 2019","FY 2019","Currency=USD","Period=FY","BEST_FPERIOD_OVERRIDE=FY","FILING_STATUS=MR","SCALING_FORMAT=MLN","FA_ADJUSTED=Adjusted","Sort=A","Dates=H","DateFormat=P","Fill=—","Direction=H","UseDPDF=Y") -> #NAME? | L14: =_xll.BDH("WAB US Equity","GROSS_PROFIT","FY 2020","FY 2020","Currency=USD","Period=FY","BEST_FPERIOD_OVERRIDE=FY","FILING_STATUS=MR","SCALING_FORMAT=MLN","FA_ADJUSTED=Adjusted","Sort=A","Dates=H","DateFormat=P","Fill=—","Direction=H","UseDPDF=Y") -> #NAME? | M14: =_xll.BDH("WAB US Equity","GROSS_PROFIT","FY 2021","FY 2021","Currency=USD","Period=FY","BEST_FPERIOD_OVERRIDE=FY","FILING_STATUS=MR","SCALING_FORMAT=MLN","FA_ADJUSTED=Adjusted","Sort=A","Dates=H","DateFormat=P","Fill=—","Direction=H","UseDPDF=Y") -> #NAME? | N14: =_xll.BDH("WAB US Equity","GROSS_PROFIT","FY 2022","FY 2022","Currency=USD","Period=FY","BEST_FPERIOD_OVERRIDE=FY","FILING_STATUS=MR","SCALING_FORMAT=MLN","FA_ADJUSTED=Adjusted","Sort=A","Dates=H","DateFormat=P","Fill=—","Direction=H","UseDPDF=Y") -> #NAME? | O14: 2867 | P14: 2956.6243 | Q14: 3174.9997
A15: Margin % | B15: GROSS_PROFIT | C15: 28.990307 | D15: 29.047744 | E15: 29.770472 | F15: 30.770115 | G15: 31.675231 | H15: 31.531209 | I15: 27.4441 | J15: 28.27711 | K15: 30.841043 | L15: 28.870714 | M15: 30.963948 | N15: 30.889739 | O15: 30.316168 | P15: 30.849 | Q15: 31.443
A16: EBITDA, Adj | B16: EBITDA | C16: =_xll.BDH("WAB US Equity","EBITDA","FY 2011","FY 2011","Currency=USD","Period=FY","BEST_FPERIOD_OVERRIDE=FY","FILING_STATUS=MR","SCALING_FORMAT=MLN","FA_ADJUSTED=Adjusted","Sort=A","Dates=H","DateFormat=P","Fill=—","Direction=H","UseDPDF=Y") -> #NAME? | D16: =_xll.BDH("WAB US Equity","EBITDA","FY 2012","FY 2012","Currency=USD","Period=FY","BEST_FPERIOD_OVERRIDE=FY","FILING_STATUS=MR","SCALING_FORMAT=MLN","FA_ADJUSTED=Adjusted","Sort=A","Dates=H","DateFormat=P","Fill=—","Direction=H","UseDPDF=Y") -> #NAME? | E16: =_xll.BDH("WAB US Equity","EBITDA","FY 2013","FY 2013","Currency=USD","Period=FY","BEST_FPERIOD_OVERRIDE=FY","FILING_STATUS=MR","SCALING_FORMAT=MLN","FA_ADJUSTED=Adjusted","Sort=A","Dates=H","DateFormat=P","Fill=—","Direction=H","UseDPDF=Y") -> #NAME? | F16: =_xll.BDH("WAB US Equity","EBITDA","FY 2014","FY 2014","Currency=USD","Period=FY","BEST_FPERIOD_OVERRIDE=FY","FILING_STATUS=MR","SCALING_FORMAT=MLN","FA_ADJUSTED=Adjusted","Sort=A","Dates=H","DateFormat=P","Fill=—","Direction=H","UseDPDF=Y") -> #NAME? | G16: =_xll.BDH("WAB US Equity","EBITDA","FY 2015","FY 2015","Currency=USD","Period=FY","BEST_FPERIOD_OVERRIDE=FY","FILING_STATUS=MR","SCALING_FORMAT=MLN","FA_ADJUSTED=Adjusted","Sort=A","Dates=H","DateFormat=P","Fill=—","Direction=H","UseDPDF=Y") -> #NAME? | H16: =_xll.BDH("WAB US Equity","EBITDA","FY 2016","FY 2016","Currency=USD","Period=FY","BEST_FPERIOD_OVERRIDE=FY","FILING_STATUS=MR","SCALING_FORMAT=MLN","FA_ADJUSTED=Adjusted","Sort=A","Dates=H","DateFormat=P","Fill=—","Direction=H","UseDPDF=Y") -> #NAME? | I16: =_xll.BDH("WAB US Equity","EBITDA","FY 2017","FY 2017","Currency=USD","Period=FY","BEST_FPERIOD_OVERRIDE=FY","FILING_STATUS=MR","SCALING_FORMAT=MLN","FA_ADJUSTED=Adjusted","Sort=A","Dates=H","DateFormat=P","Fill=—","Direction=H","UseDPDF=Y") -> #NAME? | J16: =_xll.BDH("WAB US Equity","EBITDA","FY 2018","FY 2018","Currency=USD","Period=FY","BEST_FPERIOD_OVERRIDE=FY","FILING_STATUS=MR","SCALING_FORMAT=MLN","FA_ADJUSTED=Adjusted","Sort=A","Dates=H","DateFormat=P","Fill=—","Direction=H","UseDPDF=Y") -> #NAME? | K16: =_xll.BDH("WAB US Equity","EBITDA","FY 2019","FY 2019","Currency=USD","Period=FY","BEST_FPERIOD_OVERRIDE=FY","FILING_STATUS=MR","SCALING_FORMAT=MLN","FA_ADJUSTED=Adjusted","Sort=A","Dates=H","DateFormat=P","Fill=—","Direction=H","UseDPDF=Y") -> #NAME? | L16: =_xll.BDH("WAB US Equity","EBITDA","FY 2020","FY 2020","Currency=USD","Period=FY","BEST_FPERIOD_OVERRIDE=FY","FILING_STATUS=MR","SCALING_FORMAT=MLN","FA_ADJUSTED=Adjusted","Sort=A","Dates=H","DateFormat=P","Fill=—","Direction=H","UseDPDF=Y") -> #NAME? | M16: =_xll.BDH("WAB US Equity","EBITDA","FY 2021","FY 2021","Currency=USD","Period=FY","BEST_FPERIOD_OVERRIDE=FY","FILING_STATUS=MR","SCALING_FORMAT=MLN","FA_ADJUSTED=Adjusted","Sort=A","Dates=H","DateFormat=P","Fill=—","Direction=H","UseDPDF=Y") -> #NAME? | N16: =_xll.BDH("WAB US Equity","EBITDA","FY 2022","FY 2022","Currency=USD","Period=FY","BEST_FPERIOD_OVERRIDE=FY","FILING_STATUS=MR","SCALING_FORMAT=MLN","FA_ADJUSTED=Adjusted","Sort=A","Dates=H","DateFormat=P","Fill=—","Direction=H","UseDPDF=Y") -> #NAME? | O16: 1942 | P16: 1853.75 | Q16: 1989.667
A17: Margin % | B17: EBITDA | C17: 18.405326 | D17: 18.686416 | E17: 19.86458 | F17: 20.120849 | G17: 21.17598 | H17: 19.902783 | I17: 16.158512 | J17: 15.110001 | K17: 19.712844 | L17: 18.395733 | M17: 20.250575 | N17: 20.114805 | O17: 20.535053 | P17: 19.341765 | Q17: 19.704285
